Workbook

Sheet 00_Основания
A1: Тема | B1: Условие
A2: Статус | B2: M09/v001 • 15.09.2026. Дополнение ценами SVB и других морских магазинов. Это рабочая оценка компонентов, не полная стоимость установленного МО и не утверждённая УТВ.
A3: Количество | B3: 1 двигатель с 1 редуктором, 2 генератора, 2 основных инвертора, 6+2+1 АКБ сохранены. Ранее пустые количества отдельных компонентов заданы только в явно обозначенном предварительном сценарии.
A4: Исходные цены | B4: Новые источники датированы 15.09.2026; перенесённые цены M03 сохраняют прежнюю дату и ограничения. Ни одна карточка магазина не названа полученным персональным КП.
A5: НДС | B5: NET извлечён по налоговому отображению конкретной карточки. В основной смете к NET добавлены предварительные 23% по D030. SOURCE_GROSS не облагается повторно; его ставка неизвестна.
A6: GBP | B6: Новые цены GBP переведены по ЕЦБ 14.09.2026: 1 EUR = 0.85598 GBP. Старые цены M03 с прежним FX 10.09 сохранены и маркированы. Импорт UK/доставка/таможня требуют отдельной оценки.
A7: Совместимость | B7: 12V стартерные кандидаты — только ценовые аналоги; требование владельца 24 V не изменено. Полная схема пуска от любого АКБ не разработана. PTO/Yanmar, объём пожаротушения, диаметры и расходы не подтверждены ценой.
A8: Состав | B8: Дополнительные компоненты не объявлены полными системами. За составом остались отдельные неоценённые строки; готовые баки Gianneschi 20 L и клапан HT1013 внутри гидробака повторно не начислены.
A9: Опции | B9: Резервное водяное отопление остаётся опцией и показано отдельно от основного итога.
A10: A/B/C | B10: Сохранены альтернативы M03, без ранжирования качества по цене. Общие новые компоненты применены с одинаковыми количествами; общий ценовой аналог не выдаётся за три независимых предложения.
A11: Изменения | B11: Исходные M03/M07 и комплект 1.0 сохранены. Рост суммы включает раскрытие состава и предварительных количеств, а не только изменение рыночных цен.

Sheet 01_КАЦ
A1: Вариант | B1: Система | C1: Фиксированные количества | D1: Оценено NET EUR | E1: Плановый налог EUR | F1: Оценено с налогом EUR | G1: Строк без суммы | H1: Статус | I1: Полный требуемый состав | J1: Открытые входы
A2: PK01-A | B2: Ход яхты | C2: 1 двигатель; 1 редуктор предлагается | D2: =SUMIFS(02_Состав!I2:I139,02_Состав!A2:A139,A2,02_Состав!S2:S139,"ДА") -> 46624.02 | E2: =SUMIFS(02_Состав!L2:L139,02_Состав!A2:A139,A2,02_Состав!S2:S139,"ДА") -> 10723.52 | F2: =SUMIFS(02_Состав!N2:N139,02_Состав!A2:A139,A2,02_Состав!S2:S139,"ДА") -> 57347.54 | G2: 0 | H2: НЕПОЛНЫЙ ПАКЕТ | I2: Двигатель и согласованный редуктор, заводские опоры, управление и жгуты; муфта, упорный узел, вал, дейдвуд, подшипники, уплотнение и согласованный движитель; монтаж, центровка, настройка и собственные испытания | Включения двигателя раскрыть по позициям | Внешнее топливо, охлаждение, выхлоп и вентиляция — PK09; гидронасос и его силовой привод — PK12; механическая совместимость PTO — интерфейс PK01/PK12 | J2: 300 л.с. — исходный ориентир. Скорость, сопротивление, рабочий режим и PTO не рассчитаны. Измеренная компоновка, монтажные и сервисные зоны, полный состав поставки и интерфейсы ещё требуют подтверждения.
A3: PK01-B | B3: Ход яхты | C3: 1 двигатель; 1 редуктор предлагается | D3: =SUMIFS(02_Состав!I2:I139,02_Состав!A2:A139,A3,02_Состав!S2:S139,"ДА") -> 647.02 | E3: =SUMIFS(02_Состав!L2:L139,02_Состав!A2:A139,A3,02_Состав!S2:S139,"ДА") -> 148.81 | F3: =SUMIFS(02_Состав!N2:N139,02_Состав!A2:A139,A3,02_Состав!S2:S139,"ДА") -> 59637.83 | G3: 0 | H3: НЕПОЛНЫЙ ПАКЕТ | I3: Двигатель и согласованный редуктор, заводские опоры, управление и жгуты; муфта, упорный узел, вал, дейдвуд, подшипники, уплотнение и согласованный движитель; монтаж, центровка, настройка и собственные испытания | Включения двигателя раскрыть по позициям | Внешнее топливо, охлаждение, выхлоп и вентиляция — PK09; гидронасос и его силовой привод — PK12; механическая совместимость PTO — интерфейс PK01/PK12 | J3: 300 л.с. — исходный ориентир. Скорость, сопротивление, рабочий режим и PTO не рассчитаны. Измеренная компоновка, монтажные и сервисные зоны, полный состав поставки и интерфейсы ещё требуют подтверждения.
A4: PK01-C | B4: Ход яхты | C4: 1 двигатель; 1 редуктор предлагается | D4: =SUMIFS(02_Состав!I2:I139,02_Состав!A2:A139,A4,02_Состав!S2:S139,"ДА") -> 647.02 | E4: =SUMIFS(02_Состав!L2:L139,02_Состав!A2:A139,A4,02_Состав!S2:S139,"ДА") -> 148.81 | F4: =SUMIFS(02_Состав!N2:N139,02_Состав!A2:A139,A4,02_Состав!S2:S139,"ДА") -> 795.83 | G4: 1 | H4: НЕПОЛНЫЙ ПАКЕТ | I4: Двигатель и согласованный редуктор, заводские опоры, управление и жгуты; муфта, упорный узел, вал, дейдвуд, подшипники, уплотнение и согласованный движитель; монтаж, центровка, настройка и собственные испытания | Включения двигателя раскрыть по позициям | Внешнее топливо, охлаждение, выхлоп и вентиляция — PK09; гидронасос и его силовой привод — PK12; механическая совместимость PTO — интерфейс PK01/PK12 | J4: 300 л.с. — исходный ориентир. Скорость, сопротивление, рабочий режим и PTO не рассчитаны. Измеренная компоновка, монтажные и сервисные зоны, полный состав поставки и интерфейсы ещё требуют подтверждения.
A5: PK02-A | B5: Генерация | C5: 2 генератора | D5: =SUMIFS(02_Состав!I2:I139,02_Состав!A2:A139,A5,02_Состав!S2:S139,"ДА") -> 24893 | E5: =SUMIFS(02_Состав!L2:L139,02_Состав!A2:A139,A5,02_Состав!S2:S139,"ДА") -> 5725.39 | F5: =SUMIFS(02_Состав!N2:N139,02_Состав!A2:A139,A5,02_Состав!S2:S139,"ДА") -> 30618.39 | G5: 0 | H5: НЕПОЛНЫЙ ПАКЕТ | I5: Два генераторных агрегата с согласованными капсулами, опорами, собственным управлением и заводским оснащением; монтаж, местная настройка и испытания каждого | Внешние независимые топливные, водяные и выхлопные ветви — PK09; силовое переключение, распределение и кабели — PK03; пусковые АКБ и резервные связи — PK04 | Параллельную работу не считать включённой по умолчанию | J5: Около 11.5–12 кВА — исходный ориентир. Постоянные и пиковые нагрузки, режим отказа открыты. Измеренная компоновка, монтажные и сервисные зоны, полный состав поставки и интерфейсы ещё требуют подтверждения.
A6: PK02-B | B6: Генерация | C6: 2 генератора | D6: =SUMIFS(02_Состав!I2:I139,02_Состав!A2:A139,A6,02_Состав!S2:S139,"ДА") -> 34902.44 | E6: =SUMIFS(02_Состав!L2:L139,02_Состав!A2:A139,A6,02_Состав!S2:S139,"ДА") -> 8027.56 | F6: =SUMIFS(02_Состав!N2:N139,02_Состав!A2:A139,A6,02_Состав!S2:S139,"ДА") -> 42930 | G6: 0 | H6: НЕПОЛНЫЙ ПАКЕТ | I6: Два генераторных агрегата с согласованными капсулами, опорами, собственным управлением и заводским оснащением; монтаж, местная настройка и испытания каждого | Внешние независимые топливные, водяные и выхлопные ветви — PK09; силовое переключение, распределение и кабели — PK03; пусковые АКБ и резервные связи — PK04 | Параллельную работу не считать включённой по умолчанию | J6: Около 11.5–12 кВА — исходный ориентир. Постоянные и пиковые нагрузки, режим отказа открыты. Измеренная компоновка, монтажные и сервисные зоны, полный состав поставки и интерфейсы ещё требуют подтверждения.
A7: PK02-C | B7: Генерация | C7: 2 генератора | D7: =SUMIFS(02_Состав!I2:I139,02_Состав!A2:A139,A7,02_Состав!S2:S139,"ДА") -> 35858.24 | E7: =SUMIFS(02_Состав!L2:L139,02_Состав!A2:A139,A7,02_Состав!S2:S139,"ДА") -> 8247.4 | F7: =SUMIFS(02_Состав!N2:N139,02_Состав!A2:A139,A7,02_Состав!S2:S139,"ДА") -> 44105.64 | G7: 0 | H7: НЕПОЛНЫЙ ПАКЕТ | I7: Два генераторных агрегата с согласованными капсулами, опорами, собственным управлением и заводским оснащением; монтаж, местная настройка и испытания каждого | Внешние независимые топливные, водяные и выхлопные ветви — PK09; силовое переключение, распределение и кабели — PK03; пусковые АКБ и резервные связи — PK04 | Параллельную работу не считать включённой по умолчанию | J7: Около 11.5–12 кВА — исходный ориентир. Постоянные и пиковые нагрузки, режим отказа открыты. Измеренная компоновка, монтажные и сервисные зоны, полный состав поставки и интерфейсы ещё требуют подтверждения.
A8: PK03-A | B8: Электропитание | C8: 2 основных инвертора; 1 независимая функция питания насоса | D8: =SUMIFS(02_Состав!I2:I139,02_Состав!A2:A139,A8,02_Состав!S2:S139,"ДА") -> 2475.36 | E8: =SUMIFS(02_Состав!L2:L139,02_Состав!A2:A139,A8,02_Состав!S2:S139,"ДА") -> 569.33 | F8: =SUMIFS(02_Состав!N2:N139,02_Состав!A2:A139,A8,02_Состав!S2:S139,"ДА") -> 3319.19 | G8: 2 | H8: НЕПОЛНЫЙ ПАКЕТ | I8: Два основных инвертора/зарядных устройства, береговой ввод и развязка, AC/DC распределение, защиты и общесудовые питающие кабели до границ потребителей; контроль источников, заряд и отключение второстепенных нагрузок, критическое питание | ME-06: одна независимая функция питания AC водяной ветви при отказе гостиничного инвертора; отдельный третий инвертор не назначен | Монтаж, маркировка и электрические проверки | Пусковые силовые пути, изоляция АКБ и BMS — PK04 | J8: 3 кВА — поисковый класс, не утверждённая мощность. Баланс и береговой ввод открыты. Измеренная компоновка, монтажные и сервисные зоны, полный состав поставки и интерфейсы ещё требуют подтверждения.
A9: PK03-B | B9: Электропитание | C9: 2 основных инвертора; 1 независимая функция питания насоса | D9: =SUMIFS(02_Состав!I2:I139,02_Состав!A2:A139,A9,02_Состав!S2:S139,"ДА") -> 3248.47 | E9: =SUMIFS(02_Состав!L2:L139,02_Состав!A2:A139,A9,02_Состав!S2:S139,"ДА") -> 747.14 | F9: =SUMIFS(02_Состав!N2:N139,02_Состав!A2:A139,A9,02_Состав!S2:S139,"ДА") -> 4270.11 | G9: 2 | H9: НЕПОЛНЫЙ ПАКЕТ | I9: Два основных инвертора/зарядных устройства, береговой ввод и развязка, AC/DC распределение, защиты и общесудовые питающие кабели до границ потребителей; контроль источников, заряд и отключение второстепенных нагрузок, критическое питание | ME-06: одна независимая функция питания AC водяной ветви при отказе гостиничного инвертора; отдельный третий инвертор не назначен | Монтаж, маркировка и электрические проверки | Пусковые силовые пути, изоляция АКБ и BMS — PK04 | J9: 3 кВА — поисковый класс, не утверждённая мощность. Баланс и береговой ввод открыты. Измеренная компоновка, монтажные и сервисные зоны, полный состав поставки и интерфейсы ещё требуют подтверждения.
A10: PK03-C | B10: Электропитание | C10: 2 основных инвертора; 1 независимая функция питания насоса | D10: =SUMIFS(02_Состав!I2:I139,02_Состав!A2:A139,A10,02_Состав!S2:S139,"ДА") -> 4256.89 | E10: =SUMIFS(02_Состав!L2:L139,02_Состав!A2:A139,A10,02_Состав!S2:S139,"ДА") -> 979.08 | F10: =SUMIFS(02_Состав!N2:N139,02_Состав!A2:A139,A10,02_Состав!S2:S139,"ДА") -> 5510.47 | G10: 2 | H10: НЕПОЛНЫЙ ПАКЕТ | I10: Два основных инвертора/зарядных устройства, береговой ввод и развязка, AC/DC распределение, защиты и общесудовые питающие кабели до границ потребителей; контроль источников, заряд и отключение второстепенных нагрузок, критическое питание | ME-06: одна независимая функция питания AC водяной ветви при отказе гостиничного инвертора; отдельный третий инвертор не назначен | Монтаж, маркировка и электрические проверки | Пусковые силовые пути, изоляция АКБ и BMS — PK04 | J10: 3 кВА — поисковый класс, не утверждённая мощность. Баланс и береговой ввод открыты. Измеренная компоновка, монтажные и сервисные зоны, полный состав поставки и интерфейсы ещё требуют подтверждения.
A11: PK04-A | B11: АКБ и резервный пуск | C11: 6 сервисных + 2 генераторных + 1 главного двигателя | D11: =SUMIFS(02_Состав!I2:I139,02_Состав!A2:A139,A11,02_Состав!S2:S139,"ДА") -> 2215.16 | E11: =SUMIFS(02_Состав!L2:L139,02_Состав!A2:A139,A11,02_Состав!S2:S139,"ДА") -> 509.49 | F11: =SUMIFS(02_Состав!N2:N139,02_Состав!A2:A139,A11,02_Состав!S2:S139,"ДА") -> 2724.65 | G11: 0 | H11: НЕПОЛНЫЙ ПАКЕТ | I11: Девять физических АКБ по назначению; крепления и защитные объёмы, BMS по химии, батарейная и стартерная коммутация, силовые кабели до согласованных точек подключения PK03/стартеров, дистанционные контакторы, межблокировки и подтверждение состояния | Изоляция неисправной АКБ перед резервным пуском; местная блокировка обслуживания, питание управления и проверка всех разрешённых путей запуска | Зарядные устройства — PK03; независимость и настройки зарядки совместно PK03/PK04 | J11: Уточнение 115 ампер/А·ч и напряжения каждой АКБ ожидается. Пусковые токи, химия и допустимый разряд открыты. Измеренная компоновка, монтажные и сервисные зоны, полный состав поставки и интерфейсы ещё требуют подтверждения.
A12: PK04-B | B12: АКБ и резервный пуск | C12: 6 сервисных + 2 генераторных + 1 главного двигателя | D12: =SUMIFS(02_Состав!I2:I139,02_Состав!A2:A139,A12,02_Состав!S2:S139,"ДА") -> 2982.14 | E12: =SUMIFS(02_Состав!L2:L139,02_Состав!A2:A139,A12,02_Состав!S2:S139,"ДА") -> 685.9 | F12: =SUMIFS(02_Состав!N2:N139,02_Состав!A2:A139,A12,02_Состав!S2:S139,"ДА") -> 3668.04 | G12: 0 | H12: НЕПОЛНЫЙ ПАКЕТ | I12: Девять физических АКБ по назначению; крепления и защитные объёмы, BMS по химии, батарейная и стартерная коммутация, силовые кабели до согласованных точек подключения PK03/стартеров, дистанционные контакторы, межблокировки и подтверждение состояния | Изоляция неисправной АКБ перед резервным пуском; местная блокировка обслуживания, питание управления и проверка всех разрешённых путей запуска | Зарядные устройства — PK03; независимость и настройки зарядки совместно PK03/PK04 | J12: Уточнение 115 ампер/А·ч и напряжения каждой АКБ ожидается. Пусковые токи, химия и допустимый разряд открыты. Измеренная компоновка, монтажные и сервисные зоны, полный состав поставки и интерфейсы ещё требуют подтверждения.
A13: PK04-C | B13: АКБ и резервный пуск | C13: 6 сервисных + 2 генераторных + 1 главного двигателя | D13: =SUMIFS(02_Состав!I2:I139,02_Состав!A2:A139,A13,02_Состав!S2:S139,"ДА") -> 3009.86 | E13: =SUMIFS(02_Состав!L2:L139,02_Состав!A2:A139,A13,02_Состав!S2:S139,"ДА") -> 692.27 | F13: =SUMIFS(02_Состав!N2:N139,02_Состав!A2:A139,A13,02_Состав!S2:S139,"ДА") -> 3702.13 | G13: 0 | H13: НЕПОЛНЫЙ ПАКЕТ | I13: Девять физических АКБ по назначению; крепления и защитные объёмы, BMS по химии, батарейная и стартерная коммутация, силовые кабели до согласованных точек подключения PK03/стартеров, дистанционные контакторы, межблокировки и подтверждение состояния | Изоляция неисправной АКБ перед резервным пуском; местная блокировка обслуживания, питание управления и проверка всех разрешённых путей запуска | Зарядные устройства — PK03; независимость и настройки зарядки совместно PK03/PK04 | J13: Уточнение 115 ампер/А·ч и напряжения каждой АКБ ожидается. Пусковые токи, химия и допустимый разряд открыты. Измеренная компоновка, монтажные и сервисные зоны, полный состав поставки и интерфейсы ещё требуют подтверждения.
A14: PK05-A | B14: Пресная вода | C14: 1 установка 24 В + 1 установка AC | D14: =SUMIFS(02_Состав!I2:I139,02_Состав!A2:A139,A14,02_Состав!S2:S139,"ДА") -> 1535.62 | E14: =SUMIFS(02_Состав!L2:L139,02_Состав!A2:A139,A14,02_Состав!S2:S139,"ДА") -> 353.19 | F14: =SUMIFS(02_Состав!N2:N139,02_Состав!A2:A139,A14,02_Состав!S2:S139,"ДА") -> 1888.81 | G14: 1 | H14: НЕПОЛНЫЙ ПАКЕТ | I14: Одна установка 24 В и одна AC; независимые пути с выбором и изоляцией, гидроаккумуляторы, фильтры, обратные клапаны, коллекторы, магистрали до водоразбора и контроль давления | Общие узлы ME-17, включая термостатическое смешение и рециркуляцию ГВС при принятии, принадлежат PK05 | Подача на RO промывку и бойлер — интерфейсы PK06/PK07 | Комплектные фильтры RO — PK06; баки — PK11 | Опрессовка, промывка и проверка обоих режимов | J14: Рабочая точка и одновременность водоразбора открыты. 15 л/мин при 2 бар — только поисковый пример. Измеренная компоновка, монтажные и сервисные зоны, полный состав поставки и интерфейсы ещё требуют подтверждения.
A15: PK05-B | B15: Пресная вода | C15: 1 установка 24 В + 1 установка AC | D15: =SUMIFS(02_Состав!I2:I139,02_Состав!A2:A139,A15,02_Состав!S2:S139,"ДА") -> 2656.45 | E15: =SUMIFS(02_Состав!L2:L139,02_Состав!A2:A139,A15,02_Состав!S2:S139,"ДА") -> 610.99 | F15: =SUMIFS(02_Состав!N2:N139,02_Состав!A2:A139,A15,02_Состав!S2:S139,"ДА") -> 3267.44 | G15: 0 | H15: НЕПОЛНЫЙ ПАКЕТ | I15: Одна установка 24 В и одна AC; независимые пути с выбором и изоляцией, гидроаккумуляторы, фильтры, обратные клапаны, коллекторы, магистрали до водоразбора и контроль давления | Общие узлы ME-17, включая термостатическое смешение и рециркуляцию ГВС при принятии, принадлежат PK05 | Подача на RO промывку и бойлер — интерфейсы PK06/PK07 | Комплектные фильтры RO — PK06; баки — PK11 | Опрессовка, промывка и проверка обоих режимов | J15: Рабочая точка и одновременность водоразбора открыты. 15 л/мин при 2 бар — только поисковый пример. Измеренная компоновка, монтажные и сервисные зоны, полный состав поставки и интерфейсы ещё требуют подтверждения.
A16: PK05-C | B16: Пресная вода | C16: 1 установка 24 В + 1 установка AC | D16: =SUMIFS(02_Состав!I2:I139,02_Состав!A2:A139,A16,02_Состав!S2:S139,"ДА") -> 510.7 | E16: =SUMIFS(02_Состав!L2:L139,02_Состав!A2:A139,A16,02_Состав!S2:S139,"ДА") -> 117.46 | F16: =SUMIFS(02_Состав!N2:N139,02_Состав!A2:A139,A16,02_Состав!S2:S139,"ДА") -> 628.16 | G16: 2 | H16: НЕПОЛНЫЙ ПАКЕТ | I16: Одна установка 24 В и одна AC; независимые пути с выбором и изоляцией, гидроаккумуляторы, фильтры, обратные клапаны, коллекторы, магистрали до водоразбора и контроль давления | Общие узлы ME-17, включая термостатическое смешение и рециркуляцию ГВС при принятии, принадлежат PK05 | Подача на RO промывку и бойлер — интерфейсы PK06/PK07 | Комплектные фильтры RO — PK06; баки — PK11 | Опрессовка, промывка и проверка обоих режимов | J16: Рабочая точка и одновременность водоразбора открыты. 15 л/мин при 2 бар — только поисковый пример. Измеренная компоновка, монтажные и сервисные зоны, полный состав поставки и интерфейсы ещё требуют подтверждения.
A17: PK06-A | B17: Опреснение | C17: 1 опреснитель | D17: =SUMIFS(02_Состав!I2:I139,02_Состав!A2:A139,A17,02_Состав!S2:S139,"ДА") -> 6335.29 | E17: =SUMIFS(02_Состав!L2:L139,02_Состав!A2:A139,A17,02_Состав!S2:S139,"ДА") -> 1457.12 | F17: =SUMIFS(02_Состав!N2:N139,02_Состав!A2:A139,A17,02_Состав!S2:S139,"ДА") -> 7792.41 | G17: 0 | H17: НЕПОЛНЫЙ ПАКЕТ | I17: Один RO с подающим и высоким давлением по исполнению, мембранами, штатными фильтрами, контролем солёности и автоматическим отводом некондиционного продукта, промывкой и управлением | Внутренняя обвязка, крепления, монтаж и наладка; трассы забортной подачи и концентрата этой установки принадлежат PK06, не PK09 | Подача пресной воды на промывку — PK05; приёмный танк — PK11 | Проверить качество, производительность и все автоматические режимы | J17: Температура, солёность и окончательная комплектация открыты. Измеренная компоновка, монтажные и сервисные зоны, полный состав поставки и интерфейсы ещё требуют подтверждения.
A18: PK06-B | B18: Опреснение | C18: 1 опреснитель | D18: =SUMIFS(02_Состав!I2:I139,02_Состав!A2:A139,A18,02_Состав!S2:S139,"ДА") -> 10683.5 | E18: =SUMIFS(02_Состав!L2:L139,02_Состав!A2:A139,A18,02_Состав!S2:S139,"ДА") -> 2457.21 | F18: =SUMIFS(02_Состав!N2:N139,02_Состав!A2:A139,A18,02_Состав!S2:S139,"ДА") -> 13140.71 | G18: 0 | H18: НЕПОЛНЫЙ ПАКЕТ | I18: Один RO с подающим и высоким давлением по исполнению, мембранами, штатными фильтрами, контролем солёности и автоматическим отводом некондиционного продукта, промывкой и управлением | Внутренняя обвязка, крепления, монтаж и наладка; трассы забортной подачи и концентрата этой установки принадлежат PK06, не PK09 | Подача пресной воды на промывку — PK05; приёмный танк — PK11 | Проверить качество, производительность и все автоматические режимы | J18: Температура, солёность и окончательная комплектация открыты. Измеренная компоновка, монтажные и сервисные зоны, полный состав поставки и интерфейсы ещё требуют подтверждения.
A19: PK06-C | B19: Опреснение | C19: 1 опреснитель | D19: =SUMIFS(02_Состав!I2:I139,02_Состав!A2:A139,A19,02_Состав!S2:S139,"ДА") -> 0 | E19: =SUMIFS(02_Состав!L2:L139,02_Состав!A2:A139,A19,02_Состав!S2:S139,"ДА") -> 0 | F19: =SUMIFS(02_Состав!N2:N139,02_Состав!A2:A139,A19,02_Состав!S2:S139,"ДА") -> 0 | G19: 1 | H19: НЕПОЛНЫЙ ПАКЕТ | I19: Один RO с подающим и высоким давлением по исполнению, мембранами, штатными фильтрами, контролем солёности и автоматическим отводом некондиционного продукта, промывкой и управлением | Внутренняя обвязка, крепления, монтаж и наладка; трассы забортной подачи и концентрата этой установки принадлежат PK06, не PK09 | Подача пресной воды на промывку — PK05; приёмный танк — PK11 | Проверить качество, производительность и все автоматические режимы | J19: Температура, солёность и окончательная комплектация открыты. Измеренная компоновка, монтажные и сервисные зоны, полный состав поставки и интерфейсы ещё требуют подтверждения.
A20: PK07-A | B20: Горячая вода | C20: Количество бойлеров не принято | D20: =SUMIFS(02_Состав!I2:I139,02_Состав!A2:A139,A20,02_Состав!S2:S139,"ДА") -> 614.17 | E20: =SUMIFS(02_Состав!L2:L139,02_Состав!A2:A139,A20,02_Состав!S2:S139,"ДА") -> 141.26 | F20: =SUMIFS(02_Состав!N2:N139,02_Состав!A2:A139,A20,02_Состав!S2:S139,"ДА") -> 755.43 | G20: 0 | H20: НЕПОЛНЫЙ ПАКЕТ | I20: Бойлеры с электрическим и двигательным нагревом, штатной защитной арматурой, изоляцией, креплениями и сливом; теплоноситель от согласованного присоединения двигателя до бойлера и обратно | Монтаж, проверка нагрева и восстановления запаса | Число и объём не назначены | Термостатическое смешение и общая рециркуляция — PK05, не повторная покупка PK07; питание — PK03 | J20: 40 л / 1200 Вт — рыночный пример, не заданная потребность. Измеренная компоновка, монтажные и сервисные зоны, полный состав поставки и интерфейсы ещё требуют подтверждения.
A21: PK07-B | B21: Горячая вода | C21: Количество бойлеров не принято | D21: =SUMIFS(02_Состав!I2:I139,02_Состав!A2:A139,A21,02_Состав!S2:S139,"ДА") -> 690.83 | E21: =SUMIFS(02_Состав!L2:L139,02_Состав!A2:A139,A21,02_Состав!S2:S139,"ДА") -> 158.89 | F21: =SUMIFS(02_Состав!N2:N139,02_Состав!A2:A139,A21,02_Состав!S2:S139,"ДА") -> 849.72 | G21: 0 | H21: НЕПОЛНЫЙ ПАКЕТ | I21: Бойлеры с электрическим и двигательным нагревом, штатной защитной арматурой, изоляцией, креплениями и сливом; теплоноситель от согласованного присоединения двигателя до бойлера и обратно | Монтаж, проверка нагрева и восстановления запаса | Число и объём не назначены | Термостатическое смешение и общая рециркуляция — PK05, не повторная покупка PK07; питание — PK03 | J21: 40 л / 1200 Вт — рыночный пример, не заданная потребность. Измеренная компоновка, монтажные и сервисные зоны, полный состав поставки и интерфейсы ещё требуют подтверждения.
A22: PK07-C | B22: Горячая вода | C22: Количество бойлеров не принято | D22: =SUMIFS(02_Состав!I2:I139,02_Состав!A2:A139,A22,02_Состав!S2:S139,"ДА") -> 757.5 | E22: =SUMIFS(02_Состав!L2:L139,02_Состав!A2:A139,A22,02_Состав!S2:S139,"ДА") -> 174.23 | F22: =SUMIFS(02_Состав!N2:N139,02_Состав!A2:A139,A22,02_Состав!S2:S139,"ДА") -> 931.73 | G22: 0 | H22: НЕПОЛНЫЙ ПАКЕТ | I22: Бойлеры с электрическим и двигательным нагревом, штатной защитной арматурой, изоляцией, креплениями и сливом; теплоноситель от согласованного присоединения двигателя до бойлера и обратно | Монтаж, проверка нагрева и восстановления запаса | Число и объём не назначены | Термостатическое смешение и общая рециркуляция — PK05, не повторная покупка PK07; питание — PK03 | J22: 40 л / 1200 Вт — рыночный пример, не заданная потребность. Измеренная компоновка, монтажные и сервисные зоны, полный состав поставки и интерфейсы ещё требуют подтверждения.
A23: PK08-A | B23: Климат | C23: 2 чиллера; дополнительное отопление — опция | D23: =SUMIFS(02_Состав!I2:I139,02_Состав!A2:A139,A23,02_Состав!S2:S139,"ДА") -> 8568.5 | E23: =SUMIFS(02_Состав!L2:L139,02_Состав!A2:A139,A23,02_Состав!S2:S139,"ДА") -> 1970.76 | F23: =SUMIFS(02_Состав!N2:N139,02_Состав!A2:A139,A23,02_Состав!S2:S139,"ДА") -> 10539.26 | G23: 0 | H23: НЕПОЛНЫЙ ПАКЕТ | I23: Два независимо изолируемых чиллерных модуля; шкафы и панели управления, согласованные фанкойлы по помещениям, гидравлические контуры холода и забортного охлаждения, насосы, фильтры, расширение, клапаны, трубная изоляция, воздухораспределение и дренаж конденсата; монтаж, балансировка и наладка | Все собственные HVAC водяные ветви — PK08, не PK09 | Дополнительное отопление ME-26 — отдельная опция с контуром и управлением, без автоматического назначения котла | Фанкойлы — явное расширение до результата, их количество открыто | J23: 16 000 BTU/h на модуль — пример рынка. Тепловой расчёт и уровень сервиса при отказе открыты. Измеренная компоновка, монтажные и сервисные зоны, полный состав поставки и интерфейсы ещё требуют подтверждения.
A24: PK08-B | B24: Климат | C24: 2 чиллера; дополнительное отопление — опция | D24: =SUMIFS(02_Состав!I2:I139,02_Состав!A2:A139,A24,02_Состав!S2:S139,"ДА") -> 9637.1 | E24: =SUMIFS(02_Состав!L2:L139,02_Состав!A2:A139,A24,02_Состав!S2:S139,"ДА") -> 2216.54 | F24: =SUMIFS(02_Состав!N2:N139,02_Состав!A2:A139,A24,02_Состав!S2:S139,"ДА") -> 11853.64 | G24: 0 | H24: НЕПОЛНЫЙ ПАКЕТ | I24: Два независимо изолируемых чиллерных модуля; шкафы и панели управления, согласованные фанкойлы по помещениям, гидравлические контуры холода и забортного охлаждения, насосы, фильтры, расширение, клапаны, трубная изоляция, воздухораспределение и дренаж конденсата; монтаж, балансировка и наладка | Все собственные HVAC водяные ветви — PK08, не PK09 | Дополнительное отопление ME-26 — отдельная опция с контуром и управлением, без автоматического назначения котла | Фанкойлы — явное расширение до результата, их количество открыто | J24: 16 000 BTU/h на модуль — пример рынка. Тепловой расчёт и уровень сервиса при отказе открыты. Измеренная компоновка, монтажные и сервисные зоны, полный состав поставки и интерфейсы ещё требуют подтверждения.
A25: PK08-C | B25: Климат | C25: 2 чиллера; дополнительное отопление — опция | D25: =SUMIFS(02_Состав!I2:I139,02_Состав!A2:A139,A25,02_Состав!S2:S139,"ДА") -> 1326.5 | E25: =SUMIFS(02_Состав!L2:L139,02_Состав!A2:A139,A25,02_Состав!S2:S139,"ДА") -> 305.1 | F25: =SUMIFS(02_Состав!N2:N139,02_Состав!A2:A139,A25,02_Состав!S2:S139,"ДА") -> 1631.6 | G25: 1 | H25: НЕПОЛНЫЙ ПАКЕТ | I25: Два независимо изолируемых чиллерных модуля; шкафы и панели управления, согласованные фанкойлы по помещениям, гидравлические контуры холода и забортного охлаждения, насосы, фильтры, расширение, клапаны, трубная изоляция, воздухораспределение и дренаж конденсата; монтаж, балансировка и наладка | Все собственные HVAC водяные ветви — PK08, не PK09 | Дополнительное отопление ME-26 — отдельная опция с контуром и управлением, без автоматического назначения котла | Фанкойлы — явное расширение до результата, их количество открыто | J25: 16 000 BTU/h на модуль — пример рынка. Тепловой расчёт и уровень сервиса при отказе открыты. Измеренная компоновка, монтажные и сервисные зоны, полный состав поставки и интерфейсы ещё требуют подтверждения.
A26: PK09-A | B26: Обеспечение МО | C26: Число элементов определяется выбранными системами | D26: =SUMIFS(02_Состав!I2:I139,02_Состав!A2:A139,A26,02_Состав!S2:S139,"ДА") -> 3691.47 | E26: =SUMIFS(02_Состав!L2:L139,02_Состав!A2:A139,A26,02_Состав!S2:S139,"ДА") -> 849.04 | F26: =SUMIFS(02_Состав!N2:N139,02_Состав!A2:A139,A26,02_Состав!S2:S139,"ДА") -> 4540.51 | G26: 1 | H26: НЕПОЛНЫЙ ПАКЕТ | I26: Общие и раздельные внешние топливные ветви двигателя/генераторов: фильтрация, подача, обратки, арматура и сервис; их забортное охлаждение, антисифонные меры, выхлоп и выходы; приток и вытяжка МО с каналами, заслонками и остановом по пожару | Маслосмена, поддоны, местные сервисные узлы и освещение с интерфейсом PK03 | Монтаж, изоляция, маркировка и испытания | Топливные танки и уровнемеры — PK11; заводские внутренние элементы агрегатов — PK01/PK02; отдельные RO/HVAC/гидравлические охладители и ветви — PK06/PK08/PK12 | J26: Диаметры, тепловыделение, напор, длины и комплектность открыты. Измеренная компоновка, монтажные и сервисные зоны, полный состав поставки и интерфейсы ещё требуют подтверждения.
A27: PK09-B | B27: Обеспечение МО | C27: Число элементов определяется выбранными системами | D27: =SUMIFS(02_Состав!I2:I139,02_Состав!A2:A139,A27,02_Состав!S2:S139,"ДА") -> 3855.93 | E27: =SUMIFS(02_Состав!L2:L139,02_Состав!A2:A139,A27,02_Состав!S2:S139,"ДА") -> 886.87 | F27: =SUMIFS(02_Состав!N2:N139,02_Состав!A2:A139,A27,02_Состав!S2:S139,"ДА") -> 4742.8 | G27: 0 | H27: НЕПОЛНЫЙ ПАКЕТ | I27: Общие и раздельные внешние топливные ветви двигателя/генераторов: фильтрация, подача, обратки, арматура и сервис; их забортное охлаждение, антисифонные меры, выхлоп и выходы; приток и вытяжка МО с каналами, заслонками и остановом по пожару | Маслосмена, поддоны, местные сервисные узлы и освещение с интерфейсом PK03 | Монтаж, изоляция, маркировка и испытания | Топливные танки и уровнемеры — PK11; заводские внутренние элементы агрегатов — PK01/PK02; отдельные RO/HVAC/гидравлические охладители и ветви — PK06/PK08/PK12 | J27: Диаметры, тепловыделение, напор, длины и комплектность открыты. Измеренная компоновка, монтажные и сервисные зоны, полный состав поставки и интерфейсы ещё требуют подтверждения.
A28: PK09-C | B28: Обеспечение МО | C28: Число элементов определяется выбранными системами | D28: =SUMIFS(02_Состав!I2:I139,02_Состав!A2:A139,A28,02_Состав!S2:S139,"ДА") -> 3855.93 | E28: =SUMIFS(02_Состав!L2:L139,02_Состав!A2:A139,A28,02_Состав!S2:S139,"ДА") -> 886.87 | F28: =SUMIFS(02_Состав!N2:N139,02_Состав!A2:A139,A28,02_Состав!S2:S139,"ДА") -> 4742.8 | G28: 0 | H28: НЕПОЛНЫЙ ПАКЕТ | I28: Общие и раздельные внешние топливные ветви двигателя/генераторов: фильтрация, подача, обратки, арматура и сервис; их забортное охлаждение, антисифонные меры, выхлоп и выходы; приток и вытяжка МО с каналами, заслонками и остановом по пожару | Маслосмена, поддоны, местные сервисные узлы и освещение с интерфейсом PK03 | Монтаж, изоляция, маркировка и испытания | Топливные танки и уровнемеры — PK11; заводские внутренние элементы агрегатов — PK01/PK02; отдельные RO/HVAC/гидравлические охладители и ветви — PK06/PK08/PK12 | J28: Диаметры, тепловыделение, напор, длины и комплектность открыты. Измеренная компоновка, монтажные и сервисные зоны, полный состав поставки и интерфейсы ещё требуют подтверждения.
A29: PK10-A | B29: Аварийные системы | C29: Число компонентов определяется расчётом | D29: =SUMIFS(02_Состав!I2:I139,02_Состав!A2:A139,A29,02_Состав!S2:S139,"ДА") -> 700.63 | E29: =SUMIFS(02_Состав!L2:L139,02_Состав!A2:A139,A29,02_Состав!S2:S139,"ДА") -> 161.15 | F29: =SUMIFS(02_Состав!N2:N139,02_Состав!A2:A139,A29,02_Состав!S2:S139,"ДА") -> 5699.28 | G29: 0 | H29: НЕПОЛНЫЙ ПАКЕТ | I29: Зональное и аварийное осушение с насосами, ручными средствами, трубами, арматурой, датчиками и независимой тревогой; пожарное обнаружение, стационарное тушение, ручной пуск и контроль готовности | Матрица остановов двигателя/генераторов и вентиляции, собственные исполнительные приводы пожарной отсечки топлива — PK10, корпуса топливной арматуры — PK09 | Монтаж и проверка сценариев, без необоснованного расходования заряда | Числа, защищаемый объём и тип агента открыты | J29: Отсеки, защищаемый объём и аварийные режимы открыты. Измеренная компоновка, монтажные и сервисные зоны, полный состав поставки и интерфейсы ещё требуют подтверждения.
A30: PK10-B | B30: Аварийные системы | C30: Число компонентов определяется расчётом | D30: =SUMIFS(02_Состав!I2:I139,02_Состав!A2:A139,A30,02_Состав!S2:S139,"ДА") -> 700.63 | E30: =SUMIFS(02_Состав!L2:L139,02_Состав!A2:A139,A30,02_Состав!S2:S139,"ДА") -> 161.15 | F30: =SUMIFS(02_Состав!N2:N139,02_Состав!A2:A139,A30,02_Состав!S2:S139,"ДА") -> 5699.28 | G30: 0 | H30: НЕПОЛНЫЙ ПАКЕТ | I30: Зональное и аварийное осушение с насосами, ручными средствами, трубами, арматурой, датчиками и независимой тревогой; пожарное обнаружение, стационарное тушение, ручной пуск и контроль готовности | Матрица остановов двигателя/генераторов и вентиляции, собственные исполнительные приводы пожарной отсечки топлива — PK10, корпуса топливной арматуры — PK09 | Монтаж и проверка сценариев, без необоснованного расходования заряда | Числа, защищаемый объём и тип агента открыты | J30: Отсеки, защищаемый объём и аварийные режимы открыты. Измеренная компоновка, монтажные и сервисные зоны, полный состав поставки и интерфейсы ещё требуют подтверждения.
A31: PK10-C | B31: Аварийные системы | C31: Число компонентов определяется расчётом | D31: =SUMIFS(02_Состав!I2:I139,02_Состав!A2:A139,A31,02_Состав!S2:S139,"ДА") -> 700.63 | E31: =SUMIFS(02_Состав!L2:L139,02_Состав!A2:A139,A31,02_Состав!S2:S139,"ДА") -> 161.15 | F31: =SUMIFS(02_Состав!N2:N139,02_Состав!A2:A139,A31,02_Состав!S2:S139,"ДА") -> 5699.28 | G31: 0 | H31: НЕПОЛНЫЙ ПАКЕТ | I31: Зональное и аварийное осушение с насосами, ручными средствами, трубами, арматурой, датчиками и независимой тревогой; пожарное обнаружение, стационарное тушение, ручной пуск и контроль готовности | Матрица остановов двигателя/генераторов и вентиляции, собственные исполнительные приводы пожарной отсечки топлива — PK10, корпуса топливной арматуры — PK09 | Монтаж и проверка сценариев, без необоснованного расходования заряда | Числа, защищаемый объём и тип агента открыты | J31: Отсеки, защищаемый объём и аварийные режимы открыты. Измеренная компоновка, монтажные и сервисные зоны, полный состав поставки и интерфейсы ещё требуют подтверждения.
A32: PK11-A | B32: Танки и стоки | C32: Количество и объёмы открыты | D32: =SUMIFS(02_Состав!I2:I139,02_Состав!A2:A139,A32,02_Состав!S2:S139,"ДА") -> 568.94 | E32: =SUMIFS(02_Состав!L2:L139,02_Состав!A2:A139,A32,02_Состав!S2:S139,"ДА") -> 130.86 | F32: =SUMIFS(02_Состав!N2:N139,02_Состав!A2:A139,A32,02_Состав!S2:S139,"ДА") -> 699.8 | G32: 0 | H32: НЕПОЛНЫЙ ПАКЕТ | I32: Полезные запасы и стоки: реестр фактических танков, встроенные либо съёмные ёмкости, люки, вентиляция, залив/слив, уровнемеры и управление; санитарная техническая подача, изоляция источников смыва, насосы стоков, откачка и контроль доступа к сбросу | Изготовление встроенного танка и его испытание раскрыть отдельно от испытания всей системы | В рамках учёта M03 — PK11, с интерфейсом корпусному W10.90, без двойной цены | Санприборы, не входящие в перечень МО, — внешний пакет W50.58 | Трубопроводы от танковых сервисных границ — PK05/PK09 по назначению | J32: Конструкция встроенных танков, уровни и маршруты доступа открыты. Измеренная компоновка, монтажные и сервисные зоны, полный состав поставки и интерфейсы ещё требуют подтверждения.
A33: PK11-B | B33: Танки и стоки | C33: Количество и объёмы открыты | D33: =SUMIFS(02_Состав!I2:I139,02_Состав!A2:A139,A33,02_Состав!S2:S139,"ДА") -> 1148.49 | E33: =SUMIFS(02_Состав!L2:L139,02_Состав!A2:A139,A33,02_Состав!S2:S139,"ДА") -> 264.15 | F33: =SUMIFS(02_Состав!N2:N139,02_Состав!A2:A139,A33,02_Состав!S2:S139,"ДА") -> 1412.64 | G33: 0 | H33: НЕПОЛНЫЙ ПАКЕТ | I33: Полезные запасы и стоки: реестр фактических танков, встроенные либо съёмные ёмкости, люки, вентиляция, залив/слив, уровнемеры и управление; санитарная техническая подача, изоляция источников смыва, насосы стоков, откачка и контроль доступа к сбросу | Изготовление встроенного танка и его испытание раскрыть отдельно от испытания всей системы | В рамках учёта M03 — PK11, с интерфейсом корпусному W10.90, без двойной цены | Санприборы, не входящие в перечень МО, — внешний пакет W50.58 | Трубопроводы от танковых сервисных границ — PK05/PK09 по назначению | J33: Конструкция встроенных танков, уровни и маршруты доступа открыты. Измеренная компоновка, монтажные и сервисные зоны, полный состав поставки и интерфейсы ещё требуют подтверждения.
A34: PK11-C | B34: Танки и стоки | C34: Количество и объёмы открыты | D34: =SUMIFS(02_Состав!I2:I139,02_Состав!A2:A139,A34,02_Состав!S2:S139,"ДА") -> 1148.49 | E34: =SUMIFS(02_Состав!L2:L139,02_Состав!A2:A139,A34,02_Состав!S2:S139,"ДА") -> 264.15 | F34: =SUMIFS(02_Состав!N2:N139,02_Состав!A2:A139,A34,02_Состав!S2:S139,"ДА") -> 1412.64 | G34: 0 | H34: НЕПОЛНЫЙ ПАКЕТ | I34: Полезные запасы и стоки: реестр фактических танков, встроенные либо съёмные ёмкости, люки, вентиляция, залив/слив, уровнемеры и управление; санитарная техническая подача, изоляция источников смыва, насосы стоков, откачка и контроль доступа к сбросу | Изготовление встроенного танка и его испытание раскрыть отдельно от испытания всей системы | В рамках учёта M03 — PK11, с интерфейсом корпусному W10.90, без двойной цены | Санприборы, не входящие в перечень МО, — внешний пакет W50.58 | Трубопроводы от танковых сервисных границ — PK05/PK09 по назначению | J34: Конструкция встроенных танков, уровни и маршруты доступа открыты. Измеренная компоновка, монтажные и сервисные зоны, полный состав поставки и интерфейсы ещё требуют подтверждения.
A35: PK12-A | B35: Гидравлика | C35: Гидропривод обязателен; число потребителей не принято | D35: =SUMIFS(02_Состав!I2:I139,02_Состав!A2:A139,A35,02_Состав!S2:S139,"ДА") -> 7432.51 | E35: =SUMIFS(02_Состав!L2:L139,02_Состав!A2:A139,A35,02_Состав!S2:S139,"ДА") -> 1709.47 | F35: =SUMIFS(02_Состав!N2:N139,02_Состав!A2:A139,A35,02_Состав!S2:S139,"ДА") -> 9141.98 | G35: 3 | H35: НЕПОЛНЫЙ ПАКЕТ | I35: Полная гидросистема до нужных функций всех подруливающих и всех лебёдок: насосы и выбранный привод, PTO/адаптация либо электрический или отдельный привод, бак, фильтры, охлаждение, распределители, регулирование и защита давления, трассы, местные клапаны, управление и исполнительные гидромоторы/механизмы | Выдать ведомость всех внешних потребителей и включений их пакетов: одинаковый предмет не суммировать дважды | Монтаж, промывка, чистота масла, наладка приоритетов и испытания режимов, в том числе согласованного режима без главного дизеля | Рулевое не включать в общий контур автоматически | J35: Тяга, момент, скорость, одновременность и источники мощности открыты. Измеренная компоновка, монтажные и сервисные зоны, полный состав поставки и интерфейсы ещё требуют подтверждения.
A36: PK12-B | B36: Гидравлика | C36: Гидропривод обязателен; число потребителей не принято | D36: =SUMIFS(02_Состав!I2:I139,02_Состав!A2:A139,A36,02_Состав!S2:S139,"ДА") -> 7432.51 | E36: =SUMIFS(02_Состав!L2:L139,02_Состав!A2:A139,A36,02_Состав!S2:S139,"ДА") -> 1709.47 | F36: =SUMIFS(02_Состав!N2:N139,02_Состав!A2:A139,A36,02_Состав!S2:S139,"ДА") -> 9141.98 | G36: 3 | H36: НЕПОЛНЫЙ ПАКЕТ | I36: Полная гидросистема до нужных функций всех подруливающих и всех лебёдок: насосы и выбранный привод, PTO/адаптация либо электрический или отдельный привод, бак, фильтры, охлаждение, распределители, регулирование и защита давления, трассы, местные клапаны, управление и исполнительные гидромоторы/механизмы | Выдать ведомость всех внешних потребителей и включений их пакетов: одинаковый предмет не суммировать дважды | Монтаж, промывка, чистота масла, наладка приоритетов и испытания режимов, в том числе согласованного режима без главного дизеля | Рулевое не включать в общий контур автоматически | J36: Тяга, момент, скорость, одновременность и источники мощности открыты. Измеренная компоновка, монтажные и сервисные зоны, полный состав поставки и интерфейсы ещё требуют подтверждения.
A37: PK12-C | B37: Гидравлика | C37: Гидропривод обязателен; число потребителей не принято | D37: =SUMIFS(02_Состав!I2:I139,02_Состав!A2:A139,A37,02_Состав!S2:S139,"ДА") -> 7432.51 | E37: =SUMIFS(02_Состав!L2:L139,02_Состав!A2:A139,A37,02_Состав!S2:S139,"ДА") -> 1709.47 | F37: =SUMIFS(02_Состав!N2:N139,02_Состав!A2:A139,A37,02_Состав!S2:S139,"ДА") -> 9141.98 | G37: 3 | H37: НЕПОЛНЫЙ ПАКЕТ | I37: Полная гидросистема до нужных функций всех подруливающих и всех лебёдок: насосы и выбранный привод, PTO/адаптация либо электрический или отдельный привод, бак, фильтры, охлаждение, распределители, регулирование и защита давления, трассы, местные клапаны, управление и исполнительные гидромоторы/механизмы | Выдать ведомость всех внешних потребителей и включений их пакетов: одинаковый предмет не суммировать дважды | Монтаж, промывка, чистота масла, наладка приоритетов и испытания режимов, в том числе согласованного режима без главного дизеля | Рулевое не включать в общий контур автоматически | J37: Тяга, момент, скорость, одновременность и источники мощности открыты. Измеренная компоновка, монтажные и сервисные зоны, полный состав поставки и интерфейсы ещё требуют подтверждения.
A38: Итого A | B38: Частичная компонентная оценка, не полная стоимость установки | D38: =SUMIF(A2:A37,"*-A",D2:D37) -> 105654.67 | E38: =SUMIF(A2:A37,"*-A",E2:E37) -> 24300.58 | F38: =SUMIF(A2:A37,"*-A",F2:F37) -> 135067.25
A39: Итого B | B39: Частичная компонентная оценка, не полная стоимость установки | D39: =SUMIF(A2:A37,"*-B",D2:D37) -> 78585.51 | E39: =SUMIF(A2:A37,"*-B",E2:E37) -> 18074.68 | F39: =SUMIF(A2:A37,"*-B",F2:F37) -> 160614.19
A40: Итого C | B40: Частичная компонентная оценка, не полная стоимость установки | D40: =SUMIF(A2:A37,"*-C",D2:D37) -> 59504.27 | E40: =SUMIF(A2:A37,"*-C",E2:E37) -> 13685.99 | F40: =SUMIF(A2:A37,"*-C",F2:F37) -> 78302.26

Sheet 02_Состав
A1: Вариант | B1: ID | C1: ME | D1: Исполнение | E1: Кол-во | F1: Ед. | G1: Источник | H1: NET EUR/ед. | I1: NET EUR | J1: Налог | K1: План % | L1: НДС EUR | M1: Исх.gross/ед. | N1: С налогом EUR | O1: Основание количества | P1: Открытый состав / совместимость | Q1: Дата | R1: URL | S1: В основном итоге
A2: PK01-A | B2: PK01-A-L01 | C2: ME-01|ME-02|ME-03 | D2: Volvo Penta D4-300 I + HS85A | E2: 1 | F2: package | G2: PROP-E02 | H2: 45977 | I2: =IF(AND(ISNUMBER(E2),ISNUMBER(H2)),ROUND(E2*H2,2),"") -> 45977 | J2: PL23_ESTIMATE | K2: 23 | L2: =IF(AND(J2="PL23_ESTIMATE",ISNUMBER(I2)),ROUND(I2*K2/100,2),"") -> 10574.71 | N2: =IF(J2="SOURCE_GROSS",IF(AND(ISNUMBER(E2),ISNUMBER(M2)),ROUND(E2*M2,2),""),IF(ISNUMBER(I2),ROUND(I2+L2,2),"")) -> 56551.71 | O2: Количество исходной M03; основные агрегаты без изменения | P2: 300 metric hp crank / 289 prop shaft; 3500rpm R5; 24V option price open; ratio2.500. L=433+801 W=441+407 H=274+520 from drawing; excludes projecting lifting eye/service space; not installation GA; ME-03 partial only factory mounts where included: shaft/coupling/thrust unit quantities and price OPEN | 300 metric hp crank / 289 prop shaft; 3500rpm R5; 24V option price open; ratio2.500. L=433+801 W=441+407 H=274+520 from drawing; excludes projecting lifting eye/service space; not installation GA; ME-03 partial only factory mounts where included: shaft/coupling/thrust unit quantities and price OPEN | Исключено: Исходные ограничения M03 сохранены | HISTORICAL_NET_REFERENCE|RFQ_REQUIRED|DUTY_OPEN | Q2: 2026-09-11 | R2: https://www.dbmoteurs.fr/sites/default/files/Volvo-Penta-tarifs-prix-achat-moteurs-2023-DB-Moteurs-motorisation-marine-bateau-plaisance.pdf | S2: ДА
A3: PK01-B | B3: PK01-B-L01 | C3: ME-01|ME-02 | D3: Yanmar 8LV320E-KMH50A + VC20 | E3: 1 | F3: package | G3: YAN-E01 | I3: =IF(AND(ISNUMBER(E3),ISNUMBER(H3)),ROUND(E3*H3,2),"") | J3: SOURCE_GROSS | L3: =IF(AND(J3="PL23_ESTIMATE",ISNUMBER(I3)),ROUND(I3*K3/100,2),"") | M3: 58842 | N3: =IF(J3="SOURCE_GROSS",IF(AND(ISNUMBER(E3),ISNUMBER(M3)),ROUND(E3*M3,2),""),IF(ISNUMBER(I3),ROUND(I3+L3,2),"")) -> 58842 | O3: Количество исходной M03; основные агрегаты без изменения | P3: 320 mhp / 235 kW at 3800 rpm; 1 engine + 1 KMH50A + VC20; manufacturer 2021 package dry mass 435+52 kg and envelope with gear/elbow; standard 12V starter; front belt PTO optional capacity unverified; dealer includes mounts/panel/wiring/fluids; installed propulsion scope incomplete | 320 mhp / 235 kW at 3800 rpm; 1 engine + 1 KMH50A + VC20; manufacturer 2021 package dry mass 435+52 kg and envelope with gear/elbow; standard 12V starter; front belt PTO optional capacity unverified; dealer includes mounts/panel/wiring/fluids; installed propulsion scope incomplete | Исключено: Исходные ограничения M03 сохранены | CONDITIONAL_DUTY_PTO_START_VOLTAGE; NET_RFQ_REQUIRED | Q3: 2026-09-11 | R3: https://www.abma-sneek.nl/yanmar/engines-gears-drives/powerboat-engines?prod_id=650436 | S3: ДА
A4: PK01-C | B4: PK01-C-L01 | C4: ME-01|ME-02|ME-03 | D4: FPT Industrial C90 410 rating D 300hp + gearbox RFQ | E4: 1 | F4: package | G4: PROP-E04 | I4: =IF(AND(ISNUMBER(E4),ISNUMBER(H4)),ROUND(E4*H4,2),"") | J4: PL23_ESTIMATE | K4: 23 | L4: =IF(AND(J4="PL23_ESTIMATE",ISNUMBER(I4)),ROUND(I4*K4/100,2),"") | N4: =IF(J4="SOURCE_GROSS",IF(AND(ISNUMBER(E4),ISNUMBER(M4)),ROUND(E4*M4,2),""),IF(ISNUMBER(I4),ROUND(I4+L4,2),"")) | O4: Количество исходной M03; основные агрегаты без изменения | P4: Official2026 220kW300hp@2000rpm ratingD heavy duty; gearbox unselected/unpriced; shown dimensions length to flywheel and mass ENGINE ONLY; not complete package envelope;24V option RFQ; ME-03 partial only factory mounts where included: shaft/coupling/thrust unit quantities and price OPEN | Official2026 220kW300hp@2000rpm ratingD heavy duty; gearbox unselected/unpriced; shown dimensions length to flywheel and mass ENGINE ONLY; not complete package envelope;24V option RFQ; ME-03 partial only factory mounts where included: shaft/coupling/thrust unit quantities and price OPEN | Исключено: Исходные ограничения M03 сохранены | RFQ_REQUIRED|INCOMPLETE_PACKAGE|DUTY_COMPARISON_OPEN | Q4: 2026-09-11 | R4: https://www.etruck.fi/shop-1 | S4: ДА
A5: PK02-A | B5: PK02-A-L01 | C5: ME-04|ME-19 | D5: Volpi Tecno Energia Paguro12000V AP12023050M0 | E5: 2 | F5: package | G5: PROP-G03 | H5: 12446.5 | I5: =IF(AND(ISNUMBER(E5),ISNUMBER(H5)),ROUND(E5*H5,2),"") -> 24893 | J5: PL23_ESTIMATE | K5: 23 | L5: =IF(AND(J5="PL23_ESTIMATE",ISNUMBER(I5)),ROUND(I5*K5/100,2),"") -> 5725.39 | N5: =IF(J5="SOURCE_GROSS",IF(AND(ISNUMBER(E5),ISNUMBER(M5)),ROUND(E5*M5,2),""),IF(ISNUMBER(I5),ROUND(I5+L5,2),"")) -> 30618.39 | O5: Количество исходной M03; основные агрегаты без изменения | P5: 12kVA10kW continuous50Hz230V;12V starter;mass165capsule+15control electronics. Official dimensions capsule only; separate electronics footprint RFQ. Dealer/allpa dimensions/mass differ; exact SKU installationdrawing required. Published net directly not Polish VAT assumption; ME-19 partial factory cooling only: external seawater/exhaust runs and installation OPEN | 12kVA10kW continuous50Hz230V;12V starter;mass165capsule+15control electronics. Official dimensions capsule only; separate electronics footprint RFQ. Dealer/allpa dimensions/mass differ; exact SKU installationdrawing required. Published net directly not Polish VAT assumption; ME-19 partial factory cooling only: external seawater/exhaust runs and installation OPEN | Исключено: Исходные ограничения M03 сохранены | CONDITIONAL_START_VOLTAGE|AC_COMPATIBILITY_OPEN|REVISION_OPEN | Q5: 2026-09-11 | R5: https://www.manelservice.com/it/gruppi-elettrogeni-marini/3925-vte-paguro-12000-v-ap12023050m0.html | S5: ДА
A6: PK02-B | B6: PK02-B-L01 | C6: ME-04|ME-19 | D6: Fischer Panda 12000x-230V PMS NautiRadar0028284 | E6: 2 | F6: package | G6: PAN-G02 | H6: 17451.22 | I6: =IF(AND(ISNUMBER(E6),ISNUMBER(H6)),ROUND(E6*H6,2),"") -> 34902.44 | J6: PL23_ESTIMATE | K6: 23 | L6: =IF(AND(J6="PL23_ESTIMATE",ISNUMBER(I6)),ROUND(I6*K6/100,2),"") -> 8027.56 | N6: =IF(J6="SOURCE_GROSS",IF(AND(ISNUMBER(E6),ISNUMBER(M6)),ROUND(E6*M6,2),""),IF(ISNUMBER(I6),ROUND(I6+L6,2),"")) -> 42930 | O6: Количество исходной M03; основные агрегаты без изменения | P6: 50Hz230V not yet accepted as220V target;2generators retained;standard datasheet12Vstarter, priced24V SKU unconfirmed. 10.2kW/12kVA NOMINAL at20C;2026catalogue treats0.85 kVA factor as short inductive starting only;hot continuous useful output OPEN. Capsule dimensions exclude fittings and service space;ME19 partial factory cooling only. SellerSKU0028284 vsOEMsheet0024660:exact revision must be tied to offer. EU seller does not yet prove EU dispatch/free-circulation/Poland delivery. | 50Hz230V not yet accepted as220V target;2generators retained;standard datasheet12Vstarter, priced24V SKU unconfirmed. 10.2kW/12kVA NOMINAL at20C;2026catalogue treats0.85 kVA factor as short inductive starting only;hot continuous useful output OPEN. Capsule dimensions exclude fittings and service space;ME19 partial factory cooling only. SellerSKU0028284 vsOEMsheet0024660:exact revision must be tied to offer. EU seller does not yet prove EU dispatch/free-circulation/Poland delivery. | Исключено: Исходные ограничения M03 сохранены | MARKET_REFERENCE|START24V_OPEN|HOT_OUTPUT_OPEN|SKU_REVISION_OPEN | Q6: 2026-09-11 | R6: https://www.nautiradar.pt/en/products/fischer-panda/panda-12000x-230v-pms-12kva-fixed-engine-speed-marine-generator | S6: ДА
A7: PK02-C | B7: PK02-C-L01 | C7: ME-04|ME-19 | D7: Kohler / Rehlko 12EFKOZD | E7: 2 | F7: package | G7: PROP-G02 | H7: 17929.12 | I7: =IF(AND(ISNUMBER(E7),ISNUMBER(H7)),ROUND(E7*H7,2),"") -> 35858.24 | J7: PL23_ESTIMATE | K7: 23 | L7: =IF(AND(J7="PL23_ESTIMATE",ISNUMBER(I7)),ROUND(I7*K7/100,2),"") -> 8247.4 | N7: =IF(J7="SOURCE_GROSS",IF(AND(ISNUMBER(E7),ISNUMBER(M7)),ROUND(E7*M7,2),""),IF(ISNUMBER(I7),ROUND(I7+L7,2),"")) -> 44105.64 | O7: Количество исходной M03; основные агрегаты без изменения | P7: Singlephase115/230V50Hz:12kW12kVA continuous140C rise;11/11continuous115C;10.5/10.5prime. Official12or24V; JPC exactstarter/shield revision RFQ. Official shield mass385dry398wet; dealer406kg conflict. No borrowing US24V price scope; ME-19 partial factory cooling only: external seawater/exhaust runs and installation OPEN | Singlephase115/230V50Hz:12kW12kVA continuous140C rise;11/11continuous115C;10.5/10.5prime. Official12or24V; JPC exactstarter/shield revision RFQ. Official shield mass385dry398wet; dealer406kg conflict. No borrowing US24V price scope; ME-19 partial factory cooling only: external seawater/exhaust runs and installation OPEN | Исключено: Исходные ограничения M03 сохранены | CONDITIONAL_CONFIGURATION|AC_COMPATIBILITY_OPEN|RATING_OPEN|UK_REFERENCE | Q7: 2026-09-11 | R7: https://www.jpcdirect.com/product/kohler-12-kilowatt-generator/ | S7: ДА
A8: PK03-A | B8: PK03-A-L01 | C8: ME-05 | D8: Victron MultiPlus-II 24/3000/70-32 PMP242305010 | E8: 2 | F8: pcs | G8: EL-INV-A | H8: 739.45 | I8: =IF(AND(ISNUMBER(E8),ISNUMBER(H8)),ROUND(E8*H8,2),"") -> 1478.9 | J8: PL23_ESTIMATE | K8: 23 | L8: =IF(AND(J8="PL23_ESTIMATE",ISNUMBER(I8)),ROUND(I8*K8/100,2),"") -> 340.15 | N8: =IF(J8="SOURCE_GROSS",IF(AND(ISNUMBER(E8),ISNUMBER(M8)),ROUND(E8*M8,2),""),IF(ISNUMBER(I8),ROUND(I8+L8,2),"")) -> 1819.05 | O8: Количество исходной M03; основные агрегаты без изменения | P8: 24 V input; factory 230 V. 3000 VA not 3000 W: 2400 W at25C/2200 W at40C; charger70 A. 2 devices architecture target, capacity unapproved. | 24 V input; factory 230 V. 3000 VA not 3000 W: 2400 W at25C/2200 W at40C; charger70 A. 2 devices architecture target, capacity unapproved. | Исключено: Исходные ограничения M03 сохранены | CONDITIONAL_3KVA_REFERENCE | Q8: 2026-09-11 | R8: https://www.svb.de/de/victron-wechselrichter-ladegeraet-multiplus-ii-24-v-3000-va-70-a.html | S8: ДА
A9: PK03-A | B9: PK03-A-L02 | C9: ME-09 | D9: Victron 3600 ITR040362042 | E9: 1 | F9: pcs | G9: EL-ISO-A | H9: 436.93 | I9: =IF(AND(ISNUMBER(E9),ISNUMBER(H9)),ROUND(E9*H9,2),"") -> 436.93 | J9: PL23_ESTIMATE | K9: 23 | L9: =IF(AND(J9="PL23_ESTIMATE",ISNUMBER(I9)),ROUND(I9*K9/100,2),"") -> 100.49 | N9: =IF(J9="SOURCE_GROSS",IF(AND(ISNUMBER(E9),ISNUMBER(M9)),ROUND(E9*M9,2),""),IF(ISNUMBER(I9),ROUND(I9+L9,2),"")) -> 537.42 | O9: ПРЕДВАРИТЕЛЬНЫЙ СЦЕНАРИЙ M09: один береговой ввод, один разделительный трансформатор; не утверждённое количество закупки. | P9: 3.6 class; quantity and shore capacity unknown. Dimensions/mass from opened dealer data pending native drawing confirmation; no substitute of32A at115V for32A at230V. | 3.6 class; quantity and shore capacity unknown. Dimensions/mass from opened dealer data pending native drawing confirmation; no substitute of32A at115V for32A at230V. | Исключено: Исходные ограничения M03 сохранены | CONDITIONAL_UNIT_BENCHMARK_DIMENSIONS_DEALER | Q9: 2026-09-11 | R9: https://www.svb24.com/en/p/victron-isolation-transformer-3600-w-115-230-v.html | S9: ДА
A10: PK03-B | B10: PK03-B-L01 | C10: ME-05 | D10: Victron MultiPlus-II GX 24/3000/70-32 PMP242306000 | E10: 2 | F10: pcs | G10: EL-INV-B | H10: 840.29 | I10: =IF(AND(ISNUMBER(E10),ISNUMBER(H10)),ROUND(E10*H10,2),"") -> 1680.58 | J10: PL23_ESTIMATE | K10: 23 | L10: =IF(AND(J10="PL23_ESTIMATE",ISNUMBER(I10)),ROUND(I10*K10/100,2),"") -> 386.53 | N10: =IF(J10="SOURCE_GROSS",IF(AND(ISNUMBER(E10),ISNUMBER(M10)),ROUND(E10*M10,2),""),IF(ISNUMBER(I10),ROUND(I10+L10,2),"")) -> 2067.11 | O10: Количество исходной M03; основные агрегаты без изменения | P10: 24 V; factory230 V;2400 W at25C/2200 W at40C;70 A. GX monitoring differs; two GX units not required by yacht specification. Current manual geometry differs from catalogue: confirm revision. | 24 V; factory230 V;2400 W at25C/2200 W at40C;70 A. GX monitoring differs; two GX units not required by yacht specification. Current manual geometry differs from catalogue: confirm revision. | Исключено: Исходные ограничения M03 сохранены | CONDITIONAL_3KVA_REFERENCE | Q10: 2026-09-11 | R10: https://www.svb.de/de/victron-wechselrichter-ladegeraet-multiplus-ii-gx-24-v-3000-va-70-a.html | S10: ДА
A11: PK03-B | B11: PK03-B-L02 | C11: ME-09 | D11: Mastervolt Mass GI3.5 88000355 | E11: 1 | F11: pcs | G11: EL-ISO-B | H11: 1008.36 | I11: =IF(AND(ISNUMBER(E11),ISNUMBER(H11)),ROUND(E11*H11,2),"") -> 1008.36 | J11: PL23_ESTIMATE | K11: 23 | L11: =IF(AND(J11="PL23_ESTIMATE",ISNUMBER(I11)),ROUND(I11*K11/100,2),"") -> 231.92 | N11: =IF(J11="SOURCE_GROSS",IF(AND(ISNUMBER(E11),ISNUMBER(M11)),ROUND(E11*M11,2),""),IF(ISNUMBER(I11),ROUND(I11+L11,2),"")) -> 1240.28 | O11: ПРЕДВАРИТЕЛЬНЫЙ СЦЕНАРИЙ M09: один береговой ввод, один разделительный трансформатор; не утверждённое количество закупки. | P11: 3500 VA at230 V;16 A;HF technology;source IP23 supersedes dealer IP21. Not complete shore protection. | 3500 VA at230 V;16 A;HF technology;source IP23 supersedes dealer IP21. Not complete shore protection. | Исключено: Исходные ограничения M03 сохранены | CONDITIONAL_UNIT_BENCHMARK | Q11: 2026-09-11 | R11: https://www.svb24.com/en/mastervolt-mass-gi-3-5-isolation-transformer-16-a-3-5-kw.html | S11: ДА
A12: PK03-C | B12: PK03-C-L01 | C12: ME-05 | D12: Mastervolt CombiMaster 24/3000-60 230V 35023000 | E12: 2 | F12: pcs | G12: EL-INV-C | H12: 1344.5 | I12: =IF(AND(ISNUMBER(E12),ISNUMBER(H12)),ROUND(E12*H12,2),"") -> 2689 | J12: PL23_ESTIMATE | K12: 23 | L12: =IF(AND(J12="PL23_ESTIMATE",ISNUMBER(I12)),ROUND(I12*K12/100,2),"") -> 618.47 | N12: =IF(J12="SOURCE_GROSS",IF(AND(ISNUMBER(E12),ISNUMBER(M12)),ROUND(E12*M12,2),""),IF(ISNUMBER(I12),ROUND(I12+L12,2),"")) -> 3307.47 | O12: Количество исходной M03; основные агрегаты без изменения | P12: 24 V; factory230 V;3000 VA/2600 W at40C;60 A charger;25 A transfer versus32 A Victron. Parallel operation not qualified. | 24 V; factory230 V;3000 VA/2600 W at40C;60 A charger;25 A transfer versus32 A Victron. Parallel operation not qualified. | Исключено: Исходные ограничения M03 сохранены | CONDITIONAL_3KVA_NOT_EQUAL_W | Q12: 2026-09-11 | R12: https://www.svb.de/de/mastervolt-wechselrichter-ladegeraet-combimaster-24-v-3000-va-60-a.html?question_sort=oldest | S12: ДА
A13: PK03-C | B13: PK03-C-L02 | C13: ME-09 | D13: Mastervolt Mass GI3.5 88000355 | E13: 1 | F13: pcs | G13: EL-ISO-B | H13: 1008.36 | I13: =IF(AND(ISNUMBER(E13),ISNUMBER(H13)),ROUND(E13*H13,2),"") -> 1008.36 | J13: PL23_ESTIMATE | K13: 23 | L13: =IF(AND(J13="PL23_ESTIMATE",ISNUMBER(I13)),ROUND(I13*K13/100,2),"") -> 231.92 | N13: =IF(J13="SOURCE_GROSS",IF(AND(ISNUMBER(E13),ISNUMBER(M13)),ROUND(E13*M13,2),""),IF(ISNUMBER(I13),ROUND(I13+L13,2),"")) -> 1240.28 | O13: ПРЕДВАРИТЕЛЬНЫЙ СЦЕНАРИЙ M09: один береговой ввод, один разделительный трансформатор; не утверждённое количество закупки. | P13: 3500 VA at230 V;16 A;HF technology;source IP23 supersedes dealer IP21. Not complete shore protection. | 3500 VA at230 V;16 A;HF technology;source IP23 supersedes dealer IP21. Not complete shore protection. | Исключено: Исходные ограничения M03 сохранены | CONDITIONAL_UNIT_BENCHMARK | Q13: 2026-09-11 | R13: https://www.svb24.com/en/mastervolt-mass-gi-3-5-isolation-transformer-16-a-3-5-kw.html | S13: ДА
A14: PK04-A | B14: PK04-A-L01 | C14: ME-08 | D14: Exide ER550 12V115Ah | E14: 6 | F14: pcs | G14: EL-BAT-A | H14: 140.24 | I14: =IF(AND(ISNUMBER(E14),ISNUMBER(H14)),ROUND(E14*H14,2),"") -> 841.44 | J14: PL23_ESTIMATE | K14: 23 | L14: =IF(AND(J14="PL23_ESTIMATE",ISNUMBER(I14)),ROUND(I14*K14/100,2),"") -> 193.53 | N14: =IF(J14="SOURCE_GROSS",IF(AND(ISNUMBER(E14),ISNUMBER(M14)),ROUND(E14*M14,2),""),IF(ISNUMBER(I14),ROUND(I14+L14,2),"")) -> 1034.97 | O14: Количество исходной M03; основные агрегаты без изменения | P14: Flooded. Owner only said115 amperes; Ah and unit voltage unconfirmed. 6 physical units; no bank wiring/capacity inferred. Deposit extra. Dealer350mm/29kg differs from brochure. | Flooded. Owner only said115 amperes; Ah and unit voltage unconfirmed. 6 physical units; no bank wiring/capacity inferred. Deposit extra. Dealer350mm/29kg differs from brochure. | Исключено: Исходные ограничения M03 сохранены | CONDITIONAL_115AH12V_NOT_OWNER_APPROVED | Q14: 2026-09-11 | R14: https://online-batterien.de/a/exide-er550-dual-versorgungsbatterie-starterbatterie-12v-115ah-550wh/400440 | S14: ДА
A15: PK04-A | B15: PK04-A-L02 | C15: ME-07 | D15: Vetus SMF 125 Ah 12 V, стартерный кандидат | E15: 1 | F15: pcs | G15: EL-02 | H15: 193.24 | I15: =IF(AND(ISNUMBER(E15),ISNUMBER(H15)),ROUND(E15*H15,2),"") -> 193.24 | J15: PL23_ESTIMATE | K15: 23 | L15: =IF(AND(J15="PL23_ESTIMATE",ISNUMBER(I15)),ROUND(I15*K15/100,2),"") -> 44.45 | N15: =IF(J15="SOURCE_GROSS",IF(AND(ISNUMBER(E15),ISNUMBER(M15)),ROUND(E15*M15,2),""),IF(ISNUMBER(I15),ROUND(I15+L15,2),"")) -> 237.69 | O15: Количество исходной M03; основные агрегаты без изменения | P15: Подстановка M09 вместо EL-OPEN-MAIN. Прежнее описание относится к старому SKU и сохранено в M03. | Одна физическая стартерная батарея. | Исключено: Крепление, кабели, зарядка, доставка перевозчиком. | Только условный 12 V кандидат. OEM двигателя должен подтвердить напряжение/CCA; не образует принятую 24 V схему. Паспорт VESMF125: 950 A EN. | Q15: 2026-09-15 | R15: https://www.svb24.com/en/vetus-boat-battery-60-ah-to-230-ah.html | S15: ДА
A16: PK04-A | B16: PK04-A-L03 | C16: ME-27 | D16: Vetus SMF 70 Ah 12 V, генераторный кандидат | E16: 2 | F16: pcs | G16: EL-03 | H16: 111.34 | I16: =IF(AND(ISNUMBER(E16),ISNUMBER(H16)),ROUND(E16*H16,2),"") -> 222.68 | J16: PL23_ESTIMATE | K16: 23 | L16: =IF(AND(J16="PL23_ESTIMATE",ISNUMBER(I16)),ROUND(I16*K16/100,2),"") -> 51.22 | N16: =IF(J16="SOURCE_GROSS",IF(AND(ISNUMBER(E16),ISNUMBER(M16)),ROUND(E16*M16,2),""),IF(ISNUMBER(I16),ROUND(I16+L16,2),"")) -> 273.9 | O16: Количество исходной M03; основные агрегаты без изменения | P16: Подстановка M09 вместо EL-OPEN-GEN. Прежнее описание относится к старому SKU и сохранено в M03. | Две физические батареи, цена за одну. | Исключено: Крепления, кабели, зарядка, доставка. | Условные 12 V / 640 A EN; соответствие двум выбранным генераторам открыто. Не добавлять сверх 6+2+1. | Q16: 2026-09-15 | R16: https://www.svb24.com/en/vetus-boat-battery-60-ah-to-230-ah.html | S16: ДА
... A26: PK05-A | B26: PK05-A-L01 | C26: ME-11 | D26: CEM OSC-16.062.24 / OEM identity reconcile | E26: 1 | F26: шт | G26: WC-DC-01 | H26: 1024.92 | I26: =IF(AND(ISNUMBER(E26),ISNUMBER(H26)),ROUND(E26*H26,2),"") -> 1024.92 | J26: PL23_ESTIMATE | K26: 23 | L26: =IF(AND(J26="PL23_ESTIMATE",ISNUMBER(I26)),ROUND(I26*K26/100,2),"") -> 235.73 | N26: =IF(J26="SOURCE_GROSS",IF(AND(ISNUMBER(E26),ISNUMBER(M26)),ROUND(E26*M26,2),""),IF(ISNUMBER(I26),ROUND(I26+L26,2),"")) -> 1260.65 | O26: Количество исходной M03; основные агрегаты без изменения | P26: 24V20L accumulator; dealer50L/min max; source model mapping not proven. Common proposed test15L/min at2bar NOT verified. Do not add included tank again. | 24V20L accumulator; dealer50L/min max; source model mapping not proven. Common proposed test15L/min at2bar NOT verified. Do not add included tank again. | Исключено: Исходные ограничения M03 сохранены | WORKING_POINT_AND_OEM_ID_OPEN | Q26: 2026-09-11 | R26: https://www.comptoirnautique.com/groupe-d-eau-a-pressostat/53022-cem-elettromeccanica-autoclave-cem-vase-expansion-inox-20l-24v-50-l-min.html | S26: ДА
