Workbook

Sheet 00_Итог
A1: Пакет | B1: Система | C1: Известная NET EUR | D1: НДС выделен / расчёт EUR | E1: Оценено с НДС EUR | F1: Строк без суммы | G1: Статус | H1: Примечание
A2: PK01 | B2: Ход яхты | C2: =IF(COUNT(01_Смета!J2,01_Смета!J27)=0,"",SUM(01_Смета!J2,01_Смета!J27)) | D2: =IF(COUNT(01_Смета!M2,01_Смета!M27)=0,"",SUM(01_Смета!M2,01_Смета!M27)) | E2: =IF(COUNT(01_Смета!O2,01_Смета!O27)=0,"",SUM(01_Смета!O2,01_Смета!O27)) -> 58842 | F2: 1 | G2: НЕПОЛНЫЙ | H2: Цена оборудования и компонента не закрывает установочный пакет
A3: PK02 | B3: Генерация | C3: =IF(COUNT(01_Смета!J3)=0,"",SUM(01_Смета!J3)) -> 34902.44 | D3: =IF(COUNT(01_Смета!M3)=0,"",SUM(01_Смета!M3)) -> 8027.56 | E3: =IF(COUNT(01_Смета!O3)=0,"",SUM(01_Смета!O3)) -> 42930 | F3: 0 | G3: НЕПОЛНЫЙ | H3: Цена оборудования и компонента не закрывает установочный пакет
A4: PK03 | B4: Электропитание | C4: =IF(COUNT(01_Смета!J4,01_Смета!J5,01_Смета!J28,01_Смета!J29)=0,"",SUM(01_Смета!J4,01_Смета!J5,01_Смета!J28,01_Смета!J29)) -> 1680.58 | D4: =IF(COUNT(01_Смета!M4,01_Смета!M5,01_Смета!M28,01_Смета!M29)=0,"",SUM(01_Смета!M4,01_Смета!M5,01_Смета!M28,01_Смета!M29)) -> 386.53 | E4: =IF(COUNT(01_Смета!O4,01_Смета!O5,01_Смета!O28,01_Смета!O29)=0,"",SUM(01_Смета!O4,01_Смета!O5,01_Смета!O28,01_Смета!O29)) -> 2067.11 | F4: 3 | G4: НЕПОЛНЫЙ | H4: Цена оборудования и компонента не закрывает установочный пакет
A5: PK04 | B5: АКБ и резервный пуск | C5: =IF(COUNT(01_Смета!J6,01_Смета!J7,01_Смета!J8,01_Смета!J9)=0,"",SUM(01_Смета!J6,01_Смета!J7,01_Смета!J8,01_Смета!J9)) -> 1608.42 | D5: =IF(COUNT(01_Смета!M6,01_Смета!M7,01_Смета!M8,01_Смета!M9)=0,"",SUM(01_Смета!M6,01_Смета!M7,01_Смета!M8,01_Смета!M9)) -> 369.94 | E5: =IF(COUNT(01_Смета!O6,01_Смета!O7,01_Смета!O8,01_Смета!O9)=0,"",SUM(01_Смета!O6,01_Смета!O7,01_Смета!O8,01_Смета!O9)) -> 1978.36 | F5: 3 | G5: НЕПОЛНЫЙ | H5: Цена оборудования и компонента не закрывает установочный пакет
A6: PK05 | B6: Пресная вода | C6: =IF(COUNT(01_Смета!J10,01_Смета!J11,01_Смета!J30)=0,"",SUM(01_Смета!J10,01_Смета!J11,01_Смета!J30)) -> 2145.75 | D6: =IF(COUNT(01_Смета!M10,01_Смета!M11,01_Смета!M30)=0,"",SUM(01_Смета!M10,01_Смета!M11,01_Смета!M30)) -> 493.53 | E6: =IF(COUNT(01_Смета!O10,01_Смета!O11,01_Смета!O30)=0,"",SUM(01_Смета!O10,01_Смета!O11,01_Смета!O30)) -> 2639.28 | F6: 1 | G6: НЕПОЛНЫЙ | H6: Цена оборудования и компонента не закрывает установочный пакет
A7: PK06 | B7: Опреснение | C7: =IF(COUNT(01_Смета!J12)=0,"",SUM(01_Смета!J12)) -> 10683.5 | D7: =IF(COUNT(01_Смета!M12)=0,"",SUM(01_Смета!M12)) -> 2457.21 | E7: =IF(COUNT(01_Смета!O12)=0,"",SUM(01_Смета!O12)) -> 13140.71 | F7: 0 | G7: НЕПОЛНЫЙ | H7: Цена оборудования и компонента не закрывает установочный пакет
A8: PK07 | B8: Горячая вода | C8: =IF(COUNT(01_Смета!J13)=0,"",SUM(01_Смета!J13)) | D8: =IF(COUNT(01_Смета!M13)=0,"",SUM(01_Смета!M13)) | E8: =IF(COUNT(01_Смета!O13)=0,"",SUM(01_Смета!O13)) | F8: 1 | G8: НЕПОЛНЫЙ | H8: Цена оборудования и компонента не закрывает установочный пакет
A9: PK08 | B9: Климат | C9: =IF(COUNT(01_Смета!J14,01_Смета!J15,01_Смета!J31)=0,"",SUM(01_Смета!J14,01_Смета!J15,01_Смета!J31)) -> 8310.6 | D9: =IF(COUNT(01_Смета!M14,01_Смета!M15,01_Смета!M31)=0,"",SUM(01_Смета!M14,01_Смета!M15,01_Смета!M31)) -> 1911.44 | E9: =IF(COUNT(01_Смета!O14,01_Смета!O15,01_Смета!O31)=0,"",SUM(01_Смета!O14,01_Смета!O15,01_Смета!O31)) -> 10222.04 | F9: 2 | G9: НЕПОЛНЫЙ | H9: Цена оборудования и компонента не закрывает установочный пакет
A10: PK09 | B10: Обеспечение МО | C10: =IF(COUNT(01_Смета!J16,01_Смета!J17,01_Смета!J18,01_Смета!J19)=0,"",SUM(01_Смета!J16,01_Смета!J17,01_Смета!J18,01_Смета!J19)) | D10: =IF(COUNT(01_Смета!M16,01_Смета!M17,01_Смета!M18,01_Смета!M19)=0,"",SUM(01_Смета!M16,01_Смета!M17,01_Смета!M18,01_Смета!M19)) | E10: =IF(COUNT(01_Смета!O16,01_Смета!O17,01_Смета!O18,01_Смета!O19)=0,"",SUM(01_Смета!O16,01_Смета!O17,01_Смета!O18,01_Смета!O19)) | F10: 4 | G10: НЕПОЛНЫЙ | H10: Цена оборудования и компонента не закрывает установочный пакет
A11: PK10 | B11: Аварийные системы | C11: =IF(COUNT(01_Смета!J20,01_Смета!J21,01_Смета!J22,01_Смета!J23)=0,"",SUM(01_Смета!J20,01_Смета!J21,01_Смета!J22,01_Смета!J23)) | D11: =IF(COUNT(01_Смета!M20,01_Смета!M21,01_Смета!M22,01_Смета!M23)=0,"",SUM(01_Смета!M20,01_Смета!M21,01_Смета!M22,01_Смета!M23)) | E11: =IF(COUNT(01_Смета!O20,01_Смета!O21,01_Смета!O22,01_Смета!O23)=0,"",SUM(01_Смета!O20,01_Смета!O21,01_Смета!O22,01_Смета!O23)) | F11: 4 | G11: НЕПОЛНЫЙ | H11: Цена оборудования и компонента не закрывает установочный пакет
A12: PK11 | B12: Танки и стоки | C12: =IF(COUNT(01_Смета!J24,01_Смета!J25)=0,"",SUM(01_Смета!J24,01_Смета!J25)) | D12: =IF(COUNT(01_Смета!M24,01_Смета!M25)=0,"",SUM(01_Смета!M24,01_Смета!M25)) | E12: =IF(COUNT(01_Смета!O24,01_Смета!O25)=0,"",SUM(01_Смета!O24,01_Смета!O25)) | F12: 2 | G12: НЕПОЛНЫЙ | H12: Цена оборудования и компонента не закрывает установочный пакет
A13: PK12 | B13: Гидравлика | C13: =IF(COUNT(01_Смета!J26)=0,"",SUM(01_Смета!J26)) | D13: =IF(COUNT(01_Смета!M26)=0,"",SUM(01_Смета!M26)) | E13: =IF(COUNT(01_Смета!O26)=0,"",SUM(01_Смета!O26)) | F13: 1 | G13: НЕПОЛНЫЙ | H13: Цена оборудования и компонента не закрывает установочный пакет
A14: ADD | B14: Монтаж и внешние затраты | C14: =IF(COUNT(01_Смета!J32,01_Смета!J33,01_Смета!J34,01_Смета!J35,01_Смета!J36,01_Смета!J37,01_Смета!J38,01_Смета!J39)=0,"",SUM(01_Смета!J32,01_Смета!J33,01_Смета!J34,01_Смета!J35,01_Смета!J36,01_Смета!J37,01_Смета!J38,01_Смета!J39)) | D14: =IF(COUNT(01_Смета!M32,01_Смета!M33,01_Смета!M34,01_Смета!M35,01_Смета!M36,01_Смета!M37,01_Смета!M38,01_Смета!M39)=0,"",SUM(01_Смета!M32,01_Смета!M33,01_Смета!M34,01_Смета!M35,01_Смета!M36,01_Смета!M37,01_Смета!M38,01_Смета!M39)) | E14: =IF(COUNT(01_Смета!O32,01_Смета!O33,01_Смета!O34,01_Смета!O35,01_Смета!O36,01_Смета!O37,01_Смета!O38,01_Смета!O39)=0,"",SUM(01_Смета!O32,01_Смета!O33,01_Смета!O34,01_Смета!O35,01_Смета!O36,01_Смета!O37,01_Смета!O38,01_Смета!O39)) | F14: 8 | G14: НЕПОЛНЫЙ | H14: Цена оборудования и компонента не закрывает установочный пакет
B15: ОЦЕНЁННАЯ ЧАСТЬ — НЕ ПОЛНАЯ СТОИМОСТЬ | C15: =SUM(C2:C14) -> 59331.29 | D15: =SUM(D2:D14) -> 13646.21 | E15: =SUM(E2:E14) -> 131819.5 | F15: 30
B16: Статус | C16: M07/v001 — выпуск текущей рабочей сметы по имеющимся сведениям. Не утверждённая УТВ, не заказ, не полный бюджет установленного МО.
B17: НДС в строках | C17: По уточнению владельца23% включены предварительно для известныхNET; SOURCE_GROSS уже сналогом, без повторного начисления. Налоговый вычет не применён.
B18: Смешанный gross | C18: Yanmar58842EUR включает налог неизвестнойставки. Его NET/VATневыделены. Общая оценённаяgrossсумма не единая унифицированная польская налоговая база и не график платежей.
B19: Открытые затраты | C19: Нулевых цен для неизвестного нет. Пустые количества/стоимости требуютданных; полныйитог незадан. Монтаж/материалы/трассы/таможня/ПНР не закрыты.
B20: Варианты | C20: Рабочая ветвьB сохранена изM03: Yanmar/Panda. Это не выбор закупки и не средний ценовойранг. A/C показаны в отдельном сравнении; альтернативы не складываются.
B21: Размещение | C21: По поручению владельца дальнейшаякомпоновка по сечениям проекта отдельно; G03не блокирует фиксациюэтогосостояниясметы и не подтверждает fit.
B22: Предыдущие версии | C22: U01/M01–M06/G03/EXP003 сохранены; сметные числа не перенесены в утверждённыйбюджет.
B23: Резерв | C23: Процент риска, накладных и установкиневыдуман. Неоценённыеработы не компенсированы произвольнойнадбавкой.

Sheet 01_Смета
A1: Строка | B1: Пакет | C1: Группы M01 | D1: Вид затрат | E1: Количество | F1: Ед. | G1: Наименование / исполнение | H1: Источник ID | I1: Цена NET EUR/ед. | J1: Стоимость NET EUR | K1: Основание НДС | L1: НДС % предварит. | M1: Сумма НДС EUR | N1: Исходный gross EUR/ед. | O1: Стоимость с НДС EUR | P1: Комплектность | Q1: Статус цены | R1: Примечание / исключения | S1: Прямая ссылка | T1: Цена в источнике | U1: Валюта источника
A2: PK01-B-L01 | B2: PK01 | C2: ME-01|ME-02 | D2: Оборудование / компонент | E2: 1 | F2: package | G2: Yanmar 8LV320E-KMH50A + VC20 | H2: YAN-E01 | J2: =IF(AND(ISNUMBER(E2),ISNUMBER(I2)),ROUND(E2*I2,2),"") | K2: SOURCE_GROSS | M2: =IF(AND(K2="PL23_ESTIMATE",ISNUMBER(J2),ISNUMBER(L2)),ROUND(J2*L2/100,2),"") | N2: 58842 | O2: =IF(K2="SOURCE_GROSS",IF(AND(ISNUMBER(E2),ISNUMBER(N2)),ROUND(E2*N2,2),""),IF(AND(ISNUMBER(J2),ISNUMBER(M2)),ROUND(J2+M2,2),"")) -> 58842 | P2: OPEN | Q2: NO_VERIFIED_NET | R2: 320 mhp / 235 kW at 3800 rpm; 1 engine + 1 KMH50A + VC20; manufacturer 2021 package dry mass 435+52 kg and envelope with gear/elbow; standard 12V starter; front belt PTO optional capacity unverified; dealer includes mounts/panel/wiring/fluids; installed propulsion scope incomplete | Исходный gross включает налог неизвестной ставки; без повторного23%. NET и выделенныйVAT открыты. | S2: https://www.abma-sneek.nl/yanmar/engines-gears-drives/powerboat-engines?prod_id=650436 | T2: 58842 | U2: EUR
A3: PK02-B-L01 | B3: PK02 | C3: ME-04|ME-19 | D3: Оборудование / компонент | E3: 2 | F3: package | G3: Fischer Panda 12000x-230V PMS NautiRadar0028284 | H3: PAN-G02 | I3: 17451.22 | J3: =IF(AND(ISNUMBER(E3),ISNUMBER(I3)),ROUND(E3*I3,2),"") -> 34902.44 | K3: PL23_ESTIMATE | L3: 23 | M3: =IF(AND(K3="PL23_ESTIMATE",ISNUMBER(J3),ISNUMBER(L3)),ROUND(J3*L3/100,2),"") -> 8027.56 | O3: =IF(K3="SOURCE_GROSS",IF(AND(ISNUMBER(E3),ISNUMBER(N3)),ROUND(E3*N3,2),""),IF(AND(ISNUMBER(J3),ISNUMBER(M3)),ROUND(J3+M3,2),"")) -> 42930 | P3: OPEN | Q3: OBSERVED_NET_CONDITIONAL_SCOPE | R3: 50Hz230V not yet accepted as220V target;2generators retained;standard datasheet12Vstarter, priced24V SKU unconfirmed. 10.2kW/12kVA NOMINAL at20C;2026catalogue treats0.85 kVA factor as short inductive starting only;hot continuous useful output OPEN. Capsule dimensions exclude fittings and service space;ME19 partial factory cooling only. SellerSKU0028284 vsOEMsheet0024660:exact revision must be tied to offer. EU seller does not yet prove EU dispatch/free-circulation/Poland delivery. | НДС23% предварительно по поручению владельца; не установленный режим сделки. | S3: https://www.nautiradar.pt/en/products/fischer-panda/panda-12000x-230v-pms-12kva-fixed-engine-speed-marine-generator | T3: 17451.22 | U3: EUR
A4: PK03-B-L01 | B4: PK03 | C4: ME-05 | D4: Оборудование / компонент | E4: 2 | F4: pcs | G4: Victron MultiPlus-II GX 24/3000/70-32 PMP242306000 | H4: EL-INV-B | I4: 840.29 | J4: =IF(AND(ISNUMBER(E4),ISNUMBER(I4)),ROUND(E4*I4,2),"") -> 1680.58 | K4: PL23_ESTIMATE | L4: 23 | M4: =IF(AND(K4="PL23_ESTIMATE",ISNUMBER(J4),ISNUMBER(L4)),ROUND(J4*L4/100,2),"") -> 386.53 | O4: =IF(K4="SOURCE_GROSS",IF(AND(ISNUMBER(E4),ISNUMBER(N4)),ROUND(E4*N4,2),""),IF(AND(ISNUMBER(J4),ISNUMBER(M4)),ROUND(J4+M4,2),"")) -> 2067.11 | P4: OPEN | Q4: OBSERVED_NET_CONDITIONAL_SCOPE | R4: 24 V; factory230 V;2400 W at25C/2200 W at40C;70 A. GX monitoring differs; two GX units not required by yacht specification. Current manual geometry differs from catalogue: confirm revision. | НДС23% предварительно по поручению владельца; не установленный режим сделки. | S4: https://www.svb.de/de/victron-wechselrichter-ladegeraet-multiplus-ii-gx-24-v-3000-va-70-a.html | T4: 999.95 | U4: EUR
A5: PK03-B-L02 | B5: PK03 | C5: ME-09 | D5: Оборудование / компонент | F5: pcs | G5: Mastervolt Mass GI3.5 88000355 | H5: EL-ISO-B | I5: 1008.36 | J5: =IF(AND(ISNUMBER(E5),ISNUMBER(I5)),ROUND(E5*I5,2),"") | K5: PL23_ESTIMATE | L5: 23 | M5: =IF(AND(K5="PL23_ESTIMATE",ISNUMBER(J5),ISNUMBER(L5)),ROUND(J5*L5/100,2),"") | O5: =IF(K5="SOURCE_GROSS",IF(AND(ISNUMBER(E5),ISNUMBER(N5)),ROUND(E5*N5,2),""),IF(AND(ISNUMBER(J5),ISNUMBER(M5)),ROUND(J5+M5,2),"")) | P5: OPEN | Q5: OBSERVED_NET_CONDITIONAL_SCOPE | R5: 3500 VA at230 V;16 A;HF technology;source IP23 supersedes dealer IP21. Not complete shore protection. | НДС23% предварительно по поручению владельца; не установленный режим сделки. | S5: https://www.svb24.com/en/mastervolt-mass-gi-3-5-isolation-transformer-16-a-3-5-kw.html | T5: 1008.36 | U5: EUR
A6: PK04-B-L01 | B6: PK04 | C6: ME-08 | D6: Оборудование / компонент | E6: 6 | F6: pcs | G6: Aquamot ALS12115 12V115Ah | H6: EL-BAT-B | I6: 268.07 | J6: =IF(AND(ISNUMBER(E6),ISNUMBER(I6)),ROUND(E6*I6,2),"") -> 1608.42 | K6: PL23_ESTIMATE | L6: 23 | M6: =IF(AND(K6="PL23_ESTIMATE",ISNUMBER(J6),ISNUMBER(L6)),ROUND(J6*L6/100,2),"") -> 369.94 | O6: =IF(K6="SOURCE_GROSS",IF(AND(ISNUMBER(E6),ISNUMBER(N6)),ROUND(E6*N6,2),""),IF(AND(ISNUMBER(J6),ISNUMBER(M6)),ROUND(J6+M6,2),"")) -> 1978.36 | P6: OPEN | Q6: OBSERVED_NET_CONDITIONAL_SCOPE | R6: AGM dealer description; legacy manufacturer sheet includes GEL construction wording, chemistry/revision confirmation needed. Body height214mm total220mm; dealer header6.4kg rejected in favour33.7kg technical sheet. | НДС23% предварительно по поручению владельца; не установленный режим сделки. | S6: https://www.nothnagel-marine.de/product_info.php?info=p3857_aquamot---power-battery--dc-battery-als12115-12v-115ah-agm-deep-cycle-battery.html&language=en | T6: 319 | U6: EUR
A7: PK04-B-L02 | B7: PK04 | C7: ME-07 | D7: Оборудование / компонент | E7: 1 | F7: pcs | G7: Пусковая АКБ двигателя — тип уточняется | H7: EL-OPEN-MAIN | J7: =IF(AND(ISNUMBER(E7),ISNUMBER(I7)),ROUND(E7*I7,2),"") | K7: PL23_ESTIMATE | L7: 23 | M7: =IF(AND(K7="PL23_ESTIMATE",ISNUMBER(J7),ISNUMBER(L7)),ROUND(J7*L7/100,2),"") | O7: =IF(K7="SOURCE_GROSS",IF(AND(ISNUMBER(E7),ISNUMBER(N7)),ROUND(E7*N7,2),""),IF(AND(ISNUMBER(J7),ISNUMBER(M7)),ROUND(J7+M7,2),"")) | P7: OPEN | Q7: NO_VERIFIED_NET | R7: 1 physical owner battery, capacity/voltage/chemistry unknown. Not automatically ER550 or service115Ah. | НДС23% предварительно по поручению владельца; не установленный режим сделки.
A8: PK04-B-L03 | B8: PK04 | C8: ME-27 | D8: Оборудование / компонент | E8: 2 | F8: pcs | G8: Пусковые АКБ генераторов — тип уточняется | H8: EL-OPEN-GEN | J8: =IF(AND(ISNUMBER(E8),ISNUMBER(I8)),ROUND(E8*I8,2),"") | K8: PL23_ESTIMATE | L8: 23 | M8: =IF(AND(K8="PL23_ESTIMATE",ISNUMBER(J8),ISNUMBER(L8)),ROUND(J8*L8/100,2),"") | O8: =IF(K8="SOURCE_GROSS",IF(AND(ISNUMBER(E8),ISNUMBER(N8)),ROUND(E8*N8,2),""),IF(AND(ISNUMBER(J8),ISNUMBER(M8)),ROUND(J8+M8,2),"")) | P8: OPEN | Q8: NO_VERIFIED_NET | R8: 2 physical owner batteries for2generators; capacity/voltage/CCA unknown; keep9total with6service+1main. No fictitious unit price. | НДС23% предварительно по поручению владельца; не установленный режим сделки.
A9: PK04-B-L04 | B9: PK04 | C9: ME-28 | D9: Оборудование / компонент | F9: pcs | G9: Blue Sea ML-RBS7702 24V | H9: EL-REM-A | I9: 239.45 | J9: =IF(AND(ISNUMBER(E9),ISNUMBER(I9)),ROUND(E9*I9,2),"") | K9: PL23_ESTIMATE | L9: 23 | M9: =IF(AND(K9="PL23_ESTIMATE",ISNUMBER(J9),ISNUMBER(L9)),ROUND(J9*L9/100,2),"") | O9: =IF(K9="SOURCE_GROSS",IF(AND(ISNUMBER(E9),ISNUMBER(N9)),ROUND(E9*N9,2),""),IF(AND(ISNUMBER(J9),ISNUMBER(M9)),ROUND(J9+M9,2),"")) | P9: OPEN | Q9: OBSERVED_NET_CONDITIONAL_SCOPE | R9: Manual override;24V coil;500A continuous product rating. Quantity, control failover, crank duty and24V live switching not qualified; dimensions drawing pending. | НДС23% предварительно по поручению владельца; не установленный режим сделки. | S9: https://www.svb24.com/en/blue-sea-hd-remote-battery-switch-24v.html | T9: 239.45 | U9: EUR
A10: PK05-B-L01 | B10: PK05 | C10: ME-11 | D10: Оборудование / компонент | E10: 1 | F10: шт | G10: Gianneschi EcoInox1 GE011 24V20L | H10: WC-DC-02 | I10: 1093.25 | J10: =IF(AND(ISNUMBER(E10),ISNUMBER(I10)),ROUND(E10*I10,2),"") -> 1093.25 | K10: PL23_ESTIMATE | L10: 23 | M10: =IF(AND(K10="PL23_ESTIMATE",ISNUMBER(J10),ISNUMBER(L10)),ROUND(J10*L10/100,2),"") -> 251.45 | O10: =IF(K10="SOURCE_GROSS",IF(AND(ISNUMBER(E10),ISNUMBER(N10)),ROUND(E10*N10,2),""),IF(AND(ISNUMBER(J10),ISNUMBER(M10)),ROUND(J10+M10,2),"")) -> 1344.7 | P10: OPEN | Q10: OBSERVED_NET_CONDITIONAL_SCOPE | R10: 45L/min max; common proposed15L/min at2bar needs curve. Includes20L tank/gauge/pressure switch; current OEM revision confirmation. | НДС23% предварительно по поручению владельца; не установленный режим сделки. | S10: https://www.comptoirnautique.com/groupe-d-eau-hydrophore/22947-gianneschi-groupe-d-eau-ecoinox-1-avec-reservoir-20l-24v-45lmin-7024.html | T10: 1311.9 | U10: EUR
A11: PK05-B-L02 | B11: PK05 | C11: ME-12 | D11: Оборудование / компонент | E11: 1 | F11: шт | G11: Gianneschi EcoInox2 GE017 230V20L | H11: WC-AC-02 | I11: 1052.5 | J11: =IF(AND(ISNUMBER(E11),ISNUMBER(I11)),ROUND(E11*I11,2),"") -> 1052.5 | K11: PL23_ESTIMATE | L11: 23 | M11: =IF(AND(K11="PL23_ESTIMATE",ISNUMBER(J11),ISNUMBER(L11)),ROUND(J11*L11/100,2),"") -> 242.08 | O11: =IF(K11="SOURCE_GROSS",IF(AND(ISNUMBER(E11),ISNUMBER(N11)),ROUND(E11*N11,2),""),IF(AND(ISNUMBER(J11),ISNUMBER(M11)),ROUND(J11+M11,2),"")) -> 1294.58 | P11: OPEN | Q11: OBSERVED_NET_CONDITIONAL_SCOPE | R11: Open page1052.50HT supersedes search992.50. Dealer max55L/min conflicts Kent45: curves required.0.45kW/20L; common15L/min at2bar not verified. | НДС23% предварительно по поручению владельца; не установленный режим сделки. | S11: https://www.tyboat.com/achat/P-57388-gianneschi-groupe-d-eau-ecoinox2-3-5-bars-0-45-kw-55-litres-minute-reservoir-20-litres-230-volts.html | T11: 1263 | U11: EUR
A12: PK06-B-L01 | B12: PK06 | C12: ME-13 | D12: Оборудование / компонент | E12: 1 | F12: шт | G12: Schenker ZEN150 — базовая цена «от», полный состав открыт | H12: WC-RO-02 | I12: 10683.5 | J12: =IF(AND(ISNUMBER(E12),ISNUMBER(I12)),ROUND(E12*I12,2),"") -> 10683.5 | K12: PL23_ESTIMATE | L12: 23 | M12: =IF(AND(K12="PL23_ESTIMATE",ISNUMBER(J12),ISNUMBER(L12)),ROUND(J12*L12/100,2),"") -> 2457.21 | O12: =IF(K12="SOURCE_GROSS",IF(AND(ISNUMBER(E12),ISNUMBER(N12)),ROUND(E12*N12,2),""),IF(AND(ISNUMBER(J12),ISNUMBER(M12)),ROUND(J12+M12,2),"")) -> 13140.71 | P12: OPEN | Q12: FROM_INCOMPLETE_CONFIGURATION | R12: Observed FROM base price; net is FROM benchmark only, NOT complete Touch/salinity/reject price. Nominal150L/h. Manufacturer230V±15% includes220V. Basic has no salinity; Touch optional; 24V variant permitted. Modular unit dimensions not total installed envelope. | НДС23% предварительно по поручению владельца; не установленный режим сделки. | S12: https://mar-nautic.com/schenker-watermaker-zen-150 | T12: 12820.2 | U12: EUR
A13: PK07-B-L01 | B13: PK07 | C13: ME-14 | D13: Оборудование / компонент | F13: шт | G13: Quick BX 40L1200W FLBX4012S000A00 | H13: WC-HW-02 | I13: 690.83 | J13: =IF(AND(ISNUMBER(E13),ISNUMBER(I13)),ROUND(E13*I13,2),"") | K13: PL23_ESTIMATE | L13: 23 | M13: =IF(AND(K13="PL23_ESTIMATE",ISNUMBER(J13),ISNUMBER(L13)),ROUND(J13*L13/100,2),"") | O13: =IF(K13="SOURCE_GROSS",IF(AND(ISNUMBER(E13),ISNUMBER(N13)),ROUND(E13*N13,2),""),IF(AND(ISNUMBER(J13),ISNUMBER(M13)),ROUND(J13+M13,2),"")) | P13: OPEN | Q13: OBSERVED_NET_CONDITIONAL_SCOPE | R13: 40L1200W220V plus engine heat exchanger common illustrative class; not owner size. Supplier dimensions/mass in research only pending official drawing. Thermostatic mixing equalise separately. | НДС23% предварительно по поручению владельца; не установленный режим сделки. | S13: https://www.tyboat.com/achat/P-8880-quick-chauffe-eau-cylindrique-bx-40-litres-220-volts-1200-watts.html | T13: 829 | U13: EUR
A14: PK08-B-L01 | B14: PK08 | C14: ME-15 | D14: Оборудование / компонент | E14: 2 | F14: шт | G14: Climma CWS Aquacontrol161RC 230/1/50 | H14: WC-CH-02 | I14: 4155.3 | J14: =IF(AND(ISNUMBER(E14),ISNUMBER(I14)),ROUND(E14*I14,2),"") -> 8310.6 | K14: PL23_ESTIMATE | L14: 23 | M14: =IF(AND(K14="PL23_ESTIMATE",ISNUMBER(J14),ISNUMBER(L14)),ROUND(J14*L14/100,2),"") -> 1911.44 | O14: =IF(K14="SOURCE_GROSS",IF(AND(ISNUMBER(E14),ISNUMBER(N14)),ROUND(E14*N14,2),""),IF(AND(ISNUMBER(J14),ISNUMBER(M14)),ROUND(J14+M14,2),"")) -> 10222.04 | P14: OPEN | Q14: OBSERVED_NET_CONDITIONAL_SCOPE | R14: 16000BTU/h each; reversecycle. Price recovered live requests HTTP200 after web429; local source text retained. OEM dimensions require authenticated download; old dealerPDF not promoted. | НДС23% предварительно по поручению владельца; не установленный режим сделки. | S14: https://mdislandsupply.com/en/climma/879-cws-aquacontrol-161-rc-230150-climma.html | T14: 4155.3 | U14: EUR
A15: PK08-B-L02 | B15: PK08 | C15: ME-16 | D15: Оборудование / компонент | F15: шт | G15: Frigomar NH150PS SWM0150230 | H15: WC-AUX-01 | I15: 663.25 | J15: =IF(AND(ISNUMBER(E15),ISNUMBER(I15)),ROUND(E15*I15,2),"") | K15: PL23_ESTIMATE | L15: 23 | M15: =IF(AND(K15="PL23_ESTIMATE",ISNUMBER(J15),ISNUMBER(L15)),ROUND(J15*L15/100,2),"") | O15: =IF(K15="SOURCE_GROSS",IF(AND(ISNUMBER(E15),ISNUMBER(N15)),ROUND(E15*N15,2),""),IF(AND(ISNUMBER(J15),ISNUMBER(M15)),ROUND(J15+M15,2),"")) | P15: OPEN | Q15: OBSERVED_NET_CONDITIONAL_SCOPE | R15: 230V50/60Hz magneticdrive; count and pump duty notfixed. No proof this model meets both seawater and chilledwater circuits; official detailed curve required. | НДС23% предварительно по поручению владельца; не установленный режим сделки. | S15: https://www.comptoirnautique.com/climatisation-bateau/91819-frigomar-pompes-a-entrainement-magnetique.html | T15: 795.9 | U15: EUR
A16: PK09-B-L01 | B16: PK09 | C16: ME-18 | D16: Оборудование / компонент | F16: шт | G16: Parker Racor 75500MAXM30 | H16: A09 | I16: 1848.66 | J16: =IF(AND(ISNUMBER(E16),ISNUMBER(I16)),ROUND(E16*I16,2),"") | K16: PL23_ESTIMATE | L16: 23 | M16: =IF(AND(K16="PL23_ESTIMATE",ISNUMBER(J16),ISNUMBER(L16)),ROUND(J16*L16/100,2),"") | O16: =IF(K16="SOURCE_GROSS",IF(AND(ISNUMBER(E16),ISNUMBER(N16)),ROUND(E16*N16,2),""),IF(AND(ISNUMBER(J16),ISNUMBER(M16)),ROUND(J16+M16,2),"")) | P16: OPEN | Q16: VARIABLE_PRICE_RECONFIRM | R16: Root open2612.00gross/19%=2194.96NET; повторное открытие независимым агентом2199.90gross/19%=1848.66NET. Принято последнее наблюдение, расхождение сохранено; подтвердить цену до сравнения. Дуплексный узел, микроны/расход одной ветви под двигатель. | НДС23% предварительно по поручению владельца; не установленный режим сделки. | S16: https://racorshop.de/product/racor-75500maxm30-turbine-filter-marine/ | T16: 2199.9 | U16: EUR
A17: PK09-B-L02 | B17: PK09 | C17: ME-19 | D17: Оборудование / компонент | F17: шт | G17: Vetus FTR33032M | H17: A11 | I17: 164.46 | J17: =IF(AND(ISNUMBER(E17),ISNUMBER(I17)),ROUND(E17*I17,2),"") | K17: PL23_ESTIMATE | L17: 23 | M17: =IF(AND(K17="PL23_ESTIMATE",ISNUMBER(J17),ISNUMBER(L17)),ROUND(J17*L17/100,2),"") | O17: =IF(K17="SOURCE_GROSS",IF(AND(ISNUMBER(E17),ISNUMBER(N17)),ROUND(E17*N17,2),""),IF(AND(ISNUMBER(J17),ISNUMBER(M17)),ROUND(J17+M17,2),"")) | P17: OPEN | Q17: OBSERVED_NET_CONDITIONAL_SCOPE | R17: NET явно exclusiefBTW; усиленная версия с металлической крышкой. Сравнение с FTR330/32 требует одинаковых давления/установочного положения. | НДС23% предварительно по поручению владельца; не установленный режим сделки. | S17: https://www.mediawinkel.eu/nl/heavy-duty-waterfilter-32-mm.html | T17: 164.46 | U17: EUR
A18: PK09-B-L03 | B18: PK09 | C18: ME-22 | D18: Оборудование / компонент | F18: шт | G18: Jabsco 35770-0094 /24V | H18: A15 | J18: =IF(AND(ISNUMBER(E18),ISNUMBER(I18)),ROUND(E18*I18,2),"") | K18: PL23_ESTIMATE | L18: 23 | M18: =IF(AND(K18="PL23_ESTIMATE",ISNUMBER(J18),ISNUMBER(L18)),ROUND(J18*L18/100,2),"") | O18: =IF(K18="SOURCE_GROSS",IF(AND(ISNUMBER(E18),ISNUMBER(N18)),ROUND(E18*N18,2),""),IF(AND(ISNUMBER(J18),ISNUMBER(M18)),ROUND(J18+M18,2),"")) | P18: OPEN | Q18: NO_VERIFIED_NET | R18: Поиск224.42exVAT, открытиеchallenge. Раздел дилера предупреждаетhold EU compliance. NET поле пусто; не считать доступным. Официально7м³/мин свободныйрасход, требуемыйнапорнепроверен. | НДС23% предварительно по поручению владельца; не установленный режим сделки. | S18: https://www.mackengineering.co.uk/35770-0094-24v-flexmount-blower.html | T18: 224.42 | U18: GBP
A19: PK09-B-L04 | B19: PK09 | C19: ME-23 | D19: Оборудование / компонент | F19: шт | G19: Marco UP3/OIL 16402013 /24V | H19: A16 | I19: 188.56 | J19: =IF(AND(ISNUMBER(E19),ISNUMBER(I19)),ROUND(E19*I19,2),"") | K19: PL23_ESTIMATE | L19: 23 | M19: =IF(AND(K19="PL23_ESTIMATE",ISNUMBER(J19),ISNUMBER(L19)),ROUND(J19*L19/100,2),"") | O19: =IF(K19="SOURCE_GROSS",IF(AND(ISNUMBER(E19),ISNUMBER(N19)),ROUND(E19*N19,2),""),IF(AND(ISNUMBER(J19),ISNUMBER(M19)),ROUND(J19+M19,2),"")) | P19: OPEN | Q19: OBSERVED_NET_CONDITIONAL_SCOPE | R19: Только насос; коллектор3агрегатов,шланги,поддоны,свет и автоматика не включены. | НДС23% предварительно по поручению владельца; не установленный режим сделки. | S19: https://www.mackengineering.co.uk/marco-up3-oil-pump-24v.html | T19: 162 | U19: GBP
A20: PK10-B-L01 | B20: PK10 | C20: ME-20 | D20: Оборудование / компонент | F20: шт | G20: Rule 2000 GPH / model12 /24V | H20: A12 | I20: 124.82 | J20: =IF(AND(ISNUMBER(E20),ISNUMBER(I20)),ROUND(E20*I20,2),"") | K20: PL23_ESTIMATE | L20: 23 | M20: =IF(AND(K20="PL23_ESTIMATE",ISNUMBER(J20),ISNUMBER(L20)),ROUND(J20*L20/100,2),"") | O20: =IF(K20="SOURCE_GROSS",IF(AND(ISNUMBER(E20),ISNUMBER(N20)),ROUND(E20*N20,2),""),IF(AND(ISNUMBER(J20),ISNUMBER(M20)),ROUND(J20+M20,2),"")) | P20: OPEN | Q20: OBSERVED_NET_CONDITIONAL_SCOPE | R20: Габариты из официальной таблицы, у дилера155×105 отличаются; сверить ревизию. Не вся система осушения; поплавок/сигнализация отдельно. | НДС23% предварительно по поручению владельца; не установленный режим сделки. | S20: https://www.mackengineering.co.uk/rule-2000-gph-bilge-pump-24v.html | T20: 107.24 | U20: GBP
A21: PK10-B-L02 | B21: PK10 | C21: ME-20 | D21: Оборудование / компонент | F21: шт | G21: Whale Gusher Urchin BP9005 | H21: A13 | I21: 64.13 | J21: =IF(AND(ISNUMBER(E21),ISNUMBER(I21)),ROUND(E21*I21,2),"") | K21: PL23_ESTIMATE | L21: 23 | M21: =IF(AND(K21="PL23_ESTIMATE",ISNUMBER(J21),ISNUMBER(L21)),ROUND(J21*L21/100,2),"") | O21: =IF(K21="SOURCE_GROSS",IF(AND(ISNUMBER(E21),ISNUMBER(N21)),ROUND(E21*N21,2),""),IF(AND(ISNUMBER(J21),ISNUMBER(M21)),ROUND(J21+M21,2),"")) | P21: OPEN | Q21: OBSERVED_NET_CONDITIONAL_SCOPE | R21: Ориентир цены ручного насоса; не назначенный главный аварийный насос67ft, расход/напор/доступ проверить. | НДС23% предварительно по поручению владельца; не установленный режим сделки. | S21: https://www.mackengineering.co.uk/bp9005-whale-gusher-urchin-hand-pump.html | T21: 55.1 | U21: GBP
A22: PK10-B-L03 | B22: PK10 | C22: ME-20 | D22: Оборудование / компонент | F22: шт | G22: Rule 32ALA /24V | H22: A14 | I22: 85.19 | J22: =IF(AND(ISNUMBER(E22),ISNUMBER(I22)),ROUND(E22*I22,2),"") | K22: PL23_ESTIMATE | L22: 23 | M22: =IF(AND(K22="PL23_ESTIMATE",ISNUMBER(J22),ISNUMBER(L22)),ROUND(J22*L22/100,2),"") | O22: =IF(K22="SOURCE_GROSS",IF(AND(ISNUMBER(E22),ISNUMBER(N22)),ROUND(E22*N22,2),""),IF(AND(ISNUMBER(J22),ISNUMBER(M22)),ROUND(J22+M22,2),"")) | P22: OPEN | Q22: OBSERVED_NET_CONDITIONAL_SCOPE | R22: Цена связанного товара открытой карточки; состав сигнализации и число отсеков открыты. | НДС23% предварительно по поручению владельца; не установленный режим сделки. | S22: https://www.mackengineering.co.uk/rule-2000-gph-bilge-pump-24v.html | T22: 73.19 | U22: GBP
A23: PK10-B-L04 | B23: PK10 | C23: ME-21 | D23: Оборудование / компонент | F23: шт | G23: Fireboy MA series 31.620.55 | H23: A20 | J23: =IF(AND(ISNUMBER(E23),ISNUMBER(I23)),ROUND(E23*I23,2),"") | K23: PL23_ESTIMATE | L23: 23 | M23: =IF(AND(K23="PL23_ESTIMATE",ISNUMBER(J23),ISNUMBER(L23)),ROUND(J23*L23/100,2),"") | O23: =IF(K23="SOURCE_GROSS",IF(AND(ISNUMBER(E23),ISNUMBER(N23)),ROUND(E23*N23,2),""),IF(AND(ISNUMBER(J23),ISNUMBER(M23)),ROUND(J23+M23,2),"")) | P23: OPEN | Q23: NO_VERIFIED_NET | R23: Поиск1950NET, открытиеошибка. Заголовок51м³, таблица15.6м³ противоречат; модель/заряд не выбраны. Нельзя уменьшать заряд ради габарита. Отключение двигателей/вентиляции и ручнойпуск по отдельномуBOM. | НДС23% предварительно по поручению владельца; не установленный режим сделки. | S23: https://www.oltrevela.com/en/31-620-55-fireboy-ma-series-automatic-manual-fire-extinguisher-13-4-kg-for-engine-rooms-and-motor-compartments-up-to-51m-uscg-and-iso-rina-approved-fireboy-4 | T23: 1950 | U23: EUR
A24: PK11-B-L01 | B24: PK11 | C24: ME-24 | D24: Оборудование / компонент | F24: шт | G24: Vetus SENSORA | H24: A18 | I24: 187.69 | J24: =IF(AND(ISNUMBER(E24),ISNUMBER(I24)),ROUND(E24*I24,2),"") | K24: PL23_ESTIMATE | L24: 23 | M24: =IF(AND(K24="PL23_ESTIMATE",ISNUMBER(J24),ISNUMBER(L24)),ROUND(J24*L24/100,2),"") | O24: =IF(K24="SOURCE_GROSS",IF(AND(ISNUMBER(E24),ISNUMBER(N24)),ROUND(E24*N24,2),""),IF(AND(ISNUMBER(J24),ISNUMBER(M24)),ROUND(J24+M24,2),"")) | P24: OPEN | Q24: OBSERVED_NET_CONDITIONAL_SCOPE | R24: Ультразвуковой аналоговый датчик; работа в конкретном танке и интерфейс подлежат проверке. Не цена танка. | НДС23% предварительно по поручению владельца; не установленный режим сделки. | S24: https://www.vetus-shop.com/vetus-fuel-tank-quickfit-diesel-40-litre-8mm-p-1786.html | T24: 161.25 | U24: GBP
A25: PK11-B-L02 | B25: PK11 | C25: ME-25 | D25: Оборудование / компонент | F25: шт | G25: Jabsco 18590-2094 /24V | H25: A19 | I25: 164.85 | J25: =IF(AND(ISNUMBER(E25),ISNUMBER(I25)),ROUND(E25*I25,2),"") | K25: PL23_ESTIMATE | L25: 23 | M25: =IF(AND(K25="PL23_ESTIMATE",ISNUMBER(J25),ISNUMBER(L25)),ROUND(J25*L25/100,2),"") | O25: =IF(K25="SOURCE_GROSS",IF(AND(ISNUMBER(E25),ISNUMBER(N25)),ROUND(E25*N25,2),""),IF(AND(ISNUMBER(J25),ISNUMBER(M25)),ROUND(J25+M25,2),"")) | P25: OPEN | Q25: OBSERVED_NET_CONDITIONAL_SCOPE | R25: 24V; только насос сточного танка. Пересечение с комплектом туалета проверять; число танков не назначено. | НДС23% предварительно по поручению владельца; не установленный режим сделки. | S25: https://www.cactusnav.com/jabsco-macerator-pump-p-37922.html | T25: 141.63 | U25: GBP
A26: PK12-B-L01 | B26: PK12 | C26: ME-29 | D26: Оборудование / компонент | F26: шт | G26: Sleipner Load-sensing system / bulkhead tank 40L | H26: A07 | J26: =IF(AND(ISNUMBER(E26),ISNUMBER(I26)),ROUND(E26*I26,2),"") | K26: PL23_ESTIMATE | L26: 23 | M26: =IF(AND(K26="PL23_ESTIMATE",ISNUMBER(J26),ISNUMBER(L26)),ROUND(J26*L26/100,2),"") | O26: =IF(K26="SOURCE_GROSS",IF(AND(ISNUMBER(E26),ISNUMBER(N26)),ROUND(E26*N26,2),""),IF(AND(ISNUMBER(J26),ISNUMBER(M26)),ROUND(J26+M26,2),"")) | P26: OPEN | Q26: NO_VERIFIED_NET | R26: Справочный габарит настенного танк-модуля из каталога2020; с блоком одного подруливающего, без всей установки. Ещё100мм для замены фильтра. Нужны текущийCAD и расчёт всех потребителей. | НДС23% предварительно по поручению владельца; не установленный режим сделки. | U26: EUR
A27: OPEN-ME-03 | B27: PK01 | C27: ME-03 | D27: Неоценённая функция | G27: Муфта, опоры, упорный узел и элементы валопровода | H27: M01/ME-03 | J27: =IF(AND(ISNUMBER(E27),ISNUMBER(I27)),ROUND(E27*I27,2),"") | K27: PL23_ESTIMATE | L27: 23 | M27: =IF(AND(K27="PL23_ESTIMATE",ISNUMBER(J27),ISNUMBER(L27)),ROUND(J27*L27/100,2),"") | O27: =IF(K27="SOURCE_GROSS",IF(AND(ISNUMBER(E27),ISNUMBER(N27)),ROUND(E27*N27,2),""),IF(AND(ISNUMBER(J27),ISNUMBER(M27)),ROUND(J27+M27,2),"")) | P27: OPEN | Q27: NO_PRICE | R27: Функциональная линия одна; числа подшипников/опор/уплотнений и комплектность не установлены | Резервсостава,неповтор комплектных деталей; количествоаппаратов не назначено.
A28: OPEN-ME-06 | B28: PK03 | C28: ME-06 | D28: Неоценённая функция | E28: 1 | F28: канал | G28: Независимое инверторное питание AC насоса пресной воды | H28: M01/ME-06 | J28: =IF(AND(ISNUMBER(E28),ISNUMBER(I28)),ROUND(E28*I28,2),"") | K28: PL23_ESTIMATE | L28: 23 | M28: =IF(AND(K28="PL23_ESTIMATE",ISNUMBER(J28),ISNUMBER(L28)),ROUND(J28*L28/100,2),"") | O28: =IF(K28="SOURCE_GROSS",IF(AND(ISNUMBER(E28),ISNUMBER(N28)),ROUND(E28*N28,2),""),IF(AND(ISNUMBER(J28),ISNUMBER(M28)),ROUND(J28+M28,2),"")) | P28: OPEN | Q28: NO_PRICE | R28: РеестрO02 предлагает1 отдельный инвертор; brief допускает отдельное либо изолированное исполнение. Аппаратное исполнение выбрать одинаково для3вариантов | Резервсостава,неповтор комплектных деталей; количествоаппаратов не назначено.
A29: OPEN-ME-10 | B29: PK03 | C29: ME-10 | D29: Неоценённая функция | G29: Распределение AC/DC, переключение источников, зарядная и защитная автоматика | H29: M01/ME-10 | J29: =IF(AND(ISNUMBER(E29),ISNUMBER(I29)),ROUND(E29*I29,2),"") | K29: PL23_ESTIMATE | L29: 23 | M29: =IF(AND(K29="PL23_ESTIMATE",ISNUMBER(J29),ISNUMBER(L29)),ROUND(J29*L29/100,2),"") | O29: =IF(K29="SOURCE_GROSS",IF(AND(ISNUMBER(E29),ISNUMBER(N29)),ROUND(E29*N29,2),""),IF(AND(ISNUMBER(J29),ISNUMBER(M29)),ROUND(J29+M29,2),"")) | P29: OPEN | Q29: NO_PRICE | R29: Состав щитов/аппаратов/датчиков по однолинейной схеме; штатное включение в инверторы/генераторы не считать дважды | Резервсостава,неповтор комплектных деталей; количествоаппаратов не назначено.
A30: OPEN-ME-17 | B30: PK05 | C30: ME-17 | D30: Неоценённая функция | G30: Гидроаккумуляторы, коллекторы, фильтры, клапаны и рециркуляция ГВС | H30: M01/ME-17 | J30: =IF(AND(ISNUMBER(E30),ISNUMBER(I30)),ROUND(E30*I30,2),"") | K30: PL23_ESTIMATE | L30: 23 | M30: =IF(AND(K30="PL23_ESTIMATE",ISNUMBER(J30),ISNUMBER(L30)),ROUND(J30*L30/100,2),"") | O30: =IF(K30="SOURCE_GROSS",IF(AND(ISNUMBER(E30),ISNUMBER(N30)),ROUND(E30*N30,2),""),IF(AND(ISNUMBER(J30),ISNUMBER(M30)),ROUND(J30+M30,2),"")) | P30: OPEN | Q30: NO_PRICE | R30: Разделить комплектные и внешние детали; количество по P&ID, рециркуляция по необходимости | Резервсостава,неповтор комплектных деталей; количествоаппаратов не назначено.
A31: OPEN-ME-26 | B31: PK08 | C31: ME-26 | D31: Неоценённая функция | G31: Резервное водяное отопление | H31: M01/ME-26 | J31: =IF(AND(ISNUMBER(E31),ISNUMBER(I31)),ROUND(E31*I31,2),"") | K31: PL23_ESTIMATE | L31: 23 | M31: =IF(AND(K31="PL23_ESTIMATE",ISNUMBER(J31),ISNUMBER(L31)),ROUND(J31*L31/100,2),"") | O31: =IF(K31="SOURCE_GROSS",IF(AND(ISNUMBER(E31),ISNUMBER(N31)),ROUND(E31*N31,2),""),IF(AND(ISNUMBER(J31),ISNUMBER(M31)),ROUND(J31+M31,2),"")) | P31: CONDITIONAL | Q31: NO_PRICE | R31: Не обязательная покупка до решения; обратный цикл чиллеров и отдельное отопление не назначаются автоматически | Резервсостава,неповтор комплектных деталей; количествоаппаратов не назначено.
A32: GAP-01 | B32: ADD | D32: Работа / внешняя затрата | G32: Рабочее проектирование и интеграция МО | H32: M06/scope + office/cost-policy | J32: =IF(AND(ISNUMBER(E32),ISNUMBER(I32)),ROUND(E32*I32,2),"") | K32: PL23_ESTIMATE | L32: 23 | M32: =IF(AND(K32="PL23_ESTIMATE",ISNUMBER(J32),ISNUMBER(L32)),ROUND(J32*L32/100,2),"") | O32: =IF(K32="SOURCE_GROSS",IF(AND(ISNUMBER(E32),ISNUMBER(N32)),ROUND(E32*N32,2),""),IF(AND(ISNUMBER(J32),ISNUMBER(M32)),ROUND(J32+M32,2),"")) | P32: OPEN | Q32: NO_PRICE | R32: Чертежи фундаментов/трасс/систем; без общей архитектуры всей яхты
A33: GAP-02 | B33: ADD | D33: Работа / внешняя затрата | G33: Внешние трубопроводы, кабели и монтажные материалы | H33: M06/scope + office/cost-policy | J33: =IF(AND(ISNUMBER(E33),ISNUMBER(I33)),ROUND(E33*I33,2),"") | K33: PL23_ESTIMATE | L33: 23 | M33: =IF(AND(K33="PL23_ESTIMATE",ISNUMBER(J33),ISNUMBER(L33)),ROUND(J33*L33/100,2),"") | O33: =IF(K33="SOURCE_GROSS",IF(AND(ISNUMBER(E33),ISNUMBER(N33)),ROUND(E33*N33,2),""),IF(AND(ISNUMBER(J33),ISNUMBER(M33)),ROUND(J33+M33,2),"")) | P33: OPEN | Q33: NO_PRICE | R33: Только невключённые в поставку материалы: длины, диаметры, крепления и изоляция по проекту
A34: GAP-03 | B34: ADD | D34: Работа / внешняя затрата | G34: Изготовление фундаментов и локальных усилений | H34: M06/scope + office/cost-policy | J34: =IF(AND(ISNUMBER(E34),ISNUMBER(I34)),ROUND(E34*I34,2),"") | K34: PL23_ESTIMATE | L34: 23 | M34: =IF(AND(K34="PL23_ESTIMATE",ISNUMBER(J34),ISNUMBER(L34)),ROUND(J34*L34/100,2),"") | O34: =IF(K34="SOURCE_GROSS",IF(AND(ISNUMBER(E34),ISNUMBER(N34)),ROUND(E34*N34,2),""),IF(AND(ISNUMBER(J34),ISNUMBER(M34)),ROUND(J34+M34,2),"")) | P34: OPEN | Q34: NO_PRICE | R34: Внешние корпусные работы; не повтор заводских виброопор и корпусного бюджета
A35: GAP-04 | B35: ADD | D35: Работа / внешняя затрата | G35: Монтаж и центровка оборудования | H35: M06/scope + office/cost-policy | J35: =IF(AND(ISNUMBER(E35),ISNUMBER(I35)),ROUND(E35*I35,2),"") | K35: PL23_ESTIMATE | L35: 23 | M35: =IF(AND(K35="PL23_ESTIMATE",ISNUMBER(J35),ISNUMBER(L35)),ROUND(J35*L35/100,2),"") | O35: =IF(K35="SOURCE_GROSS",IF(AND(ISNUMBER(E35),ISNUMBER(N35)),ROUND(E35*N35,2),""),IF(AND(ISNUMBER(J35),ISNUMBER(M35)),ROUND(J35+M35,2),"")) | P35: OPEN | Q35: NO_PRICE | R35: Труд и оснастка; без уже включённого монтажа из будущих КП
A36: GAP-05 | B36: ADD | D36: Работа / внешняя затрата | G36: Настройка, пусконаладка и испытания МО | H36: M06/scope + office/cost-policy | J36: =IF(AND(ISNUMBER(E36),ISNUMBER(I36)),ROUND(E36*I36,2),"") | K36: PL23_ESTIMATE | L36: 23 | M36: =IF(AND(K36="PL23_ESTIMATE",ISNUMBER(J36),ISNUMBER(L36)),ROUND(J36*L36/100,2),"") | O36: =IF(K36="SOURCE_GROSS",IF(AND(ISNUMBER(E36),ISNUMBER(N36)),ROUND(E36*N36,2),""),IF(AND(ISNUMBER(J36),ISNUMBER(M36)),ROUND(J36+M36,2),"")) | P36: OPEN | Q36: NO_PRICE | R36: Системные/интеграционные испытания; не повтор заводских испытаний и общесудовой приёмки
A37: GAP-06 | B37: ADD | D37: Работа / внешняя затрата | G37: Доставка и страхование до верфи | H37: M06/scope + office/cost-policy | J37: =IF(AND(ISNUMBER(E37),ISNUMBER(I37)),ROUND(E37*I37,2),"") | K37: PL23_ESTIMATE | L37: 23 | M37: =IF(AND(K37="PL23_ESTIMATE",ISNUMBER(J37),ISNUMBER(L37)),ROUND(J37*L37/100,2),"") | O37: =IF(K37="SOURCE_GROSS",IF(AND(ISNUMBER(E37),ISNUMBER(N37)),ROUND(E37*N37,2),""),IF(AND(ISNUMBER(J37),ISNUMBER(M37)),ROUND(J37+M37,2),"")) | P37: OPEN | Q37: NO_PRICE | R37: Маршрут, местоотгрузки,масса/габариты; есливключеноКП — обоснованныйноль
A38: GAP-07 | B38: ADD | D38: Работа / внешняя затрата | G38: Пошлина и таможенное оформление | H38: M06/scope + office/cost-policy | J38: =IF(AND(ISNUMBER(E38),ISNUMBER(I38)),ROUND(E38*I38,2),"") | K38: TAX_REVIEW | M38: =IF(AND(K38="PL23_ESTIMATE",ISNUMBER(J38),ISNUMBER(L38)),ROUND(J38*L38/100,2),"") | O38: =IF(K38="SOURCE_GROSS",IF(AND(ISNUMBER(E38),ISNUMBER(N38)),ROUND(E38*N38,2),""),IF(AND(ISNUMBER(J38),ISNUMBER(M38)),ROUND(J38+M38,2),"")) | P38: OPEN | Q38: NO_PRICE | R38: Применимость по маршруту и происхождению; не автоматическое начисление; VATбаза уточняется
A39: GAP-08 | B39: ADD | D39: Работа / внешняя затрата | G39: Дополнительная установочная комплектность | H39: M06/scope + office/cost-policy | J39: =IF(AND(ISNUMBER(E39),ISNUMBER(I39)),ROUND(E39*I39,2),"") | K39: PL23_ESTIMATE | L39: 23 | M39: =IF(AND(K39="PL23_ESTIMATE",ISNUMBER(J39),ISNUMBER(L39)),ROUND(J39*L39/100,2),"") | O39: =IF(K39="SOURCE_GROSS",IF(AND(ISNUMBER(E39),ISNUMBER(N39)),ROUND(E39*N39,2),""),IF(AND(ISNUMBER(J39),ISNUMBER(M39)),ROUND(J39+M39,2),"")) | P39: OPEN | Q39: NO_PRICE | R39: Недостающие соединители,контроллеры,сервисные принадлежности послеM06; оплачиватьодинразпоBOM
G40: Известная оценённая часть, НЕ полный бюджет | J40: =SUM(J2:J39) -> 59331.29 | M40: =SUM(M2:M39) -> 13646.21 | O40: =SUM(O2:O39) -> 131819.5 | R40: NET и выделенныйVAT не включаютYanmarSOURCE_GROSS; суммаgrossсмешиваетPL23сценарий иценупродавцаснеизвестнойставкой. Остальныепустыезатраты сверхсуммы.

Sheet 02_Сравнение
A1: Пакет | B1: Система | C1: A известная NET | D1: A без оценки | E1: B известная NET | F1: B без оценки | G1: C известная NET | H1: C без оценки | I1: Условие
A2: PK01 | B2: Ход яхты | C2: 45977 | D2: 0 | F2: 1 | H2: 1 | I2: Только известная NETчасть; состав/налоги различны; неранжировать и нескладывать альтернативы
A3: PK02 | B3: Генерация | C3: 24893 | D3: 0 | E3: 34902.44 | F3: 0 | G3: 35858.24 | H3: 0 | I3: Только известная NETчасть; состав/налоги различны; неранжировать и нескладывать альтернативы
A4: PK03 | B4: Электропитание | C4: 1478.9 | D4: 1 | E4: 1680.58 | F4: 1 | G4: 2689 | H4: 1 | I4: Только известная NETчасть; состав/налоги различны; неранжировать и нескладывать альтернативы
A5: PK04 | B5: АКБ и резервный пуск | C5: 841.44 | D5: 3 | E5: 1608.42 | F5: 3 | G5: 1636.14 | H5: 3 | I5: Только известная NETчасть; состав/налоги различны; неранжировать и нескладывать альтернативы
A6: PK05 | B6: Пресная вода | C6: 1024.92 | D6: 1 | E6: 2145.75 | F6: 0 | H6: 2 | I6: Только известная NETчасть; состав/налоги различны; неранжировать и нескладывать альтернативы
A7: PK06 | B7: Опреснение | C7: 6335.29 | D7: 0 | E7: 10683.5 | F7: 0 | H7: 1 | I7: Только известная NETчасть; состав/налоги различны; неранжировать и нескладывать альтернативы
A8: PK07 | B8: Горячая вода | D8: 1 | F8: 1 | H8: 1 | I8: Только известная NETчасть; состав/налоги различны; неранжировать и нескладывать альтернативы
A9: PK08 | B9: Климат | C9: 7242 | D9: 1 | E9: 8310.6 | F9: 1 | H9: 2 | I9: Только известная NETчасть; состав/налоги различны; неранжировать и нескладывать альтернативы
A10: PK09 | B10: Обеспечение МО | D10: 4 | F10: 4 | H10: 4 | I10: Только известная NETчасть; состав/налоги различны; неранжировать и нескладывать альтернативы
A11: PK10 | B11: Аварийные системы | D11: 4 | F11: 4 | H11: 4 | I11: Только известная NETчасть; состав/налоги различны; неранжировать и нескладывать альтернативы
A12: PK11 | B12: Танки и стоки | D12: 2 | F12: 2 | H12: 2 | I12: Только известная NETчасть; состав/налоги различны; неранжировать и нескладывать альтернативы
A13: PK12 | B13: Гидравлика | D13: 5 | F13: 1 | H13: 1 | I13: Только известная NETчасть; состав/налоги различны; неранжировать и нескладывать альтернативы

Sheet 03_Источники
A1: candidate_id | B1: me_id | C1: category | D1: manufacturer | E1: model | F1: qty | G1: unit | H1: currency | I1: listed_price | J1: tax_basis | K1: tax_rate | L1: net_unit_price | M1: price_url | N1: spec_url | O1: length_mm | P1: width_mm | Q1: height_mm | R1: mass_kg | S1: technical_status | T1: scope_notes | U1: availability | V1: access_date | W1: price_class | X1: evidence_type | Y1: price_date | Z1: source_revision | AA1: eur_net_unit
A2: PROP-E01 | B2: ME-01|ME-02|ME-03 | C2: engine_gearbox | D2: Volvo Penta | E2: D4-300 I + HS68A | F2: 1 | G2: package | H2: EUR | I2: 44716 | J2: explicit HT; historical March 2023 | L2: 44716 | M2: https://www.dbmoteurs.fr/sites/default/files/Volvo-Penta-tarifs-prix-achat-moteurs-2023-DB-Moteurs-motorisation-marine-bateau-plaisance.pdf | N2: https://www.dbmoteurs.fr/sites/default/files/Moteur-Volvo-Penta-D4-270-300-320-fiche-commerciale-2021-47711815-en.pdf | R2: 580 | S2: HISTORICAL_NET_REFERENCE|RFQ_REQUIRED|DUTY_OPEN | T2: 300 metric hp crank / 289 prop shaft at3500rpm; R5; 24V option official but quoted configuration unspecified; HS68A ratio selection open; dimensions for HS85A must not be substituted; ME-03 partial only factory mounts where included: shaft/coupling/thrust unit quantities and price OPEN | U2: 2026 availability unknown | V2: 2026-09-11 | W2: HISTORICAL_NOT_CURRENT | X2: PUBLIC_PRICE_NOT_KP | Y2: 2023-03 | Z2: deliverables/M02/v001/01_support/all-candidates.csv | AA2: 44716
A3: PROP-E02 | B3: ME-01|ME-02|ME-03 | C3: engine_gearbox | D3: Volvo Penta | E3: D4-300 I + HS85A | F3: 1 | G3: package | H3: EUR | I3: 45977 | J3: explicit HT; historical March 2023 | L3: 45977 | M3: https://www.dbmoteurs.fr/sites/default/files/Volvo-Penta-tarifs-prix-achat-moteurs-2023-DB-Moteurs-motorisation-marine-bateau-plaisance.pdf | N3: https://www.dbmoteurs.fr/sites/default/files/Moteur-Volvo-Penta-D4-270-300-320-fiche-commerciale-2021-47711815-en.pdf | O3: 1234 | P3: 848 | Q3: 794 | R3: 605 | S3: HISTORICAL_NET_REFERENCE|RFQ_REQUIRED|DUTY_OPEN | T3: 300 metric hp crank / 289 prop shaft; 3500rpm R5; 24V option price open; ratio2.500. L=433+801 W=441+407 H=274+520 from drawing; excludes projecting lifting eye/service space; not installation GA; ME-03 partial only factory mounts where included: shaft/coupling/thrust unit quantities and price OPEN | U3: 2026 availability unknown | V3: 2026-09-11 | W3: HISTORICAL_NOT_CURRENT | X3: PUBLIC_PRICE_NOT_KP | Y3: 2023-03 | Z3: deliverables/M02/v001/01_support/all-candidates.csv | AA3: 45977
A4: PROP-E03 | B4: ME-01|ME-02|ME-03 | C4: engine_gearbox | D4: Volvo Penta | E4: D6-300 I + HS85A | F4: 1 | G4: package | H4: EUR | I4: 50146 | J4: explicit HT; historical March 2023 | L4: 50146 | M4: https://www.dbmoteurs.fr/sites/default/files/Volvo-Penta-tarifs-prix-achat-moteurs-2023-DB-Moteurs-motorisation-marine-bateau-plaisance.pdf | N4: https://www.dbmoteurs.fr/sites/default/files/Moteur-Volvo-Penta-D6-300-340-380-fiche-commerciale-brochure-2021-47711891-fr-dbmoteurs.pdf | O4: 1470 | P4: 848 | Q4: 794 | R4: 690 | S4: HISTORICAL_NET_REFERENCE|RFQ_REQUIRED|DUTY_OPEN | T4: 300 metric hp crank /289 prop shaft;3300rpm. 24V option price open; L=433+1037 W=441+407 H=274+520 drawing dimensions not installation/service envelope; lifting eye extends above dimension; ME-03 partial only factory mounts where included: shaft/coupling/thrust unit quantities and price OPEN | U4: 2026 availability unknown | V4: 2026-09-11 | W4: HISTORICAL_NOT_CURRENT | X4: PUBLIC_PRICE_NOT_KP | Y4: 2023-03 | Z4: deliverables/M02/v001/01_support/all-candidates.csv | AA4: 50146
A5: PROP-E04 | B5: ME-01|ME-02|ME-03 | C5: engine_gearbox | D5: FPT Industrial | E5: C90 410 rating D 300hp + gearbox RFQ | F5: 1 | G5: package | H5: EUR | J5: RFQ_REQUIRED | M5: https://www.etruck.fi/shop-1 | N5: https://www.fptindustrial.com/-/media/FPT/Brochures/Engines/MARINE/COMMERCIAL/Marine_Commercial_FR_2026.pdf?rev=-1 | O5: 1289 | P5: 861 | Q5: 973 | R5: 950 | S5: RFQ_REQUIRED|INCOMPLETE_PACKAGE|DUTY_COMPARISON_OPEN | T5: Official2026 220kW300hp@2000rpm ratingD heavy duty; gearbox unselected/unpriced; shown dimensions length to flywheel and mass ENGINE ONLY; not complete package envelope;24V option RFQ; ME-03 partial only factory mounts where included: shaft/coupling/thrust unit quantities and price OPEN | U5: No exact300hp package price found | V5: 2026-09-11 | W5: NO_VERIFIED_NET | X5: PUBLIC_PRICE_NOT_KP | Y5: UNKNOWN | Z5: deliverables/M02/v001/01_support/all-candidates.csv
A6: PROP-G01 | B6: ME-04|ME-19 | C6: generator | D6: Fischer Panda | E6: Panda12000x PMS | F6: 2 | G6: package | H6: GBP | I6: 16830 | J6: explicit inc vat/ex vat pair | K6: 20 | L6: 14025 | M6: https://www.jpcdirect.com/product/fischer-panda-12000x-generator/ | N6: https://www.onefischerpanda.com/marine/marine-generators/xseries-generators/panda-12000x-pms/ | O6: 705 | P6: 450 | Q6: 590 | R6: 195 | S6: CONDITIONAL_START_VOLTAGE|AC_COMPATIBILITY_OPEN|RATING_OPEN|UK_REFERENCE | T6: 12kVA10.2kW nominal; Manel continuous10.8kVA9.2kW;50Hz230V +/-3V;12V starter;capsule included spec; verify exactJPCSKU/manufacturer0024660 and installation accessories; UK import/logistics not included; ME-19 partial factory cooling only: external seawater/exhaust runs and installation OPEN; JPC revision conflict H565 / additional700x470x580 and192kg vs OEM705x450x590/195kg: exactSKU CAD RFQ; OEM values retained | U6: Available on back-order; qty2 and lead time RFQ | V6: 2026-09-11 | W6: OBSERVED_NET_CONDITIONAL_SCOPE | X6: PUBLIC_PRICE_NOT_KP | Y6: UNKNOWN | Z6: deliverables/M02/v001/01_support/all-candidates.csv | AA6: 16324.27
A7: PROP-G02 | B7: ME-04|ME-19 | C7: generator | D7: Kohler / Rehlko | E7: 12EFKOZD | F7: 2 | G7: package | H7: GBP | I7: 18484.56 | J7: explicit inc vat/ex vat pair | K7: 20 | L7: 15403.8 | M7: https://www.jpcdirect.com/product/kohler-12-kilowatt-generator/ | N7: https://techcomm.rehlko.com/techcomm/pdf/g2186.pdf | O7: 1064 | P7: 652.5 | Q7: 711 | R7: 385 | S7: CONDITIONAL_CONFIGURATION|AC_COMPATIBILITY_OPEN|RATING_OPEN|UK_REFERENCE | T7: Singlephase115/230V50Hz:12kW12kVA continuous140C rise;11/11continuous115C;10.5/10.5prime. Official12or24V; JPC exactstarter/shield revision RFQ. Official shield mass385dry398wet; dealer406kg conflict. No borrowing US24V price scope; ME-19 partial factory cooling only: external seawater/exhaust runs and installation OPEN | U7: Available on back-order | V7: 2026-09-11 | W7: OBSERVED_NET_CONDITIONAL_SCOPE | X7: PUBLIC_PRICE_NOT_KP | Y7: UNKNOWN | Z7: deliverables/M02/v001/01_support/all-candidates.csv | AA7: 17929.12
A8: PROP-G03 | B8: ME-04|ME-19 | C8: generator | D8: Volpi Tecno Energia | E8: Paguro12000V AP12023050M0 | F8: 2 | G8: package | H8: EUR | I8: 14935.8 | J8: direct page12446.50 +IVA; gross14935.80 labelled SK20% locale | K8: 20 | L8: 12446.5 | M8: https://www.manelservice.com/it/gruppi-elettrogeni-marini/3925-vte-paguro-12000-v-ap12023050m0.html | N8: https://www.volpitecno.com/portfolio/paguro-12000-v-10-kw-2000-%C3%B7-3000-g-1/ | O8: 770 | P8: 460 | Q8: 620 | R8: 180 | S8: CONDITIONAL_START_VOLTAGE|AC_COMPATIBILITY_OPEN|REVISION_OPEN | T8: 12kVA10kW continuous50Hz230V;12V starter;mass165capsule+15control electronics. Official dimensions capsule only; separate electronics footprint RFQ. Dealer/allpa dimensions/mass differ; exact SKU installationdrawing required. Published net directly not Polish VAT assumption; ME-19 partial factory cooling only: external seawater/exhaust runs and installation OPEN | U8: Manel Disponibile; qty2 and delivery date RFQ | V8: 2026-09-11 | W8: OBSERVED_NET_CONDITIONAL_SCOPE | X8: PUBLIC_PRICE_NOT_KP | Y8: UNKNOWN | Z8: deliverables/M02/v001/01_support/all-candidates.csv | AA8: 12446.5
A9: PROP-G04 | B9: ME-04|ME-19 | C9: generator | D9: Kohler / Rehlko | E9: 12EFKOZD24-SS | F9: 2 | G9: package | H9: USD | I9: 20165.6 | J9: not stated | M9: https://mmarineonline.com/products/kohler-marine-diesel-generator-24v-12efkozd-ss-50hz-with-sound-shield | N9: https://techcomm.rehlko.com/techcomm/pdf/g2186.pdf | O9: 1064 | P9: 652.5 | Q9: 711 | R9: 385 | S9: NO_NET|US_REFERENCE_ONLY|AC_COMPATIBILITY_OPEN|RATING_OPEN | T9: Alternative offer for G02 not fourthgenerator;24V plus shield explicitlySKU; tax/import/Poland availability unknown; price originalUSD noFX; ME-19 partial factory cooling only: external seawater/exhaust runs and installation OPEN | U9: Contradictory availability template; RFQ | V9: 2026-09-11 | W9: NO_VERIFIED_NET | X9: PUBLIC_PRICE_NOT_KP | Y9: UNKNOWN | Z9: deliverables/M02/v001/01_support/all-candidates.csv
A10: EL-INV-A | B10: ME-05 | C10: inverter_charger | D10: Victron | E10: MultiPlus-II 24/3000/70-32 PMP242305010 | F10: 2 | G10: pcs | H10: EUR | I10: 879.95 | J10: GROSS_RATE_CONFIRMED | K10: 19 | L10: 739.45 | M10: https://www.svb.de/de/victron-wechselrichter-ladegeraet-multiplus-ii-24-v-3000-va-70-a.html | N10: https://www.victronenergy.com/media/pg/MultiPlus-II_230V/en/technical-specifications-mp-ii-230v.html | O10: 141 | P10: 268 | Q10: 499 | R10: 19 | S10: CONDITIONAL_3KVA_REFERENCE | T10: 24 V input; factory 230 V. 3000 VA not 3000 W: 2400 W at25C/2200 W at40C; charger70 A. 2 devices architecture target, capacity unapproved. | U10: 1 listed in stock; second unconfirmed | V10: 2026-09-11 | W10: OBSERVED_NET_CONDITIONAL_SCOPE | X10: PUBLIC_PRICE_NOT_KP | Y10: UNKNOWN | Z10: deliverables/M02/v001/01_support/all-candidates.csv | AA10: 739.45
A11: EL-INV-B | B11: ME-05 | C11: inverter_charger | D11: Victron | E11: MultiPlus-II GX 24/3000/70-32 PMP242306000 | F11: 2 | G11: pcs | H11: EUR | I11: 999.95 | J11: GROSS_RATE_CONFIRMED | K11: 19 | L11: 840.29 | M11: https://www.svb.de/de/victron-wechselrichter-ladegeraet-multiplus-ii-gx-24-v-3000-va-70-a.html | N11: https://www.victronenergy.com/media/pg/MultiPlus-II_GX/en/technical-specifications-mp-ii-gx-230v.html | O11: 147 | P11: 275 | Q11: 506 | R11: 20 | S11: CONDITIONAL_3KVA_REFERENCE | T11: 24 V; factory230 V;2400 W at25C/2200 W at40C;70 A. GX monitoring differs; two GX units not required by yacht specification. Current manual geometry differs from catalogue: confirm revision. | U11: expected1-2weeks | V11: 2026-09-11 | W11: OBSERVED_NET_CONDITIONAL_SCOPE | X11: PUBLIC_PRICE_NOT_KP | Y11: UNKNOWN | Z11: deliverables/M02/v001/01_support/all-candidates.csv | AA11: 840.29
A12: EL-INV-C | B12: ME-05 | C12: inverter_charger | D12: Mastervolt | E12: CombiMaster 24/3000-60 230V 35023000 | F12: 2 | G12: pcs | H12: EUR | I12: 1599.96 | J12: GROSS_RATE_CONFIRMED | K12: 19 | L12: 1344.5 | M12: https://www.svb.de/de/mastervolt-wechselrichter-ladegeraet-combimaster-24-v-3000-va-60-a.html?question_sort=oldest | N12: https://www.mastervolt.com/products/combimaster/combimaster-24-3000-60-230-v/ | O12: 155 | P12: 284 | Q12: 448 | R12: 9.3 | S12: CONDITIONAL_3KVA_NOT_EQUAL_W | T12: 24 V; factory230 V;3000 VA/2600 W at40C;60 A charger;25 A transfer versus32 A Victron. Parallel operation not qualified. | U12: 1 listed in stock; second unconfirmed | V12: 2026-09-11 | W12: OBSERVED_NET_CONDITIONAL_SCOPE | X12: PUBLIC_PRICE_NOT_KP | Y12: UNKNOWN | Z12: deliverables/M02/v001/01_support/all-candidates.csv | AA12: 1344.5
A13: EL-ISO-A | B13: ME-09 | C13: isolation_transformer | D13: Victron | E13: 3600 ITR040362042 | G13: pcs | H13: EUR | I13: 436.93 | J13: NET_EXPLICIT | L13: 436.93 | M13: https://www.svb24.com/en/p/victron-isolation-transformer-3600-w-115-230-v.html | N13: https://www.victronenergy.com/upload/documents/Datasheet-Isolation-Transformers-EN.pdf | O13: 221 | P13: 258 | Q13: 362 | R13: 21.7 | S13: CONDITIONAL_UNIT_BENCHMARK_DIMENSIONS_DEALER | T13: 3.6 class; quantity and shore capacity unknown. Dimensions/mass from opened dealer data pending native drawing confirmation; no substitute of32A at115V for32A at230V. | U13: expected1-2weeks | V13: 2026-09-11 | W13: OBSERVED_NET_CONDITIONAL_SCOPE | X13: PUBLIC_PRICE_NOT_KP | Y13: UNKNOWN | Z13: deliverables/M02/v001/01_support/all-candidates.csv | AA13: 436.93
A14: EL-ISO-B | B14: ME-09 | C14: isolation_transformer | D14: Mastervolt | E14: Mass GI3.5 88000355 | G14: pcs | H14: EUR | I14: 1008.36 | J14: NET_EXPLICIT | L14: 1008.36 | M14: https://www.svb24.com/en/mastervolt-mass-gi-3-5-isolation-transformer-16-a-3-5-kw.html | N14: https://www.mastervolt.com/products/mass-gi/mass-gi-35-kva-16a-lightweight/ | O14: 144 | P14: 261 | Q14: 340 | R14: 6 | S14: CONDITIONAL_UNIT_BENCHMARK | T14: 3500 VA at230 V;16 A;HF technology;source IP23 supersedes dealer IP21. Not complete shore protection. | U14: 1 listed in stock | V14: 2026-09-11 | W14: OBSERVED_NET_CONDITIONAL_SCOPE | X14: PUBLIC_PRICE_NOT_KP | Y14: UNKNOWN | Z14: deliverables/M02/v001/01_support/all-candidates.csv | AA14: 1008.36
A15: EL-ISO-C | B15: ME-09 | C15: isolation_transformer | D15: WhisperPower | E15: GI3600 60110102 | G15: pcs | H15: EUR | I15: 1885 | J15: GROSS_RATE_UNCONFIRMED | M15: https://www.hansenautic.de/36377/wp-gi-compact-galvanic-isolation-transformator-230v-16a-120v-32a/ | N15: https://www.whisperpower.com/gi-3600-compact-galvanic-isolation-transformer | O15: 208 | P15: 290 | Q15: 380 | R15: 28.6 | S15: CONDITIONAL_NET_PENDING_TAX | T15: 3.6 kVA;230/110 V;16/32 A. Open page confirms VAT included but not rate: NET deliberately blank. | U15: availability on request | V15: 2026-09-11 | W15: NO_VERIFIED_NET | X15: PUBLIC_PRICE_NOT_KP | Y15: UNKNOWN | Z15: deliverables/M02/v001/01_support/all-candidates.csv
A16: EL-BAT-A | B16: ME-08 | C16: service_battery | D16: Exide | E16: ER550 12V115Ah | F16: 6 | G16: pcs | H16: EUR | I16: 166.89 | J16: GROSS_RATE_CONFIRMED | K16: 19 | L16: 140.24 | M16: https://online-batterien.de/a/exide-er550-dual-versorgungsbatterie-starterbatterie-12v-115ah-550wh/400440 | N16: https://www.exidegroup.com/en/document/ml-brochure-2022 | O16: 349 | P16: 175 | Q16: 235 | R16: 28 | S16: CONDITIONAL_115AH12V_NOT_OWNER_APPROVED | T16: Flooded. Owner only said115 amperes; Ah and unit voltage unconfirmed. 6 physical units; no bank wiring/capacity inferred. Deposit extra. Dealer350mm/29kg differs from brochure. | U16: not in stock | V16: 2026-09-11 | W16: OBSERVED_NET_CONDITIONAL_SCOPE | X16: PUBLIC_PRICE_NOT_KP | Y16: UNKNOWN | Z16: deliverables/M02/v001/01_support/all-candidates.csv | AA16: 140.24
A17: EL-BAT-B | B17: ME-08 | C17: service_battery | D17: Aquamot | E17: ALS12115 12V115Ah | F17: 6 | G17: pcs | H17: EUR | I17: 319 | J17: GROSS_RATE_CONFIRMED | K17: 19 | L17: 268.07 | M17: https://www.nothnagel-marine.de/product_info.php?info=p3857_aquamot---power-battery--dc-battery-als12115-12v-115ah-agm-deep-cycle-battery.html&language=en | N17: https://aquamot.at/wp-content/uploads/2018/02/Die-Batterie-Aquamot.pdf | O17: 331 | P17: 176 | Q17: 220 | R17: 33.7 | S17: CONDITIONAL_115AH12V_NOT_OWNER_APPROVED | T17: AGM dealer description; legacy manufacturer sheet includes GEL construction wording, chemistry/revision confirmation needed. Body height214mm total220mm; dealer header6.4kg rejected in favour33.7kg technical sheet. | U17: 3-7days; abroad may vary | V17: 2026-09-11 | W17: OBSERVED_NET_CONDITIONAL_SCOPE | X17: PUBLIC_PRICE_NOT_KP | Y17: UNKNOWN | Z17: deliverables/M02/v001/01_support/all-candidates.csv | AA17: 268.07
A18: EL-BAT-C | B18: ME-08 | C18: service_battery | D18: Victron | E18: AGM Telecom115Ah M8 BAT412105164 | F18: 6 | G18: pcs | H18: EUR | I18: 329.95 | J18: GROSS_RATE_CONFIRMED | K18: 21 | L18: 272.69 | M18: https://ab-marineservice.com/product/12v-115ah-agm-telecom-batt-m8/ | N18: https://www.victronenergy.com/upload/documents/Datasheet-Telecom-batteries-EN.pdf | O18: 395 | P18: 110 | Q18: 293 | R18: 35 | S18: CONDITIONAL_115AH12V_NOT_OWNER_APPROVED | T18: 12 V AGM front terminal;6 units only if owner confirms115Ah12V. No12V housebus inferred. Open page21% supersedes search19%. | U18: backorder3-5workingdays | V18: 2026-09-11 | W18: OBSERVED_NET_CONDITIONAL_SCOPE | X18: PUBLIC_PRICE_NOT_KP | Y18: UNKNOWN | Z18: deliverables/M02/v001/01_support/all-candidates.csv | AA18: 272.69
A19: EL-DIST-A | B19: ME-10 | C19: dc_distribution_module | D19: Victron | E19: Lynx Distributor M8 LYN060102000 | G19: pcs | H19: EUR | I19: 182.75 | J19: NET_EXPLICIT | L19: 182.75 | M19: https://www.dynastart.nl/lyn060102000-lynx-distributor-m8 | N19: https://www.victronenergy.com/media/pg/Lynx_Distributor/en/technical-specifications-lynx-distributor.html | O19: 170 | P19: 80 | Q19: 290 | R19: 2.2 | S19: CONDITIONAL_UNIT_BENCHMARK | T19: Supports24 V;1000 A product rating not yacht demand; four fuse ways, fuses/monitor supply and full installation separate. Source axis hxlxw=290x170x80; check drawing for orientation. | U19: in stock | V19: 2026-09-11 | W19: OBSERVED_NET_CONDITIONAL_SCOPE | X19: PUBLIC_PRICE_NOT_KP | Y19: UNKNOWN | Z19: deliverables/M02/v001/01_support/all-candidates.csv | AA19: 182.75
A20: EL-DIST-B | B20: ME-10 | C20: dc_distribution_panel | D20: Philippi | E20: STV207 020002071 | G20: pcs | H20: EUR | I20: 214.24 | J20: NET_EXPLICIT | L20: 214.24 | M20: https://www.svb24.com/en/philippi-stv207-power-distribution-panel-configurable.html | N20: https://www.philippi-online.de/en/collections/serie_200-marine/products/stv-207 | O20: 70 | P20: 105 | Q20: 210 | S20: CONDITIONAL_UNIT_BENCHMARK | T20: 24 V compatible seven-circuit unit benchmark;10 A standard breakers not approved circuit ratings. DC accessory socket not permission for12V loads on24V. Mass not published. Not complete yacht switchboard. | U20: 2 listed in stock | V20: 2026-09-11 | W20: OBSERVED_NET_CONDITIONAL_SCOPE | X20: PUBLIC_PRICE_NOT_KP | Y20: UNKNOWN | Z20: deliverables/M02/v001/01_support/all-candidates.csv | AA20: 214.24
A21: EL-DIST-C | B21: ME-10 | C21: ac_shore_distribution_panel | D21: Philippi | E21: LAE113 010001130 | G21: pcs | H21: EUR | I21: 331.89 | J21: NET_EXPLICIT | L21: 331.89 | M21: https://www.svb24.com/en/philippi-lae-113-shore-connection-unit.html | N21: https://www.philippi-online.de/en/products/lae-113 | O21: 100 | P21: 260 | Q21: 185 | S21: CONDITIONAL_UNIT_BENCHMARK | T21: Factory230 V50Hz panel benchmark for220VAC target;16A/30mA RCBO and3two-pole10A circuits per official description. Not full multi-source AC switchboard; mass unknown. | U21: 2 listed in stock | V21: 2026-09-11 | W21: OBSERVED_NET_CONDITIONAL_SCOPE | X21: PUBLIC_PRICE_NOT_KP | Y21: UNKNOWN | Z21: deliverables/M02/v001/01_support/all-candidates.csv | AA21: 331.89
