Workbook

Sheet 00_Старт
A1: Тема | B1: Правило
A2: Статус | B2: M03 / 11.09.2026 — рабочая КАЦ с открытыми исходными данными. 36 слотов A/B/C для 12 функциональных пакетов; это не 36 полученных КП и не три утверждённых комплекта яхты.
A3: Yanmar и Fischer Panda | B3: Yanmar добавлен отдельными новыми источниками. Fischer Panda сохранён, добавлены предложения/исполнения. Наличие марки не означает выбор или совместимость с сетью/пуском.
A4: Сравниваем результат | B4: Разные устройства и внутренний BOM допустимы при нужном результате. Основные заданные количества сохраняются. A/B/C — гипотезы исполнения, не ранг цены или качества.
A5: Порядок работы | B5: Согласовать результат и BOM → дополнить источники цен/КП → закрыть комплектность со ссылками → проверить технику/коммерческие условия → доставка и налоги → решение. Слоты PK09–PK11 пока используют общие ориентиры, не три независимые поставки.
A6: Листы | B6: 01: функциональное задание; 02: цены и прямые URL; 03: построчный состав вариантов; 04: полнота; 05: КАЦ; 06: налоговые операции; 07: открытые вопросы.
A7: Известная часть | B7: На листе 05 сумма известных товаров дана отдельно. Полный NET появится только после закрытия состава, цен, исключений источников и двух допусков. Пустая ячейка не означает ноль. Общего итога МО нет.
A8: Количество | B8: 1 двигатель; 2 генератора; 2 основных инвертора; 6+2+1 физических АКБ; 1 водяная установка каждого питания; 1 опреснитель; 2 чиллера. ME06 — 1 функция резерва, не обязательный третий инвертор. Количество бойлеров и обвязки открыто.
A9: Цена | B9: NET в исходной валюте → единичный EUR с округлением HALF_UP до цента → количество. GBP / 0.85915, ECB 10.09.2026. Курс для сравнения, не автоматический курс налоговой декларации.
A10: Доплаты | B10: В 05_КАЦ шесть полей доплат: доставка, страхование, пошлина, оформление, монтаж/ПНР и прочее. Ввести обоснованный ноль, если затрата отсутствует или уже включена. Не учитывать повторно включённую услугу.
A11: НДС | B11: Покупатель, VAT-UE и использование яхты ещё неизвестны. На 06_НДС нет ставки 23% по умолчанию и автоматического вычета. Операции разделять по счетам/таможенным документам; не применять одну ставку ко всему варианту без основания.
A12: НДС и деньги | B12: Невозмещаемый VAT входит в стоимость, вычет показывается отдельно. Денежный платёж и ожидаемый возврат вводятся отдельно: при WNT зачёт может быть без оплаты VAT. График финансирования ещё не рассчитан.
... A15: Сохранность | B15: Исходные U01/M01/M02 и чертежи сохранены. Полные сторонние PDF локально .local/M03, ссылки и SHA в сопровождении. Поставщикам ничего не отправлено.

Sheet 01_Пакеты
A1: Пакет | B1: Результат / система | C1: Группы M01 | D1: Требуемый выход | E1: Фиксированные количества | F1: Полная граница поставки | G1: Критерий приёмки | H1: Открытые параметры
A2: PK01 | B2: Ход яхты | C2: ME-01|ME-02|ME-03 | D2: Нужные скорость, тяга, длительная работа, манёвр и привод гидравлики | E2: 1 двигатель; 1 редуктор предлагается | F2: Двигатель и согласованный редуктор, заводские опоры, управление и жгуты; муфта, упорный узел, вал, дейдвуд, подшипники, уплотнение и согласованный движитель; монтаж, центровка, настройка и собственные испытания | Включения двигателя раскрыть по позициям | Внешнее топливо, охлаждение, выхлоп и вентиляция — PK09; гидронасос и его силовой привод — PK12; механическая совместимость PTO — интерфейс PK01/PK12 | G2: Расход на крейсерском ходу, установленная длина и масса, шум, обслуживание. Номинал 300 л.с. не доказывает одинаковый результат. Единый согласованный режим и протокол проверки результата для слотов A/B/C; собственные монтажные испытания пакета отдельно от общесудовой приёмки. | H2: 300 л.с. — исходный ориентир. Скорость, сопротивление, рабочий режим и PTO не рассчитаны. Измеренная компоновка, монтажные и сервисные зоны, полный состав поставки и интерфейсы ещё требуют подтверждения.
A3: PK02 | B3: Генерация | C3: ME-04 | D3: Питание нагрузок и заряд; согласованный уровень сервиса при отказе одного генератора | E3: 2 генератора | F3: Два генераторных агрегата с согласованными капсулами, опорами, собственным управлением и заводским оснащением; монтаж, местная настройка и испытания каждого | Внешние независимые топливные, водяные и выхлопные ветви — PK09; силовое переключение, распределение и кабели — PK03; пусковые АКБ и резервные связи — PK04 | Параллельную работу не считать включённой по умолчанию | G3: Полезные кВт в условиях МО, пуск нагрузок, шум на одинаковой нагрузке, расход топлива, доступ для сервиса. Единый согласованный режим и протокол проверки результата для слотов A/B/C; собственные монтажные испытания пакета отдельно от общесудовой приёмки. | H3: Около 11.5–12 кВА — исходный ориентир. Постоянные и пиковые нагрузки, режим отказа открыты. Измеренная компоновка, монтажные и сервисные зоны, полный состав поставки и интерфейсы ещё требуют подтверждения.
A4: PK03 | B4: Электропитание | C4: ME-05|ME-06|ME-09|ME-10 | D4: 24 В DC / 220 В AC; питание согласованных потребителей, переключение источников и сохранение воды при отказе общего инвертора | E4: 2 основных инвертора; 1 независимая функция питания насоса | F4: Два основных инвертора/зарядных устройства, береговой ввод и развязка, AC/DC распределение, защиты и общесудовые питающие кабели до границ потребителей; контроль источников, заряд и отключение второстепенных нагрузок, критическое питание | ME-06: одна независимая функция питания AC водяной ветви при отказе гостиничного инвертора; отдельный третий инвертор не назначен | Монтаж, маркировка и электрические проверки | Пусковые силовые пути, изоляция АКБ и BMS — PK04 | G4: Непрерывная мощность при температуре МО, пуск потребителей, время заряда, потери, масса, габариты и резерв. Единый согласованный режим и протокол проверки результата для слотов A/B/C; собственные монтажные испытания пакета отдельно от общесудовой приёмки. | H4: 3 кВА — поисковый класс, не утверждённая мощность. Баланс и береговой ввод открыты. Измеренная компоновка, монтажные и сервисные зоны, полный состав поставки и интерфейсы ещё требуют подтверждения.
A5: PK04 | B5: АКБ и резервный пуск | C5: ME-07|ME-08|ME-27|ME-28 | D5: Автономность сервисных нагрузок и запуск с поста управления при отказе пусковой АКБ | E5: 6 сервисных + 2 генераторных + 1 главного двигателя | F5: Девять физических АКБ по назначению; крепления и защитные объёмы, BMS по химии, батарейная и стартерная коммутация, силовые кабели до согласованных точек подключения PK03/стартеров, дистанционные контакторы, межблокировки и подтверждение состояния | Изоляция неисправной АКБ перед резервным пуском; местная блокировка обслуживания, питание управления и проверка всех разрешённых путей запуска | Зарядные устройства — PK03; независимость и настройки зарядки совместно PK03/PK04 | G5: Доступная энергия при принятом разряде, пусковая способность резервных источников, ресурс и обслуживание. Одинаковые А·ч не достаточны. Единый согласованный режим и протокол проверки результата для слотов A/B/C; собственные монтажные испытания пакета отдельно от общесудовой приёмки. | H5: Уточнение 115 ампер/А·ч и напряжения каждой АКБ ожидается. Пусковые токи, химия и допустимый разряд открыты. Измеренная компоновка, монтажные и сервисные зоны, полный состав поставки и интерфейсы ещё требуют подтверждения.
A6: PK05 | B6: Пресная вода | C6: ME-11|ME-12|ME-17 | D6: Нужные напор и расход при согласованном числе открытых точек; работа резервной ветви | E6: 1 установка 24 В + 1 установка AC | F6: Одна установка 24 В и одна AC; независимые пути с выбором и изоляцией, гидроаккумуляторы, фильтры, обратные клапаны, коллекторы, магистрали до водоразбора и контроль давления | Общие узлы ME-17, включая термостатическое смешение и рециркуляцию ГВС при принятии, принадлежат PK05 | Подача на RO промывку и бойлер — интерфейсы PK06/PK07 | Комплектные фильтры RO — PK06; баки — PK11 | Опрессовка, промывка и проверка обоих режимов | G6: Напор в точке потребления, пульсации, шум, циклы включения, ресурс. Максимальный расход без напора не считать рабочим. Единый согласованный режим и протокол проверки результата для слотов A/B/C; собственные монтажные испытания пакета отдельно от общесудовой приёмки. | H6: Рабочая точка и одновременность водоразбора открыты. 15 л/мин при 2 бар — только поисковый пример. Измеренная компоновка, монтажные и сервисные зоны, полный состав поставки и интерфейсы ещё требуют подтверждения.
A7: PK06 | B7: Опреснение | C7: ME-13 | D7: 150 л/ч воды нужного качества в заданных условиях; промывка и отвод некачественной воды | E7: 1 опреснитель | F7: Один RO с подающим и высоким давлением по исполнению, мембранами, штатными фильтрами, контролем солёности и автоматическим отводом некондиционного продукта, промывкой и управлением | Внутренняя обвязка, крепления, монтаж и наладка; трассы забортной подачи и концентрата этой установки принадлежат PK06, не PK09 | Подача пресной воды на промывку — PK05; приёмный танк — PK11 | Проверить качество, производительность и все автоматические режимы | G7: Энергия на литр, включённая автоматика, шум, размещение модулей, путь извлечения мембран и обслуживание. Единый согласованный режим и протокол проверки результата для слотов A/B/C; собственные монтажные испытания пакета отдельно от общесудовой приёмки. | H7: Температура, солёность и окончательная комплектация открыты. Измеренная компоновка, монтажные и сервисные зоны, полный состав поставки и интерфейсы ещё требуют подтверждения.
A8: PK07 | B8: Горячая вода | C8: ME-14 | D8: Нужный запас воды заданной температуры и восстановление после душей | E8: Количество бойлеров не принято | F8: Бойлеры с электрическим и двигательным нагревом, штатной защитной арматурой, изоляцией, креплениями и сливом; теплоноситель от согласованного присоединения двигателя до бойлера и обратно | Монтаж, проверка нагрева и восстановления запаса | Число и объём не назначены | Термостатическое смешение и общая рециркуляция — PK05, не повторная покупка PK07; питание — PK03 | G8: Полезный запас с подмешиванием, время нагрева, теплопотери, масса, форма и извлечение нагревателя. Единый согласованный режим и протокол проверки результата для слотов A/B/C; собственные монтажные испытания пакета отдельно от общесудовой приёмки. | H8: 40 л / 1200 Вт — рыночный пример, не заданная потребность. Измеренная компоновка, монтажные и сервисные зоны, полный состав поставки и интерфейсы ещё требуют подтверждения.
A9: PK08 | B9: Климат | C9: ME-15|ME-16|ME-26 | D9: Комфортные температура и влажность по помещениям; допустимые шум и режим при отказе одного модуля | E9: 2 чиллера; дополнительное отопление — опция | F9: Два независимо изолируемых чиллерных модуля; шкафы и панели управления, согласованные фанкойлы по помещениям, гидравлические контуры холода и забортного охлаждения, насосы, фильтры, расширение, клапаны, трубная изоляция, воздухораспределение и дренаж конденсата; монтаж, балансировка и наладка | Все собственные HVAC водяные ветви — PK08, не PK09 | Дополнительное отопление ME-26 — отдельная опция с контуром и управлением, без автоматического назначения котла | Фанкойлы — явное расширение до результата, их количество открыто | G9: Холодопроизводительность в одинаковых условиях, потребление, шум, насосы, управление, обвязка и сервисные зоны. Единый согласованный режим и протокол проверки результата для слотов A/B/C; собственные монтажные испытания пакета отдельно от общесудовой приёмки. | H9: 16 000 BTU/h на модуль — пример рынка. Тепловой расчёт и уровень сервиса при отказе открыты. Измеренная компоновка, монтажные и сервисные зоны, полный состав поставки и интерфейсы ещё требуют подтверждения.
A10: PK09 | B10: Обеспечение МО | C10: ME-18|ME-19|ME-22|ME-23 | D10: Надёжные подача топлива, выхлоп, охлаждение, вентиляция и обслуживание | E10: Число элементов определяется выбранными системами | F10: Общие и раздельные внешние топливные ветви двигателя/генераторов: фильтрация, подача, обратки, арматура и сервис; их забортное охлаждение, антисифонные меры, выхлоп и выходы; приток и вытяжка МО с каналами, заслонками и остановом по пожару | Маслосмена, поддоны, местные сервисные узлы и освещение с интерфейсом PK03 | Монтаж, изоляция, маркировка и испытания | Топливные танки и уровнемеры — PK11; заводские внутренние элементы агрегатов — PK01/PK02; отдельные RO/HVAC/гидравлические охладители и ветви — PK06/PK08/PK12 | G10: Полная установленная система с защитами. Компактность должна сохранять доступ и допустимую температуру. Единый согласованный режим и протокол проверки результата для слотов A/B/C; собственные монтажные испытания пакета отдельно от общесудовой приёмки. | H10: Диаметры, тепловыделение, напор, длины и комплектность открыты. Измеренная компоновка, монтажные и сервисные зоны, полный состав поставки и интерфейсы ещё требуют подтверждения.
A11: PK10 | B11: Аварийные системы | C11: ME-20|ME-21 | D11: Осушение расчётного поступления воды, обнаружение и тушение пожара | E11: Число компонентов определяется расчётом | F11: Зональное и аварийное осушение с насосами, ручными средствами, трубами, арматурой, датчиками и независимой тревогой; пожарное обнаружение, стационарное тушение, ручной пуск и контроль готовности | Матрица остановов двигателя/генераторов и вентиляции, собственные исполнительные приводы пожарной отсечки топлива — PK10, корпуса топливной арматуры — PK09 | Монтаж и проверка сценариев, без необоснованного расходования заряда | Числа, защищаемый объём и тип агента открыты | G11: Фактическая производительность, защищённость, доступ и независимость. Цена одного насоса/баллона не равна цене системы. Единый согласованный режим и протокол проверки результата для слотов A/B/C; собственные монтажные испытания пакета отдельно от общесудовой приёмки. | H11: Отсеки, защищаемый объём и аварийные режимы открыты. Измеренная компоновка, монтажные и сервисные зоны, полный состав поставки и интерфейсы ещё требуют подтверждения.
A12: PK11 | B12: Танки и стоки | C12: ME-24|ME-25 | D12: Требуемые запасы, управляемое хранение и откачка стоков | E12: Количество и объёмы открыты | F12: Полезные запасы и стоки: реестр фактических танков, встроенные либо съёмные ёмкости, люки, вентиляция, залив/слив, уровнемеры и управление; санитарная техническая подача, изоляция источников смыва, насосы стоков, откачка и контроль доступа к сбросу | Изготовление встроенного танка и его испытание раскрыть отдельно от испытания всей системы | В рамках учёта M03 — PK11, с интерфейсом корпусному W10.90, без двойной цены | Санприборы, не входящие в перечень МО, — внешний пакет W50.58 | Трубопроводы от танковых сервисных границ — PK05/PK09 по назначению | G12: Полезный объём, гигиена, обслуживание, герметичность и масса. Заводской бак не равен изготовлению встроенного танка. Единый согласованный режим и протокол проверки результата для слотов A/B/C; собственные монтажные испытания пакета отдельно от общесудовой приёмки. | H12: Конструкция встроенных танков, уровни и маршруты доступа открыты. Измеренная компоновка, монтажные и сервисные зоны, полный состав поставки и интерфейсы ещё требуют подтверждения.
A13: PK12 | B13: Гидравлика | C13: ME-29 | D13: Нужная тяга подруливающих и работа всех лебёдок, включая согласованные режимы при остановленном дизеле | E13: Гидропривод обязателен; число потребителей не принято | F13: Полная гидросистема до нужных функций всех подруливающих и всех лебёдок: насосы и выбранный привод, PTO/адаптация либо электрический или отдельный привод, бак, фильтры, охлаждение, распределители, регулирование и защита давления, трассы, местные клапаны, управление и исполнительные гидромоторы/механизмы | Выдать ведомость всех внешних потребителей и включений их пакетов: одинаковый предмет не суммировать дважды | Монтаж, промывка, чистота масла, наладка приоритетов и испытания режимов, в том числе согласованного режима без главного дизеля | Рулевое не включать в общий контур автоматически | G13: Полная стоимость до исполнительных функций, тепло, ток, шум, ресурс, PTO/резерв и объём сервисных зон. Единый согласованный режим и протокол проверки результата для слотов A/B/C; собственные монтажные испытания пакета отдельно от общесудовой приёмки. | H13: Тяга, момент, скорость, одновременность и источники мощности открыты. Измеренная компоновка, монтажные и сервисные зоны, полный состав поставки и интерфейсы ещё требуют подтверждения.

Sheet 02_Цены
A1: Источник_ID | B1: M01 | C1: Производитель | D1: Исполнение | E1: Кол-во ориентир | F1: Ед. | G1: Валюта | H1: Исходная цена | I1: Налоговая основа | J1: Ставка источника % | K1: NET / ед. валюта | L1: NET / ед. EUR | M1: Класс цены | N1: Тип доказательства | O1: Дата цены | P1: Дата просмотра | Q1: Прямая цена | R1: Спецификация | S1: Габарит изделия мм | T1: Масса кг | U1: Технический статус | V1: Включения и ограничения | W1: Наличие | X1: Происхождение записи
A2: PROP-E01 | B2: ME-01|ME-02|ME-03 | C2: Volvo Penta | D2: D4-300 I + HS68A | E2: 1 | F2: package | G2: EUR | H2: 44716 | I2: explicit HT; historical March 2023 | K2: 44716 | L2: =IF(AND(ISNUMBER(K2),K2>=0,G2="EUR"),ROUND(K2,2),IF(AND(ISNUMBER(K2),K2>=0,G2="GBP"),ROUND(ROUND(K2,2)/0.85915,2),"")) -> 44716 | M2: HISTORICAL_NOT_CURRENT | N2: PUBLIC_PRICE_NOT_KP | O2: 2023-03 | P2: 2026-09-11 | Q2: https://www.dbmoteurs.fr/sites/default/files/Volvo-Penta-tarifs-prix-achat-moteurs-2023-DB-Moteurs-motorisation-marine-bateau-plaisance.pdf | R2: https://www.dbmoteurs.fr/sites/default/files/Moteur-Volvo-Penta-D4-270-300-320-fiche-commerciale-2021-47711815-en.pdf | T2: 580 | U2: HISTORICAL_NET_REFERENCE|RFQ_REQUIRED|DUTY_OPEN | V2: 300 metric hp crank / 289 prop shaft at3500rpm; R5; 24V option official but quoted configuration unspecified; HS68A ratio selection open; dimensions for HS85A must not be substituted; ME-03 partial only factory mounts where included: shaft/coupling/thrust unit quantities and price OPEN | W2: 2026 availability unknown | X2: deliverables/M02/v001/01_support/all-candidates.csv
A3: PROP-E02 | B3: ME-01|ME-02|ME-03 | C3: Volvo Penta | D3: D4-300 I + HS85A | E3: 1 | F3: package | G3: EUR | H3: 45977 | I3: explicit HT; historical March 2023 | K3: 45977 | L3: =IF(AND(ISNUMBER(K3),K3>=0,G3="EUR"),ROUND(K3,2),IF(AND(ISNUMBER(K3),K3>=0,G3="GBP"),ROUND(ROUND(K3,2)/0.85915,2),"")) -> 45977 | M3: HISTORICAL_NOT_CURRENT | N3: PUBLIC_PRICE_NOT_KP | O3: 2023-03 | P3: 2026-09-11 | Q3: https://www.dbmoteurs.fr/sites/default/files/Volvo-Penta-tarifs-prix-achat-moteurs-2023-DB-Moteurs-motorisation-marine-bateau-plaisance.pdf | R3: https://www.dbmoteurs.fr/sites/default/files/Moteur-Volvo-Penta-D4-270-300-320-fiche-commerciale-2021-47711815-en.pdf | S3: 1234 × 848 × 794 | T3: 605 | U3: HISTORICAL_NET_REFERENCE|RFQ_REQUIRED|DUTY_OPEN | V3: 300 metric hp crank / 289 prop shaft; 3500rpm R5; 24V option price open; ratio2.500. L=433+801 W=441+407 H=274+520 from drawing; excludes projecting lifting eye/service space; not installation GA; ME-03 partial only factory mounts where included: shaft/coupling/thrust unit quantities and price OPEN | W3: 2026 availability unknown | X3: deliverables/M02/v001/01_support/all-candidates.csv
A4: PROP-E03 | B4: ME-01|ME-02|ME-03 | C4: Volvo Penta | D4: D6-300 I + HS85A | E4: 1 | F4: package | G4: EUR | H4: 50146 | I4: explicit HT; historical March 2023 | K4: 50146 | L4: =IF(AND(ISNUMBER(K4),K4>=0,G4="EUR"),ROUND(K4,2),IF(AND(ISNUMBER(K4),K4>=0,G4="GBP"),ROUND(ROUND(K4,2)/0.85915,2),"")) -> 50146 | M4: HISTORICAL_NOT_CURRENT | N4: PUBLIC_PRICE_NOT_KP | O4: 2023-03 | P4: 2026-09-11 | Q4: https://www.dbmoteurs.fr/sites/default/files/Volvo-Penta-tarifs-prix-achat-moteurs-2023-DB-Moteurs-motorisation-marine-bateau-plaisance.pdf | R4: https://www.dbmoteurs.fr/sites/default/files/Moteur-Volvo-Penta-D6-300-340-380-fiche-commerciale-brochure-2021-47711891-fr-dbmoteurs.pdf | S4: 1470 × 848 × 794 | T4: 690 | U4: HISTORICAL_NET_REFERENCE|RFQ_REQUIRED|DUTY_OPEN | V4: 300 metric hp crank /289 prop shaft;3300rpm. 24V option price open; L=433+1037 W=441+407 H=274+520 drawing dimensions not installation/service envelope; lifting eye extends above dimension; ME-03 partial only factory mounts where included: shaft/coupling/thrust unit quantities and price OPEN | W4: 2026 availability unknown | X4: deliverables/M02/v001/01_support/all-candidates.csv
A5: PROP-E04 | B5: ME-01|ME-02|ME-03 | C5: FPT Industrial | D5: C90 410 rating D 300hp + gearbox RFQ | E5: 1 | F5: package | G5: EUR | I5: RFQ_REQUIRED | L5: =IF(AND(ISNUMBER(K5),K5>=0,G5="EUR"),ROUND(K5,2),IF(AND(ISNUMBER(K5),K5>=0,G5="GBP"),ROUND(ROUND(K5,2)/0.85915,2),"")) | M5: NO_VERIFIED_NET | N5: PUBLIC_PRICE_NOT_KP | O5: UNKNOWN | P5: 2026-09-11 | Q5: https://www.etruck.fi/shop-1 | R5: https://www.fptindustrial.com/-/media/FPT/Brochures/Engines/MARINE/COMMERCIAL/Marine_Commercial_FR_2026.pdf?rev=-1 | S5: 1289 × 861 × 973 | T5: 950 | U5: RFQ_REQUIRED|INCOMPLETE_PACKAGE|DUTY_COMPARISON_OPEN | V5: Official2026 220kW300hp@2000rpm ratingD heavy duty; gearbox unselected/unpriced; shown dimensions length to flywheel and mass ENGINE ONLY; not complete package envelope;24V option RFQ; ME-03 partial only factory mounts where included: shaft/coupling/thrust unit quantities and price OPEN | W5: No exact300hp package price found | X5: deliverables/M02/v001/01_support/all-candidates.csv
A6: PROP-G01 | B6: ME-04|ME-19 | C6: Fischer Panda | D6: Panda12000x PMS | E6: 2 | F6: package | G6: GBP | H6: 16830 | I6: explicit inc vat/ex vat pair | J6: 20 | K6: 14025 | L6: =IF(AND(ISNUMBER(K6),K6>=0,G6="EUR"),ROUND(K6,2),IF(AND(ISNUMBER(K6),K6>=0,G6="GBP"),ROUND(ROUND(K6,2)/0.85915,2),"")) -> 16324.27 | M6: OBSERVED_NET_CONDITIONAL_SCOPE | N6: PUBLIC_PRICE_NOT_KP | O6: UNKNOWN | P6: 2026-09-11 | Q6: https://www.jpcdirect.com/product/fischer-panda-12000x-generator/ | R6: https://www.onefischerpanda.com/marine/marine-generators/xseries-generators/panda-12000x-pms/ | S6: 705 × 450 × 590 | T6: 195 | U6: CONDITIONAL_START_VOLTAGE|AC_COMPATIBILITY_OPEN|RATING_OPEN|UK_REFERENCE | V6: 12kVA10.2kW nominal; Manel continuous10.8kVA9.2kW;50Hz230V +/-3V;12V starter;capsule included spec; verify exactJPCSKU/manufacturer0024660 and installation accessories; UK import/logistics not included; ME-19 partial factory cooling only: external seawater/exhaust runs and installation OPEN; JPC revision conflict H565 / additional700x470x580 and192kg vs OEM705x450x590/195kg: exactSKU CAD RFQ; OEM values retained | W6: Available on back-order; qty2 and lead time RFQ | X6: deliverables/M02/v001/01_support/all-candidates.csv
A7: PROP-G02 | B7: ME-04|ME-19 | C7: Kohler / Rehlko | D7: 12EFKOZD | E7: 2 | F7: package | G7: GBP | H7: 18484.56 | I7: explicit inc vat/ex vat pair | J7: 20 | K7: 15403.8 | L7: =IF(AND(ISNUMBER(K7),K7>=0,G7="EUR"),ROUND(K7,2),IF(AND(ISNUMBER(K7),K7>=0,G7="GBP"),ROUND(ROUND(K7,2)/0.85915,2),"")) -> 17929.12 | M7: OBSERVED_NET_CONDITIONAL_SCOPE | N7: PUBLIC_PRICE_NOT_KP | O7: UNKNOWN | P7: 2026-09-11 | Q7: https://www.jpcdirect.com/product/kohler-12-kilowatt-generator/ | R7: https://techcomm.rehlko.com/techcomm/pdf/g2186.pdf | S7: 1064 × 652.5 × 711 | T7: 385 | U7: CONDITIONAL_CONFIGURATION|AC_COMPATIBILITY_OPEN|RATING_OPEN|UK_REFERENCE | V7: Singlephase115/230V50Hz:12kW12kVA continuous140C rise;11/11continuous115C;10.5/10.5prime. Official12or24V; JPC exactstarter/shield revision RFQ. Official shield mass385dry398wet; dealer406kg conflict. No borrowing US24V price scope; ME-19 partial factory cooling only: external seawater/exhaust runs and installation OPEN | W7: Available on back-order | X7: deliverables/M02/v001/01_support/all-candidates.csv
A8: PROP-G03 | B8: ME-04|ME-19 | C8: Volpi Tecno Energia | D8: Paguro12000V AP12023050M0 | E8: 2 | F8: package | G8: EUR | H8: 14935.8 | I8: direct page12446.50 +IVA; gross14935.80 labelled SK20% locale | J8: 20 | K8: 12446.5 | L8: =IF(AND(ISNUMBER(K8),K8>=0,G8="EUR"),ROUND(K8,2),IF(AND(ISNUMBER(K8),K8>=0,G8="GBP"),ROUND(ROUND(K8,2)/0.85915,2),"")) -> 12446.5 | M8: OBSERVED_NET_CONDITIONAL_SCOPE | N8: PUBLIC_PRICE_NOT_KP | O8: UNKNOWN | P8: 2026-09-11 | Q8: https://www.manelservice.com/it/gruppi-elettrogeni-marini/3925-vte-paguro-12000-v-ap12023050m0.html | R8: https://www.volpitecno.com/portfolio/paguro-12000-v-10-kw-2000-%C3%B7-3000-g-1/ | S8: 770 × 460 × 620 | T8: 180 | U8: CONDITIONAL_START_VOLTAGE|AC_COMPATIBILITY_OPEN|REVISION_OPEN | V8: 12kVA10kW continuous50Hz230V;12V starter;mass165capsule+15control electronics. Official dimensions capsule only; separate electronics footprint RFQ. Dealer/allpa dimensions/mass differ; exact SKU installationdrawing required. Published net directly not Polish VAT assumption; ME-19 partial factory cooling only: external seawater/exhaust runs and installation OPEN | W8: Manel Disponibile; qty2 and delivery date RFQ | X8: deliverables/M02/v001/01_support/all-candidates.csv
A9: PROP-G04 | B9: ME-04|ME-19 | C9: Kohler / Rehlko | D9: 12EFKOZD24-SS | E9: 2 | F9: package | G9: USD | H9: 20165.6 | I9: not stated | L9: =IF(AND(ISNUMBER(K9),K9>=0,G9="EUR"),ROUND(K9,2),IF(AND(ISNUMBER(K9),K9>=0,G9="GBP"),ROUND(ROUND(K9,2)/0.85915,2),"")) | M9: NO_VERIFIED_NET | N9: PUBLIC_PRICE_NOT_KP | O9: UNKNOWN | P9: 2026-09-11 | Q9: https://mmarineonline.com/products/kohler-marine-diesel-generator-24v-12efkozd-ss-50hz-with-sound-shield | R9: https://techcomm.rehlko.com/techcomm/pdf/g2186.pdf | S9: 1064 × 652.5 × 711 | T9: 385 | U9: NO_NET|US_REFERENCE_ONLY|AC_COMPATIBILITY_OPEN|RATING_OPEN | V9: Alternative offer for G02 not fourthgenerator;24V plus shield explicitlySKU; tax/import/Poland availability unknown; price originalUSD noFX; ME-19 partial factory cooling only: external seawater/exhaust runs and installation OPEN | W9: Contradictory availability template; RFQ | X9: deliverables/M02/v001/01_support/all-candidates.csv
A10: EL-INV-A | B10: ME-05 | C10: Victron | D10: MultiPlus-II 24/3000/70-32 PMP242305010 | E10: 2 | F10: pcs | G10: EUR | H10: 879.95 | I10: GROSS_RATE_CONFIRMED | J10: 19 | K10: 739.45 | L10: =IF(AND(ISNUMBER(K10),K10>=0,G10="EUR"),ROUND(K10,2),IF(AND(ISNUMBER(K10),K10>=0,G10="GBP"),ROUND(ROUND(K10,2)/0.85915,2),"")) -> 739.45 | M10: OBSERVED_NET_CONDITIONAL_SCOPE | N10: PUBLIC_PRICE_NOT_KP | O10: UNKNOWN | P10: 2026-09-11 | Q10: https://www.svb.de/de/victron-wechselrichter-ladegeraet-multiplus-ii-24-v-3000-va-70-a.html | R10: https://www.victronenergy.com/media/pg/MultiPlus-II_230V/en/technical-specifications-mp-ii-230v.html | S10: 141 × 268 × 499 | T10: 19 | U10: CONDITIONAL_3KVA_REFERENCE | V10: 24 V input; factory 230 V. 3000 VA not 3000 W: 2400 W at25C/2200 W at40C; charger70 A. 2 devices architecture target, capacity unapproved. | W10: 1 listed in stock; second unconfirmed | X10: deliverables/M02/v001/01_support/all-candidates.csv
A11: EL-INV-B | B11: ME-05 | C11: Victron | D11: MultiPlus-II GX 24/3000/70-32 PMP242306000 | E11: 2 | F11: pcs | G11: EUR | H11: 999.95 | I11: GROSS_RATE_CONFIRMED | J11: 19 | K11: 840.29 | L11: =IF(AND(ISNUMBER(K11),K11>=0,G11="EUR"),ROUND(K11,2),IF(AND(ISNUMBER(K11),K11>=0,G11="GBP"),ROUND(ROUND(K11,2)/0.85915,2),"")) -> 840.29 | M11: OBSERVED_NET_CONDITIONAL_SCOPE | N11: PUBLIC_PRICE_NOT_KP | O11: UNKNOWN | P11: 2026-09-11 | Q11: https://www.svb.de/de/victron-wechselrichter-ladegeraet-multiplus-ii-gx-24-v-3000-va-70-a.html | R11: https://www.victronenergy.com/media/pg/MultiPlus-II_GX/en/technical-specifications-mp-ii-gx-230v.html | S11: 147 × 275 × 506 | T11: 20 | U11: CONDITIONAL_3KVA_REFERENCE | V11: 24 V; factory230 V;2400 W at25C/2200 W at40C;70 A. GX monitoring differs; two GX units not required by yacht specification. Current manual geometry differs from catalogue: confirm revision. | W11: expected1-2weeks | X11: deliverables/M02/v001/01_support/all-candidates.csv
A12: EL-INV-C | B12: ME-05 | C12: Mastervolt | D12: CombiMaster 24/3000-60 230V 35023000 | E12: 2 | F12: pcs | G12: EUR | H12: 1599.96 | I12: GROSS_RATE_CONFIRMED | J12: 19 | K12: 1344.5 | L12: =IF(AND(ISNUMBER(K12),K12>=0,G12="EUR"),ROUND(K12,2),IF(AND(ISNUMBER(K12),K12>=0,G12="GBP"),ROUND(ROUND(K12,2)/0.85915,2),"")) -> 1344.5 | M12: OBSERVED_NET_CONDITIONAL_SCOPE | N12: PUBLIC_PRICE_NOT_KP | O12: UNKNOWN | P12: 2026-09-11 | Q12: https://www.svb.de/de/mastervolt-wechselrichter-ladegeraet-combimaster-24-v-3000-va-60-a.html?question_sort=oldest | R12: https://www.mastervolt.com/products/combimaster/combimaster-24-3000-60-230-v/ | S12: 155 × 284 × 448 | T12: 9.3 | U12: CONDITIONAL_3KVA_NOT_EQUAL_W | V12: 24 V; factory230 V;3000 VA/2600 W at40C;60 A charger;25 A transfer versus32 A Victron. Parallel operation not qualified. | W12: 1 listed in stock; second unconfirmed | X12: deliverables/M02/v001/01_support/all-candidates.csv
A13: EL-ISO-A | B13: ME-09 | C13: Victron | D13: 3600 ITR040362042 | F13: pcs | G13: EUR | H13: 436.93 | I13: NET_EXPLICIT | K13: 436.93 | L13: =IF(AND(ISNUMBER(K13),K13>=0,G13="EUR"),ROUND(K13,2),IF(AND(ISNUMBER(K13),K13>=0,G13="GBP"),ROUND(ROUND(K13,2)/0.85915,2),"")) -> 436.93 | M13: OBSERVED_NET_CONDITIONAL_SCOPE | N13: PUBLIC_PRICE_NOT_KP | O13: UNKNOWN | P13: 2026-09-11 | Q13: https://www.svb24.com/en/p/victron-isolation-transformer-3600-w-115-230-v.html | R13: https://www.victronenergy.com/upload/documents/Datasheet-Isolation-Transformers-EN.pdf | S13: 221 × 258 × 362 | T13: 21.7 | U13: CONDITIONAL_UNIT_BENCHMARK_DIMENSIONS_DEALER | V13: 3.6 class; quantity and shore capacity unknown. Dimensions/mass from opened dealer data pending native drawing confirmation; no substitute of32A at115V for32A at230V. | W13: expected1-2weeks | X13: deliverables/M02/v001/01_support/all-candidates.csv
A14: EL-ISO-B | B14: ME-09 | C14: Mastervolt | D14: Mass GI3.5 88000355 | F14: pcs | G14: EUR | H14: 1008.36 | I14: NET_EXPLICIT | K14: 1008.36 | L14: =IF(AND(ISNUMBER(K14),K14>=0,G14="EUR"),ROUND(K14,2),IF(AND(ISNUMBER(K14),K14>=0,G14="GBP"),ROUND(ROUND(K14,2)/0.85915,2),"")) -> 1008.36 | M14: OBSERVED_NET_CONDITIONAL_SCOPE | N14: PUBLIC_PRICE_NOT_KP | O14: UNKNOWN | P14: 2026-09-11 | Q14: https://www.svb24.com/en/mastervolt-mass-gi-3-5-isolation-transformer-16-a-3-5-kw.html | R14: https://www.mastervolt.com/products/mass-gi/mass-gi-35-kva-16a-lightweight/ | S14: 144 × 261 × 340 | T14: 6 | U14: CONDITIONAL_UNIT_BENCHMARK | V14: 3500 VA at230 V;16 A;HF technology;source IP23 supersedes dealer IP21. Not complete shore protection. | W14: 1 listed in stock | X14: deliverables/M02/v001/01_support/all-candidates.csv
A15: EL-ISO-C | B15: ME-09 | C15: WhisperPower | D15: GI3600 60110102 | F15: pcs | G15: EUR | H15: 1885 | I15: GROSS_RATE_UNCONFIRMED | L15: =IF(AND(ISNUMBER(K15),K15>=0,G15="EUR"),ROUND(K15,2),IF(AND(ISNUMBER(K15),K15>=0,G15="GBP"),ROUND(ROUND(K15,2)/0.85915,2),"")) | M15: NO_VERIFIED_NET | N15: PUBLIC_PRICE_NOT_KP | O15: UNKNOWN | P15: 2026-09-11 | Q15: https://www.hansenautic.de/36377/wp-gi-compact-galvanic-isolation-transformator-230v-16a-120v-32a/ | R15: https://www.whisperpower.com/gi-3600-compact-galvanic-isolation-transformer | S15: 208 × 290 × 380 | T15: 28.6 | U15: CONDITIONAL_NET_PENDING_TAX | V15: 3.6 kVA;230/110 V;16/32 A. Open page confirms VAT included but not rate: NET deliberately blank. | W15: availability on request | X15: deliverables/M02/v001/01_support/all-candidates.csv
A16: EL-BAT-A | B16: ME-08 | C16: Exide | D16: ER550 12V115Ah | E16: 6 | F16: pcs | G16: EUR | H16: 166.89 | I16: GROSS_RATE_CONFIRMED | J16: 19 | K16: 140.24 | L16: =IF(AND(ISNUMBER(K16),K16>=0,G16="EUR"),ROUND(K16,2),IF(AND(ISNUMBER(K16),K16>=0,G16="GBP"),ROUND(ROUND(K16,2)/0.85915,2),"")) -> 140.24 | M16: OBSERVED_NET_CONDITIONAL_SCOPE | N16: PUBLIC_PRICE_NOT_KP | O16: UNKNOWN | P16: 2026-09-11 | Q16: https://online-batterien.de/a/exide-er550-dual-versorgungsbatterie-starterbatterie-12v-115ah-550wh/400440 | R16: https://www.exidegroup.com/en/document/ml-brochure-2022 | S16: 349 × 175 × 235 | T16: 28 | U16: CONDITIONAL_115AH12V_NOT_OWNER_APPROVED | V16: Flooded. Owner only said115 amperes; Ah and unit voltage unconfirmed. 6 physical units; no bank wiring/capacity inferred. Deposit extra. Dealer350mm/29kg differs from brochure. | W16: not in stock | X16: deliverables/M02/v001/01_support/all-candidates.csv
A17: EL-BAT-B | B17: ME-08 | C17: Aquamot | D17: ALS12115 12V115Ah | E17: 6 | F17: pcs | G17: EUR | H17: 319 | I17: GROSS_RATE_CONFIRMED | J17: 19 | K17: 268.07 | L17: =IF(AND(ISNUMBER(K17),K17>=0,G17="EUR"),ROUND(K17,2),IF(AND(ISNUMBER(K17),K17>=0,G17="GBP"),ROUND(ROUND(K17,2)/0.85915,2),"")) -> 268.07 | M17: OBSERVED_NET_CONDITIONAL_SCOPE | N17: PUBLIC_PRICE_NOT_KP | O17: UNKNOWN | P17: 2026-09-11 | Q17: https://www.nothnagel-marine.de/product_info.php?info=p3857_aquamot---power-battery--dc-battery-als12115-12v-115ah-agm-deep-cycle-battery.html&language=en | R17: https://aquamot.at/wp-content/uploads/2018/02/Die-Batterie-Aquamot.pdf | S17: 331 × 176 × 220 | T17: 33.7 | U17: CONDITIONAL_115AH12V_NOT_OWNER_APPROVED | V17: AGM dealer description; legacy manufacturer sheet includes GEL construction wording, chemistry/revision confirmation needed. Body height214mm total220mm; dealer header6.4kg rejected in favour33.7kg technical sheet. | W17: 3-7days; abroad may vary | X17: deliverables/M02/v001/01_support/all-candidates.csv
A18: EL-BAT-C | B18: ME-08 | C18: Victron | D18: AGM Telecom115Ah M8 BAT412105164 | E18: 6 | F18: pcs | G18: EUR | H18: 329.95 | I18: GROSS_RATE_CONFIRMED | J18: 21 | K18: 272.69 | L18: =IF(AND(ISNUMBER(K18),K18>=0,G18="EUR"),ROUND(K18,2),IF(AND(ISNUMBER(K18),K18>=0,G18="GBP"),ROUND(ROUND(K18,2)/0.85915,2),"")) -> 272.69 | M18: OBSERVED_NET_CONDITIONAL_SCOPE | N18: PUBLIC_PRICE_NOT_KP | O18: UNKNOWN | P18: 2026-09-11 | Q18: https://ab-marineservice.com/product/12v-115ah-agm-telecom-batt-m8/ | R18: https://www.victronenergy.com/upload/documents/Datasheet-Telecom-batteries-EN.pdf | S18: 395 × 110 × 293 | T18: 35 | U18: CONDITIONAL_115AH12V_NOT_OWNER_APPROVED | V18: 12 V AGM front terminal;6 units only if owner confirms115Ah12V. No12V housebus inferred. Open page21% supersedes search19%. | W18: backorder3-5workingdays | X18: deliverables/M02/v001/01_support/all-candidates.csv
A19: EL-DIST-A | B19: ME-10 | C19: Victron | D19: Lynx Distributor M8 LYN060102000 | F19: pcs | G19: EUR | H19: 182.75 | I19: NET_EXPLICIT | K19: 182.75 | L19: =IF(AND(ISNUMBER(K19),K19>=0,G19="EUR"),ROUND(K19,2),IF(AND(ISNUMBER(K19),K19>=0,G19="GBP"),ROUND(ROUND(K19,2)/0.85915,2),"")) -> 182.75 | M19: OBSERVED_NET_CONDITIONAL_SCOPE | N19: PUBLIC_PRICE_NOT_KP | O19: UNKNOWN | P19: 2026-09-11 | Q19: https://www.dynastart.nl/lyn060102000-lynx-distributor-m8 | R19: https://www.victronenergy.com/media/pg/Lynx_Distributor/en/technical-specifications-lynx-distributor.html | S19: 170 × 80 × 290 | T19: 2.2 | U19: CONDITIONAL_UNIT_BENCHMARK | V19: Supports24 V;1000 A product rating not yacht demand; four fuse ways, fuses/monitor supply and full installation separate. Source axis hxlxw=290x170x80; check drawing for orientation. | W19: in stock | X19: deliverables/M02/v001/01_support/all-candidates.csv
A20: EL-DIST-B | B20: ME-10 | C20: Philippi | D20: STV207 020002071 | F20: pcs | G20: EUR | H20: 214.24 | I20: NET_EXPLICIT | K20: 214.24 | L20: =IF(AND(ISNUMBER(K20),K20>=0,G20="EUR"),ROUND(K20,2),IF(AND(ISNUMBER(K20),K20>=0,G20="GBP"),ROUND(ROUND(K20,2)/0.85915,2),"")) -> 214.24 | M20: OBSERVED_NET_CONDITIONAL_SCOPE | N20: PUBLIC_PRICE_NOT_KP | O20: UNKNOWN | P20: 2026-09-11 | Q20: https://www.svb24.com/en/philippi-stv207-power-distribution-panel-configurable.html | R20: https://www.philippi-online.de/en/collections/serie_200-marine/products/stv-207 | S20: 70 × 105 × 210 | U20: CONDITIONAL_UNIT_BENCHMARK | V20: 24 V compatible seven-circuit unit benchmark;10 A standard breakers not approved circuit ratings. DC accessory socket not permission for12V loads on24V. Mass not published. Not complete yacht switchboard. | W20: 2 listed in stock | X20: deliverables/M02/v001/01_support/all-candidates.csv
A21: EL-DIST-C | B21: ME-10 | C21: Philippi | D21: LAE113 010001130 | F21: pcs | G21: EUR | H21: 331.89 | I21: NET_EXPLICIT | K21: 331.89 | L21: =IF(AND(ISNUMBER(K21),K21>=0,G21="EUR"),ROUND(K21,2),IF(AND(ISNUMBER(K21),K21>=0,G21="GBP"),ROUND(ROUND(K21,2)/0.85915,2),"")) -> 331.89 | M21: OBSERVED_NET_CONDITIONAL_SCOPE | N21: PUBLIC_PRICE_NOT_KP | O21: UNKNOWN | P21: 2026-09-11 | Q21: https://www.svb24.com/en/philippi-lae-113-shore-connection-unit.html | R21: https://www.philippi-online.de/en/products/lae-113 | S21: 100 × 260 × 185 | U21: CONDITIONAL_UNIT_BENCHMARK | V21: Factory230 V50Hz panel benchmark for220VAC target;16A/30mA RCBO and3two-pole10A circuits per official description. Not full multi-source AC switchboard; mass unknown. | W21: 2 listed in stock | X21: deliverables/M02/v001/01_support/all-candidates.csv
A22: EL-REM-A | B22: ME-28 | C22: Blue Sea | D22: ML-RBS7702 24V | F22: pcs | G22: EUR | H22: 239.45 | I22: NET_EXPLICIT | K22: 239.45 | L22: =IF(AND(ISNUMBER(K22),K22>=0,G22="EUR"),ROUND(K22,2),IF(AND(ISNUMBER(K22),K22>=0,G22="GBP"),ROUND(ROUND(K22,2)/0.85915,2),"")) -> 239.45 | M22: OBSERVED_NET_CONDITIONAL_SCOPE | N22: PUBLIC_PRICE_NOT_KP | O22: UNKNOWN | P22: 2026-09-11 | Q22: https://www.svb24.com/en/blue-sea-hd-remote-battery-switch-24v.html | R22: https://www.bluesea.com/products/7702/ML-RBS_Remote_Battery_Switch_with_Manual_Control_-_24V_DC_500A | T22: 0.95 | U22: CONDITIONAL_UNIT_BENCHMARK | V22: Manual override;24V coil;500A continuous product rating. Quantity, control failover, crank duty and24V live switching not qualified; dimensions drawing pending. | W22: 9 listed in stock | X22: deliverables/M02/v001/01_support/all-candidates.csv
A23: EL-REM-B | B23: ME-28 | C23: Blue Sea | D23: 7703 24V | F23: pcs | G23: EUR | H23: 226.85 | I23: NET_EXPLICIT | K23: 226.85 | L23: =IF(AND(ISNUMBER(K23),K23>=0,G23="EUR"),ROUND(K23,2),IF(AND(ISNUMBER(K23),K23>=0,G23="GBP"),ROUND(ROUND(K23,2)/0.85915,2),"")) -> 226.85 | M23: OBSERVED_NET_CONDITIONAL_SCOPE | N23: PUBLIC_PRICE_NOT_KP | O23: UNKNOWN | P23: 2026-09-11 | Q23: https://www.svb24.com/en/blue-sea-universal-solenoid-switch-24-v.html | R23: https://d2pyqm2yd3fw2i.cloudfront.net/files/resources/instructions/990180170-006.pdf | U23: CONDITIONAL_UNIT_BENCHMARK | V23: Solenoid unit benchmark without manual override of7702; not automatic equivalent. Physical dimensions/mass unverified. No assertion reserve-start scheme works. | W23: 2 listed in stock | X23: deliverables/M02/v001/01_support/all-candidates.csv
A24: EL-OPEN-PUMP | B24: ME-06 | D24: UNSIZED | E24: 1 | F24: function | I24: UNKNOWN | L24: =IF(AND(ISNUMBER(K24),K24>=0,G24="EUR"),ROUND(K24,2),IF(AND(ISNUMBER(K24),K24>=0,G24="GBP"),ROUND(ROUND(K24,2)/0.85915,2),"")) | M24: NO_VERIFIED_NET | N24: PUBLIC_PRICE_NOT_KP | O24: UNKNOWN | P24: 2026-09-11 | U24: OPEN_LOAD_AND_STARTUP | V24: 1 independent function, not necessarily extra inverter. Select after pump running power/start waveform/duty; avoid double counting ME05. | W24: NOT_CONFIRMED | X24: deliverables/M02/v001/01_support/all-candidates.csv
A25: EL-OPEN-MAIN | B25: ME-07 | D25: UNSIZED | E25: 1 | F25: pcs | I25: UNKNOWN | L25: =IF(AND(ISNUMBER(K25),K25>=0,G25="EUR"),ROUND(K25,2),IF(AND(ISNUMBER(K25),K25>=0,G25="GBP"),ROUND(ROUND(K25,2)/0.85915,2),"")) | M25: NO_VERIFIED_NET | N25: PUBLIC_PRICE_NOT_KP | O25: UNKNOWN | P25: 2026-09-11 | U25: OPEN_START_VOLTAGE_CCA | V25: 1 physical owner battery, capacity/voltage/chemistry unknown. Not automatically ER550 or service115Ah. | W25: NOT_CONFIRMED | X25: deliverables/M02/v001/01_support/all-candidates.csv
A26: EL-OPEN-GEN | B26: ME-27 | D26: UNSIZED | E26: 2 | F26: pcs | I26: UNKNOWN | L26: =IF(AND(ISNUMBER(K26),K26>=0,G26="EUR"),ROUND(K26,2),IF(AND(ISNUMBER(K26),K26>=0,G26="GBP"),ROUND(ROUND(K26,2)/0.85915,2),"")) | M26: NO_VERIFIED_NET | N26: PUBLIC_PRICE_NOT_KP | O26: UNKNOWN | P26: 2026-09-11 | U26: OPEN_START_VOLTAGE_CCA | V26: 2 physical owner batteries for2generators; capacity/voltage/CCA unknown; keep9total with6service+1main. No fictitious unit price. | W26: NOT_CONFIRMED | X26: deliverables/M02/v001/01_support/all-candidates.csv
A27: WC-RO-01 | B27: ME-13 | C27: Aquatec | D27: AC150 230V single phase | E27: 1 | F27: шт | G27: EUR | H27: 7539 | I27: EXPLICIT_NET_AND_19_PERCENT_GROSS | J27: 19 | K27: 6335.29 | L27: =IF(AND(ISNUMBER(K27),K27>=0,G27="EUR"),ROUND(K27,2),IF(AND(ISNUMBER(K27),K27>=0,G27="GBP"),ROUND(ROUND(K27,2)/0.85915,2),"")) -> 6335.29 | M27: OBSERVED_NET_CONDITIONAL_SCOPE | N27: PUBLIC_PRICE_NOT_KP | O27: UNKNOWN | P27: 2026-09-11 | Q27: https://www.aquatec-watermaker.de/wassermacher-produkt-ac150-ac240.html | R27: https://www.aquatec-watermaker.de/wassermacher-produkt-ac150-ac240.html | U27: FUNCTION_PARITY_OPEN;220V_COMPATIBILITY_OPEN | V27: 150 L/h nominal ±10% at25C/35000ppm; modular conventional HP pump; base price only: automatic flush/salinity/reject parity must be itemised; generator minimum4kW manufacturer target, not electrical demand or selection | W27: NOT_CONFIRMED | X27: deliverables/M02/v001/01_support/all-candidates.csv
A28: WC-RO-02 | B28: ME-13 | C28: Schenker | D28: ZEN150 24V/230V Touch plus salinity/reject | E28: 1 | F28: шт | G28: EUR | H28: 12820.2 | I28: FROM_GROSS_EXPLICIT_20_PERCENT | J28: 20 | K28: 10683.5 | L28: =IF(AND(ISNUMBER(K28),K28>=0,G28="EUR"),ROUND(K28,2),IF(AND(ISNUMBER(K28),K28>=0,G28="GBP"),ROUND(ROUND(K28,2)/0.85915,2),"")) -> 10683.5 | M28: FROM_INCOMPLETE_CONFIGURATION | N28: PUBLIC_PRICE_NOT_KP | O28: UNKNOWN | P28: 2026-09-11 | Q28: https://mar-nautic.com/schenker-watermaker-zen-150 | R28: https://schenkerwatermakers.com/wp-content/uploads/2025/03/ZEN150_datasheet_v4.pdf | U28: FROM_PRICE_NOT_CONFIGURED;RFQ_REQUIRED | V28: Observed FROM base price; net is FROM benchmark only, NOT complete Touch/salinity/reject price. Nominal150L/h. Manufacturer230V±15% includes220V. Basic has no salinity; Touch optional; 24V variant permitted. Modular unit dimensions not total installed envelope. | W28: Out of stock; order lead time on request | X28: deliverables/M02/v001/01_support/all-candidates.csv
A29: WC-RO-03 | B29: ME-13 | C29: Osmosea | D29: NEW12 150C 24V | E29: 1 | F29: шт | G29: EUR | L29: =IF(AND(ISNUMBER(K29),K29>=0,G29="EUR"),ROUND(K29,2),IF(AND(ISNUMBER(K29),K29>=0,G29="GBP"),ROUND(ROUND(K29,2)/0.85915,2),"")) | M29: NO_VERIFIED_NET | N29: PUBLIC_PRICE_NOT_KP | O29: UNKNOWN | P29: 2026-09-11 | Q29: https://www.manelservice.com/en/marine-desalination-systems/17102-osmosea-new12-150c-nautical-watermaker-150-lth.html | R29: https://osmosea.it/en/new-12/ | T29: 63 | U29: RFQ_REQUIRED;COMPACT_CANDIDATE | V29: Official150L/h/600W; flush/salinometer/unsafe-water discard included. Official63kg conflicts dealer65kg; dimensions dealer796x317x408 not official therefore blank. Dealer install/service kits included vs manufacturer optional: reconcile | W29: NOT_CONFIRMED | X29: deliverables/M02/v001/01_support/all-candidates.csv
A30: WC-DC-01 | B30: ME-11 | C30: CEM | D30: OSC-16.062.24 / OEM identity reconcile | E30: 1 | F30: шт | G30: EUR | H30: 1229.9 | I30: EXPLICIT_HT | K30: 1024.92 | L30: =IF(AND(ISNUMBER(K30),K30>=0,G30="EUR"),ROUND(K30,2),IF(AND(ISNUMBER(K30),K30>=0,G30="GBP"),ROUND(ROUND(K30,2)/0.85915,2),"")) -> 1024.92 | M30: OBSERVED_NET_CONDITIONAL_SCOPE | N30: PUBLIC_PRICE_NOT_KP | O30: UNKNOWN | P30: 2026-09-11 | Q30: https://www.comptoirnautique.com/groupe-d-eau-a-pressostat/53022-cem-elettromeccanica-autoclave-cem-vase-expansion-inox-20l-24v-50-l-min.html | R30: https://cempumps.com/wp-content/uploads/2024/10/Autoclavi_20L-20X.pdf | U30: WORKING_POINT_AND_OEM_ID_OPEN | V30: 24V20L accumulator; dealer50L/min max; source model mapping not proven. Common proposed test15L/min at2bar NOT verified. Do not add included tank again. | W30: Preorder; replenishment23/09/2026 | X30: deliverables/M02/v001/01_support/all-candidates.csv
A31: WC-DC-02 | B31: ME-11 | C31: Gianneschi | D31: EcoInox1 GE011 24V20L | E31: 1 | F31: шт | G31: EUR | H31: 1311.9 | I31: EXPLICIT_HT | K31: 1093.25 | L31: =IF(AND(ISNUMBER(K31),K31>=0,G31="EUR"),ROUND(K31,2),IF(AND(ISNUMBER(K31),K31>=0,G31="GBP"),ROUND(ROUND(K31,2)/0.85915,2),"")) -> 1093.25 | M31: OBSERVED_NET_CONDITIONAL_SCOPE | N31: PUBLIC_PRICE_NOT_KP | O31: UNKNOWN | P31: 2026-09-11 | Q31: https://www.comptoirnautique.com/groupe-d-eau-hydrophore/22947-gianneschi-groupe-d-eau-ecoinox-1-avec-reservoir-20l-24v-45lmin-7024.html | R31: https://www.gianneschipumps.com/GIANNESCHI_Brochure-web.pdf | U31: WORKING_POINT_OPEN | V31: 45L/min max; common proposed15L/min at2bar needs curve. Includes20L tank/gauge/pressure switch; current OEM revision confirmation. | W31: In stock48/72h | X31: deliverables/M02/v001/01_support/all-candidates.csv
A32: WC-DC-03 | B32: ME-11 | C32: ENAG | D32: GH24-0.37-24L-OT RB18-ED | E32: 1 | F32: шт | G32: EUR | L32: =IF(AND(ISNUMBER(K32),K32>=0,G32="EUR"),ROUND(K32,2),IF(AND(ISNUMBER(K32),K32>=0,G32="GBP"),ROUND(ROUND(K32,2)/0.85915,2),"")) | M32: NO_VERIFIED_NET | N32: PUBLIC_PRICE_NOT_KP | O32: UNKNOWN | P32: 2026-09-11 | Q32: https://www.enag.fr/english/wp-content/uploads/sites/5/2022/11/FC-GH-EN-C.pdf | R32: https://www.enag.fr/english/wp-content/uploads/sites/5/2022/11/FC-GH-EN-C.pdf | T32: 29 | U32: RFQ_REQUIRED;WORKING_POINT_OPEN | V32: Official24V/0.37kW; 1m3/h at30m published point; pressure switch1.5/2.5bar.24L tank differs20L competitors: standardise accumulator scope before comparison. Dimensions drawing orientation not mapped into LWH. | W32: NOT_CONFIRMED | X32: deliverables/M02/v001/01_support/all-candidates.csv
A33: WC-AC-01 | B33: ME-12 | C33: CEM | D33: J-INOX/20X 230M | E33: 1 | F33: шт | G33: EUR | L33: =IF(AND(ISNUMBER(K33),K33>=0,G33="EUR"),ROUND(K33,2),IF(AND(ISNUMBER(K33),K33>=0,G33="GBP"),ROUND(ROUND(K33,2)/0.85915,2),"")) | M33: NO_VERIFIED_NET | N33: PUBLIC_PRICE_NOT_KP | O33: UNKNOWN | P33: 2026-09-11 | Q33: https://cempumps.com/wp-content/uploads/2024/10/Autoclavi_20L-20X.pdf | R33: https://cempumps.com/wp-content/uploads/2024/10/Autoclavi_20L-20X.pdf | U33: RFQ_REQUIRED;220V_COMPATIBILITY_OPEN;WORKING_POINT_OPEN | V33: Official230V singlephase variant exists. Proposedcommon15L/min at2bar not accepted from maxflow.20L stainless tank included. No price borrowed from24V sibling. | W33: NOT_CONFIRMED | X33: deliverables/M02/v001/01_support/all-candidates.csv
A34: WC-AC-02 | B34: ME-12 | C34: Gianneschi | D34: EcoInox2 GE017 230V20L | E34: 1 | F34: шт | G34: EUR | H34: 1263 | I34: EXPLICIT_HT | K34: 1052.5 | L34: =IF(AND(ISNUMBER(K34),K34>=0,G34="EUR"),ROUND(K34,2),IF(AND(ISNUMBER(K34),K34>=0,G34="GBP"),ROUND(ROUND(K34,2)/0.85915,2),"")) -> 1052.5 | M34: OBSERVED_NET_CONDITIONAL_SCOPE | N34: PUBLIC_PRICE_NOT_KP | O34: UNKNOWN | P34: 2026-09-11 | Q34: https://www.tyboat.com/achat/P-57388-gianneschi-groupe-d-eau-ecoinox2-3-5-bars-0-45-kw-55-litres-minute-reservoir-20-litres-230-volts.html | R34: https://www.gianneschipumps.com/GIANNESCHI_Brochure-web.pdf | U34: 220V_COMPATIBILITY_OPEN;WORKING_POINT_OPEN | V34: Open page1052.50HT supersedes search992.50. Dealer max55L/min conflicts Kent45: curves required.0.45kW/20L; common15L/min at2bar not verified. | W34: Stock1–6businessdays | X34: deliverables/M02/v001/01_support/all-candidates.csv
A35: WC-AC-03 | B35: ME-12 | C35: ENAG | D35: GH230mono-0.37-24L-JET M-ED | E35: 1 | F35: шт | G35: EUR | L35: =IF(AND(ISNUMBER(K35),K35>=0,G35="EUR"),ROUND(K35,2),IF(AND(ISNUMBER(K35),K35>=0,G35="GBP"),ROUND(ROUND(K35,2)/0.85915,2),"")) | M35: NO_VERIFIED_NET | N35: PUBLIC_PRICE_NOT_KP | O35: UNKNOWN | P35: 2026-09-11 | Q35: https://www.enag.fr/english/wp-content/uploads/sites/5/2022/11/FC-GH-EN-C.pdf | R35: https://www.enag.fr/english/wp-content/uploads/sites/5/2022/11/FC-GH-EN-C.pdf | T35: 18 | U35: RFQ_REQUIRED;220V_COMPATIBILITY_OPEN;WORKING_POINT_OPEN | V35: Explicit230V singlephase; official1m3/h at40m, pressure switch1.5/2.5bar.24L accumulator vs20L needs standardisation; no equivalence claim. | W35: NOT_CONFIRMED | X35: deliverables/M02/v001/01_support/all-candidates.csv
A36: WC-CH-01 | B36: ME-15 | C36: Thermowell | D36: UC16H | E36: 2 | F36: шт | G36: EUR | H36: 4544.35 | I36: GROSS_EXPLICIT_ALV25.5 | J36: 25.5 | K36: 3621 | L36: =IF(AND(ISNUMBER(K36),K36>=0,G36="EUR"),ROUND(K36,2),IF(AND(ISNUMBER(K36),K36>=0,G36="GBP"),ROUND(ROUND(K36,2)/0.85915,2),"")) -> 3621 | M36: OBSERVED_NET_CONDITIONAL_SCOPE | N36: PUBLIC_PRICE_NOT_KP | O36: UNKNOWN | P36: 2026-09-11 | Q36: https://www.esconet.fi/shop/uc16h-thermowell-uc16h-ilmastointilaite-chiller-230v-16000btu-27518 | R36: https://www.thermowellmarine.com/wp-content/uploads/2023/04/THERMOWELL-2023_rev1_apr_web.pdf | S36: 350 × 340 × 380 | T36: 38 | U36: REFERENCE_SIZE_ONLY;VOLTAGE_REVISION_CHECK;SUPPLY_SCOPE_CONFLICT_RFQ | V36: 16000BTU/h each; illustrative class NOT yacht heatload. Officialcatalog220/1/50; dealer230V. Dimensions exclude controlbox. OEM catalogue says box/display included BUT priced Esco SKU requires airhandler/controlpanel separately: inclusion CONFLICT, RFQ required; do not assume included display.1.5kWnominput at catalogue conditions; independent2module integration open. | W36: Esco stock0; supplier availability unknown | X36: deliverables/M02/v001/01_support/all-candidates.csv
A37: WC-CH-02 | B37: ME-15 | C37: Climma | D37: CWS Aquacontrol161RC 230/1/50 | E37: 2 | F37: шт | G37: EUR | H37: 4155.3 | I37: EXPLICIT_TAX_EXCLUDED | K37: 4155.3 | L37: =IF(AND(ISNUMBER(K37),K37>=0,G37="EUR"),ROUND(K37,2),IF(AND(ISNUMBER(K37),K37>=0,G37="GBP"),ROUND(ROUND(K37,2)/0.85915,2),"")) -> 4155.3 | M37: OBSERVED_NET_CONDITIONAL_SCOPE | N37: PUBLIC_PRICE_NOT_KP | O37: UNKNOWN | P37: 2026-09-11 | Q37: https://mdislandsupply.com/en/climma/879-cws-aquacontrol-161-rc-230150-climma.html | R37: https://www.veco.net/en/prodotti/climma-cws-aquacontrol-chillers/ | U37: REFERENCE_SIZE_ONLY;220V_COMPATIBILITY_OPEN | V37: 16000BTU/h each; reversecycle. Price recovered live requests HTTP200 after web429; local source text retained. OEM dimensions require authenticated download; old dealerPDF not promoted. | W37: Last items;1–2businessdays claim | X37: deliverables/M02/v001/01_support/all-candidates.csv
A38: WC-CH-03 | B38: ME-15 | C38: Webasto | D38: BlueCool C16M | E38: 2 | F38: шт | G38: EUR | L38: =IF(AND(ISNUMBER(K38),K38>=0,G38="EUR"),ROUND(K38,2),IF(AND(ISNUMBER(K38),K38>=0,G38="GBP"),ROUND(ROUND(K38,2)/0.85915,2),"")) | M38: NO_VERIFIED_NET | N38: PUBLIC_PRICE_NOT_KP | O38: UNKNOWN | P38: 2026-09-11 | Q38: https://www.nauticsale.com/en/airconditioning/bluecool-chiller-systems/bluecool-c-series-chillers/ | R38: https://www.webasto.com/en-us/cooling/marine-chiller-air-conditioning-units/bluecool-c-series.html | S38: 385 × 290 × 350 | T38: 30 | U38: RFQ_REQUIRED;REFERENCE_SIZE_ONLY;220V_COMPATIBILITY_OPEN | V38: 16000BTU/h each; officialcurrentdimensions. Older F-suffix dealerweight differs: revision match required.3pricepaths found no verified EU net exactSKU; no US price conversion. | W38: NOT_CONFIRMED | X38: deliverables/M02/v001/01_support/all-candidates.csv
A39: WC-HW-01 | B39: ME-14 | C39: Quick | D39: B3 40L1200W FLB34012S000A00 | F39: шт | G39: EUR | H39: 737 | I39: EXPLICIT_HT | K39: 614.17 | L39: =IF(AND(ISNUMBER(K39),K39>=0,G39="EUR"),ROUND(K39,2),IF(AND(ISNUMBER(K39),K39>=0,G39="GBP"),ROUND(ROUND(K39,2)/0.85915,2),"")) -> 614.17 | M39: OBSERVED_NET_CONDITIONAL_SCOPE | N39: PUBLIC_PRICE_NOT_KP | O39: UNKNOWN | P39: 2026-09-11 | Q39: https://www.tyboat.com/achat/P-8889-quick-chauffe-eau-cylindrique-b3-40-litres-220-volts-1200-watts.html | R39: https://www.quickitaly.com/it/prodotti/scalda-acqua/scalda-acqua/nautic-boiler-b3/ | U39: UNIT_BENCHMARK_ONLY;QTY_OPEN | V39: 40L1200W220V plus engine heat exchanger common illustrative class; not owner size. Supplier dimensions/mass in research only pending official drawing. Thermostatic mixing equalise separately. | W39: Stock1–6businessdays | X39: deliverables/M02/v001/01_support/all-candidates.csv
A40: WC-HW-02 | B40: ME-14 | C40: Quick | D40: BX 40L1200W FLBX4012S000A00 | F40: шт | G40: EUR | H40: 829 | I40: EXPLICIT_HT | K40: 690.83 | L40: =IF(AND(ISNUMBER(K40),K40>=0,G40="EUR"),ROUND(K40,2),IF(AND(ISNUMBER(K40),K40>=0,G40="GBP"),ROUND(ROUND(K40,2)/0.85915,2),"")) -> 690.83 | M40: OBSERVED_NET_CONDITIONAL_SCOPE | N40: PUBLIC_PRICE_NOT_KP | O40: UNKNOWN | P40: 2026-09-11 | Q40: https://www.tyboat.com/achat/P-8880-quick-chauffe-eau-cylindrique-bx-40-litres-220-volts-1200-watts.html | R40: https://www.quickitaly.com/it/prodotti/scalda-acqua/scalda-acqua/nautic-boiler-bx/ | U40: UNIT_BENCHMARK_ONLY;QTY_OPEN | V40: 40L1200W220V plus engine heat exchanger common illustrative class; not owner size. Supplier dimensions/mass in research only pending official drawing. Thermostatic mixing equalise separately. | W40: Stock1–6businessdays | X40: deliverables/M02/v001/01_support/all-candidates.csv
...

Sheet 03_Состав
A1: Строка | B1: Вариант | C1: M01 / интерфейсы | D1: Источник_ID | E1: Количество | F1: Ед. | G1: Исполнение из источника | H1: NET / ед. EUR | I1: Известная NET строки | J1: Класс цены | K1: Допуск ценового основания | L1: Состав / недостающее
A2: PK01-A-L01 | B2: PK01-A | C2: ME-01|ME-02|ME-03 | D2: PROP-E02 | E2: 1 | F2: package | G2: =IFERROR(IF(INDEX(02_Цены!$D$2:$D$1000,MATCH(D2,02_Цены!$A$2:$A$1000,0))="","",INDEX(02_Цены!$D$2:$D$1000,MATCH(D2,02_Цены!$A$2:$A$1000,0))),"") -> D4-300 I + HS85A | H2: =IFERROR(IF(INDEX(02_Цены!$L$2:$L$1000,MATCH(D2,02_Цены!$A$2:$A$1000,0))="","",INDEX(02_Цены!$L$2:$L$1000,MATCH(D2,02_Цены!$A$2:$A$1000,0))),"") -> 45977 | I2: =IF(AND(ISNUMBER(E2),E2>=0,ISNUMBER(H2)),ROUND(E2*H2,2),"") -> 45977 | J2: =IFERROR(IF(INDEX(02_Цены!$M$2:$M$1000,MATCH(D2,02_Цены!$A$2:$A$1000,0))="","",INDEX(02_Цены!$M$2:$M$1000,MATCH(D2,02_Цены!$A$2:$A$1000,0))),"") -> HISTORICAL_NOT_CURRENT | K2: =IF(AND(ISNUMBER(I2),J2="OBSERVED_NET_CONDITIONAL_SCOPE",OR(IFERROR(IF(INDEX(02_Цены!$E$2:$E$1000,MATCH(D2,02_Цены!$A$2:$A$1000,0))="","",INDEX(02_Цены!$E$2:$E$1000,MATCH(D2,02_Цены!$A$2:$A$1000,0))),"")="",E2=IFERROR(IF(INDEX(02_Цены!$E$2:$E$1000,MATCH(D2,02_Цены!$A$2:$A$1000,0))="","",INDEX(02_Цены!$E$2:$E$1000,MATCH(D2,02_Цены!$A$2:$A$1000,0))),""))),"PRICE_OBSERVED","BLOCK") -> BLOCK | L2: 300 metric hp crank / 289 prop shaft; 3500rpm R5; 24V option price open; ratio2.500. L=433+801 W=441+407 H=274+520 from drawing; excludes projecting lifting eye/service space; not installation GA; ME-03 partial only factory mounts where included: shaft/coupling/thrust unit quantities and price OPEN
A3: PK01-B-L01 | B3: PK01-B | C3: ME-01|ME-02 | D3: YAN-E01 | E3: 1 | F3: package | G3: =IFERROR(IF(INDEX(02_Цены!$D$2:$D$1000,MATCH(D3,02_Цены!$A$2:$A$1000,0))="","",INDEX(02_Цены!$D$2:$D$1000,MATCH(D3,02_Цены!$A$2:$A$1000,0))),"") -> 8LV320E-KMH50A + VC20 | H3: =IFERROR(IF(INDEX(02_Цены!$L$2:$L$1000,MATCH(D3,02_Цены!$A$2:$A$1000,0))="","",INDEX(02_Цены!$L$2:$L$1000,MATCH(D3,02_Цены!$A$2:$A$1000,0))),"") | I3: =IF(AND(ISNUMBER(E3),E3>=0,ISNUMBER(H3)),ROUND(E3*H3,2),"") | J3: =IFERROR(IF(INDEX(02_Цены!$M$2:$M$1000,MATCH(D3,02_Цены!$A$2:$A$1000,0))="","",INDEX(02_Цены!$M$2:$M$1000,MATCH(D3,02_Цены!$A$2:$A$1000,0))),"") -> NO_VERIFIED_NET | K3: =IF(AND(ISNUMBER(I3),J3="OBSERVED_NET_CONDITIONAL_SCOPE",OR(IFERROR(IF(INDEX(02_Цены!$E$2:$E$1000,MATCH(D3,02_Цены!$A$2:$A$1000,0))="","",INDEX(02_Цены!$E$2:$E$1000,MATCH(D3,02_Цены!$A$2:$A$1000,0))),"")="",E3=IFERROR(IF(INDEX(02_Цены!$E$2:$E$1000,MATCH(D3,02_Цены!$A$2:$A$1000,0))="","",INDEX(02_Цены!$E$2:$E$1000,MATCH(D3,02_Цены!$A$2:$A$1000,0))),""))),"PRICE_OBSERVED","BLOCK") -> BLOCK | L3: 320 mhp / 235 kW at 3800 rpm; 1 engine + 1 KMH50A + VC20; manufacturer 2021 package dry mass 435+52 kg and envelope with gear/elbow; standard 12V starter; front belt PTO optional capacity unverified; dealer includes mounts/panel/wiring/fluids; installed propulsion scope incomplete
A4: PK01-C-L01 | B4: PK01-C | C4: ME-01|ME-02|ME-03 | D4: PROP-E04 | E4: 1 | F4: package | G4: =IFERROR(IF(INDEX(02_Цены!$D$2:$D$1000,MATCH(D4,02_Цены!$A$2:$A$1000,0))="","",INDEX(02_Цены!$D$2:$D$1000,MATCH(D4,02_Цены!$A$2:$A$1000,0))),"") -> C90 410 rating D 300hp + gearbox RFQ | H4: =IFERROR(IF(INDEX(02_Цены!$L$2:$L$1000,MATCH(D4,02_Цены!$A$2:$A$1000,0))="","",INDEX(02_Цены!$L$2:$L$1000,MATCH(D4,02_Цены!$A$2:$A$1000,0))),"") | I4: =IF(AND(ISNUMBER(E4),E4>=0,ISNUMBER(H4)),ROUND(E4*H4,2),"") | J4: =IFERROR(IF(INDEX(02_Цены!$M$2:$M$1000,MATCH(D4,02_Цены!$A$2:$A$1000,0))="","",INDEX(02_Цены!$M$2:$M$1000,MATCH(D4,02_Цены!$A$2:$A$1000,0))),"") -> NO_VERIFIED_NET | K4: =IF(AND(ISNUMBER(I4),J4="OBSERVED_NET_CONDITIONAL_SCOPE",OR(IFERROR(IF(INDEX(02_Цены!$E$2:$E$1000,MATCH(D4,02_Цены!$A$2:$A$1000,0))="","",INDEX(02_Цены!$E$2:$E$1000,MATCH(D4,02_Цены!$A$2:$A$1000,0))),"")="",E4=IFERROR(IF(INDEX(02_Цены!$E$2:$E$1000,MATCH(D4,02_Цены!$A$2:$A$1000,0))="","",INDEX(02_Цены!$E$2:$E$1000,MATCH(D4,02_Цены!$A$2:$A$1000,0))),""))),"PRICE_OBSERVED","BLOCK") -> BLOCK | L4: Official2026 220kW300hp@2000rpm ratingD heavy duty; gearbox unselected/unpriced; shown dimensions length to flywheel and mass ENGINE ONLY; not complete package envelope;24V option RFQ; ME-03 partial only factory mounts where included: shaft/coupling/thrust unit quantities and price OPEN
A5: PK02-A-L01 | B5: PK02-A | C5: ME-04|ME-19 | D5: PROP-G03 | E5: 2 | F5: package | G5: =IFERROR(IF(INDEX(02_Цены!$D$2:$D$1000,MATCH(D5,02_Цены!$A$2:$A$1000,0))="","",INDEX(02_Цены!$D$2:$D$1000,MATCH(D5,02_Цены!$A$2:$A$1000,0))),"") -> Paguro12000V AP12023050M0 | H5: =IFERROR(IF(INDEX(02_Цены!$L$2:$L$1000,MATCH(D5,02_Цены!$A$2:$A$1000,0))="","",INDEX(02_Цены!$L$2:$L$1000,MATCH(D5,02_Цены!$A$2:$A$1000,0))),"") -> 12446.5 | I5: =IF(AND(ISNUMBER(E5),E5>=0,ISNUMBER(H5)),ROUND(E5*H5,2),"") -> 24893 | J5: =IFERROR(IF(INDEX(02_Цены!$M$2:$M$1000,MATCH(D5,02_Цены!$A$2:$A$1000,0))="","",INDEX(02_Цены!$M$2:$M$1000,MATCH(D5,02_Цены!$A$2:$A$1000,0))),"") -> OBSERVED_NET_CONDITIONAL_SCOPE | K5: =IF(AND(ISNUMBER(I5),J5="OBSERVED_NET_CONDITIONAL_SCOPE",OR(IFERROR(IF(INDEX(02_Цены!$E$2:$E$1000,MATCH(D5,02_Цены!$A$2:$A$1000,0))="","",INDEX(02_Цены!$E$2:$E$1000,MATCH(D5,02_Цены!$A$2:$A$1000,0))),"")="",E5=IFERROR(IF(INDEX(02_Цены!$E$2:$E$1000,MATCH(D5,02_Цены!$A$2:$A$1000,0))="","",INDEX(02_Цены!$E$2:$E$1000,MATCH(D5,02_Цены!$A$2:$A$1000,0))),""))),"PRICE_OBSERVED","BLOCK") -> PRICE_OBSERVED | L5: 12kVA10kW continuous50Hz230V;12V starter;mass165capsule+15control electronics. Official dimensions capsule only; separate electronics footprint RFQ. Dealer/allpa dimensions/mass differ; exact SKU installationdrawing required. Published net directly not Polish VAT assumption; ME-19 partial factory cooling only: external seawater/exhaust runs and installation OPEN
A6: PK02-B-L01 | B6: PK02-B | C6: ME-04|ME-19 | D6: PAN-G02 | E6: 2 | F6: package | G6: =IFERROR(IF(INDEX(02_Цены!$D$2:$D$1000,MATCH(D6,02_Цены!$A$2:$A$1000,0))="","",INDEX(02_Цены!$D$2:$D$1000,MATCH(D6,02_Цены!$A$2:$A$1000,0))),"") -> 12000x-230V PMS NautiRadar0028284 | H6: =IFERROR(IF(INDEX(02_Цены!$L$2:$L$1000,MATCH(D6,02_Цены!$A$2:$A$1000,0))="","",INDEX(02_Цены!$L$2:$L$1000,MATCH(D6,02_Цены!$A$2:$A$1000,0))),"") -> 17451.22 | I6: =IF(AND(ISNUMBER(E6),E6>=0,ISNUMBER(H6)),ROUND(E6*H6,2),"") -> 34902.44 | J6: =IFERROR(IF(INDEX(02_Цены!$M$2:$M$1000,MATCH(D6,02_Цены!$A$2:$A$1000,0))="","",INDEX(02_Цены!$M$2:$M$1000,MATCH(D6,02_Цены!$A$2:$A$1000,0))),"") -> OBSERVED_NET_CONDITIONAL_SCOPE | K6: =IF(AND(ISNUMBER(I6),J6="OBSERVED_NET_CONDITIONAL_SCOPE",OR(IFERROR(IF(INDEX(02_Цены!$E$2:$E$1000,MATCH(D6,02_Цены!$A$2:$A$1000,0))="","",INDEX(02_Цены!$E$2:$E$1000,MATCH(D6,02_Цены!$A$2:$A$1000,0))),"")="",E6=IFERROR(IF(INDEX(02_Цены!$E$2:$E$1000,MATCH(D6,02_Цены!$A$2:$A$1000,0))="","",INDEX(02_Цены!$E$2:$E$1000,MATCH(D6,02_Цены!$A$2:$A$1000,0))),""))),"PRICE_OBSERVED","BLOCK") -> PRICE_OBSERVED | L6: 50Hz230V not yet accepted as220V target;2generators retained;standard datasheet12Vstarter, priced24V SKU unconfirmed. 10.2kW/12kVA NOMINAL at20C;2026catalogue treats0.85 kVA factor as short inductive starting only;hot continuous useful output OPEN. Capsule dimensions exclude fittings and service space;ME19 partial factory cooling only. SellerSKU0028284 vsOEMsheet0024660:exact revision must be tied to offer. EU seller does not yet prove EU dispatch/free-circulation/Poland delivery.
