Workbook

Sheet 00_Старт
A1: VDS67 • Шаблон будущей УТВ
A2: Синие ячейки — ввод; серые — формулы. Пусто = нет данных. Код строки сохранять при сортировке.
A3: Раздел | B3: Порядок работы / правило
A4: Статус | B4: TEMPLATE / INCOMPLETE. УТВ возникает после отдельного решения владельца о базовом бюджете.
A5: 1. Основания | B5: Установить границу остатка достройки, валюту, налоговую основу, дату цен и ревизию проекта.
A6: 2. Состав | B6: WBS — системы яхты. Строки сметы разворачивать по ресурсам/работам; один пакет может содержать несколько строк.
A7: 3. Пакеты | B7: Сначала составить одинаковые задания RFQ с границами поставки, монтажа и испытаний.
A8: 4. КП | B8: Регистрировать документы и исходные строки без изменения оригиналов.
A9: 5. КАЦ | B9: Сначала техническая сопоставимость, затем единицы, валюта, налоги и исключённые работы. Автоматического выбора минимальной цены нет.
A10: 6. Смета | B10: Цена из выбранной КАЦ (KAC) или обоснованной оценки без КП (DIRECT). Количество и источник отдельно; выбор КАЦ единственный в группе.
A11: 7. Сводка | B11: Показывает только известную часть и незаполненные позиции. Пустые суммы не равны нулю. Полнота состава отдельно проверяется.
A12: Существующее | B12: Наличие, поставщик и граница затрат — разные поля. Имеющийся корпус не считать новой покупкой по умолчанию.
A13: Ноль | B13: Числовой 0 допустим с подтверждением; UNKNOWN и NOT_APPLICABLE не вводить в денежные клетки.
A14: Двойной счёт | B14: Включённые монтаж, доставка и испытания не добавлять повторно. Вести лист Стыки и ссылку на покрывающую строку.
... A20: Модель | B20: EXP-003 — принятая стартовая идея. Производственные объёмы, мощность оборудования и размеры из неё не утверждены.

Sheet 01_Основания
A1: Основания будущего бюджета
A2: Синие ячейки — ввод; серые — формулы. Пусто = нет данных. Код строки сохранять при сортировке.
A3: Поле | B3: Значение | C3: Источник / решение
A4: Проект | B4: VDS67 | C4: office/project.json
A5: Стройка | B5: Польша | C5: Решение владельца
A6: Статус | B6: TEMPLATE / INCOMPLETE | C6: Утверждение бюджета отсутствует
A7: Граница бюджета | B7: Остаток достройки; понесённое отдельно | C7: Уточнить перечень имущества и ранее оплаченного
A8: Базовая валюта
A9: Налоговая основа NET/GROSS
A10: Дата цен
A11: Ревизия проекта
A12: Владелец / заказчик
A13: Верфь / место передачи
A14: Налоговый режим / обоснование
A15: Курс: базовая валюта за1 валюты КП
A16: Решение об утверждении УТВ
A17: Дата утверждения
A18: Полнота состава проверена
A19: Правило округления | B19: Строка0.01; сумма округлённых строк | C19: Проверить договорные требования
A20: Версия шаблона | B20: U01/v001 | C20: Пустой инструмент; для заполнения копия
A21: Рабочая копия / ответственный
A22: Флаг / эксплуатация / применимость

Sheet 02_WBS
A1: Структура работ и систем яхты
A2: Синие ячейки — ввод; серые — формулы. Пусто = нет данных. Код строки сохранять при сортировке.
A3: WBS | B3: Родитель | C3: Раздел / пакет | D3: Входит | E3: Граница / исключено | F3: Нужные исходные данные | G3: Применимость | H3: Ответственный
A4: W00 | C4: Управление проектом | D4: Задание, бюджет, координация и документы | E4: См. дочерние пакеты | F4: Установить состав и ревизию | G4: REVIEW_REQUIRED
A5: W00.10 | B5: W00 | C5: Управление и координация проекта | D5: Планирование, ведение бюджета и документов, координация исполнителей | E5: Техническое проектирование W02; включённые накладные подрядчиков | F5: Организация проекта; состав услуг и договоры | G5: REVIEW_REQUIRED
A6: W01 | C6: Исходники и обследование | D6: Получение документов, обмер и состояние существующего | E6: См. дочерние пакеты | F6: Установить состав и ревизию | G6: REVIEW_REQUIRED
A7: W01.10 | B7: W01 | C7: Приёмка существующего корпуса и документов | D7: Реестр фактически имеющегося, ревизии, фотофиксация, права использования чертежей; отделение поставленного владельцем от недостающего | E7: Повторная покупка существующего корпуса; ремонт и достройка | F7: Передаточные документы; перечень имущества; происхождение и ревизии CAD | G7: REVIEW_REQUIRED
A8: W01.20 | B8: W01 | C8: Обмер, контроль состояния и дефектная ведомость | D8: Геометрия и толщины по программе обследования, доступные сварные соединения, коррозия, фактические переборки/фундаменты/танки | E8: Ремонт выявленного; производственный контроль новых швов | F8: Доступ к корпусу; программа обследования; квалификация исполнителей | G8: REVIEW_REQUIRED
A9: W02 | C9: Проектирование и применимость требований | D9: Расчётные задания, решения и необходимые согласования | E9: См. дочерние пакеты | F9: Установить состав и ревизию | G9: REVIEW_REQUIRED
A10: W02.10 | B10: W02 | C10: Базовая геометрия, компоновка и расчётная координация | D10: Сверка CAD и обмеров, общий вид/сечения, массы и центры, гидростатика/остойчивость, согласование геометрии всех дисциплин | E10: Серийное оборудование; повторное включение проектирования из пакетов поставщика | F10: Назначение и режим эксплуатации; обмер; выбранные варианты; применимые требования | G10: REVIEW_REQUIRED
A11: W02.20 | B11: W02 | C11: Проект конструкции и изменений | D11: Корпус, рубка, hardtop, мачтовая опора, кормовой гараж, фальшборт, проёмы/подкрепления; рабочие чертежи | E11: Материалы и изготовление W10; EXP-003 не рабочий проект | F11: Расчётные нагрузки; состояние корпуса; утверждённая конструктивная схема; ревизии | G11: REVIEW_REQUIRED
A12: W02.30 | B12: W02 | C12: Интерьерный проект и макеты помещаемости | D12: Раскладки помещений, чистые высоты, макеты критических проходов/мебели/мокрых зон, спецификации отделки | E12: Серийная мебель и её монтаж; повторение общей CAD координации | F12: Цель 3+1 каюты/санузлы; геометрия; сервисные габариты оборудования; образцы отделки | G12: REVIEW_REQUIRED
A13: W02.40 | B13: W02 | C13: Применимость требований и согласования | D13: Маршрут оценки соответствия, технический файл и необходимые внешние проверки по установленному флагу и эксплуатации | E13: Согласования не назначены автоматически; инженерная разработка в W02.10–30 | F13: Статус корпуса; флаг; режим эксплуатации; требования компетентных организаций | G13: REVIEW_REQUIRED
A14: W10 | C14: Корпус и конструкция | D14: Существующее, доработки и подтверждённые объёмы конструкции | E14: См. дочерние пакеты | F14: Установить состав и ревизию | G14: REVIEW_REQUIRED
A15: W10.10 | B15: W10 | C15: Ремонт и завершение исходного корпуса | D15: Только подтверждённые дефекты/недоделки: обшивка, набор, переборки, сварка, локальный производственный контроль | E15: Стоимость уже имеющегося корпуса; будущие изменения W10.20–40; покрытия W10.70–80 | F15: Дефектная ведомость; перечень выполненного; чертежи; программа контроля | G15: REVIEW_REQUIRED
A16: W10.20 | B16: W10 | C16: Новая рубка и hardtop | D16: Конструктивный металл, набор, опоры, крыша, переходы и сварка; геометрическая стартовая идея EXP-003 после переработки | E16: Остекление W20.10; интерьер W60; электрические/жидкостные сети; смета по массе визуальной сетки | F16: Рабочие чертежи; нагрузки мачты/гика; чистые высоты; ведомость металла | G16: REVIEW_REQUIRED
A17: W10.30 | B17: W10 | C17: Корма, гараж и встроенная дверь | D17: Изменение обшивки/набора, конструктивный объём гаража, силовая дверь/рама, переборки и корпусные усиления | E17: Тендер/балка W20.70–80; привод двери W20.80; отделка и системы | F17: Выбранный тендер; траектория; чертежи; нагрузки; водонепроницаемость; существующие отсеки | G17: REVIEW_REQUIRED
A18: W10.40 | B18: W10 | C18: Фальшборт, корпусные вырезы и проходы | D18: Добавка фальшборта, конструктивные кромки отверстий, приварные комингсы, встроенные подкрепления; корпусные шпигаты/штормовые портики и их конструктивное обрамление по проекту без назначения размеров | E18: Съёмные клюзы/утки/релинги W20; трубные системы палубного отвода и стоков W50; уже включённые в W10.20–30 отверстия; интегральные танки W10.90; аноды W10.85 | F18: Утверждённый периметр; узлы; водоотвод; координаты швартовного оборудования | G18: REVIEW_REQUIRED
A19: W10.50 | B19: W10 | C19: Корпусные фундаменты и встроенные опоры | D19: Приварные силовые основания двигателя/агрегатов/мачты/балки/оборудования, закладные и конструктивные проходки по единой ведомости | E19: Рамы в составе купленного агрегата; виброопоры и окончательная установка систем; уже включённые в другие W10 позиции | F19: Ведомость нагрузок и координат; граница заводского комплекта; интерфейсные листы | G19: REVIEW_REQUIRED
A20: W10.60 | B20: W10 | C20: Киль, балласт и корпусные элементы рулевого узла | D20: Проверка наличия, недостающая поставка/установка киля и балласта, корпусные опоры и трубы рулевого узла по проекту | E20: Рулевая машина/перья/подшипники если отнесены W30; не подтверждённые тип/масса балласта | F20: Исполнительные данные; выбранная конструкция; массы; комплектность; граница W30 | G20: REVIEW_REQUIRED
A21: W10.70 | B21: W10 | C21: Наружные покрытия корпуса и надстройки | D21: Подготовка алюминия, выравнивание по согласованным зонам, грунты/барьеры, наружный финиш, подводная система, локальная окраска после монтажа | E21: Палубный настил W20.30; заводское покрытие оборудования; двойной учёт ремонтной подкраски | F21: Карты площадей; требования к поверхности; выбранная совместимая система; климат нанесения | G21: REVIEW_REQUIRED
A22: W10.80 | B22: W10 | C22: Внутренние защитные покрытия | D22: Выбранные внутренние зоны корпуса, льяла и защищаемые металлические поверхности, подготовка и контроль нанесения | E22: Окраска мебельных деталей W60; заводское покрытие агрегатов; автоматически вся площадь алюминия | F22: Карта зон и доступа; спецификация покрытий; последовательность до изоляции | G22: REVIEW_REQUIRED
A23: W10.85 | B23: W10 | C23: Аноды и наружные элементы противокоррозионной защиты | D23: Аноды, их корпусные крепления и установка по проекту защиты алюминиевого корпуса | E23: Электрические защитные соединения и развязка W40.25; покрытия W10.70–80 | F23: Проект защиты; материалы смежных узлов; условия эксплуатации | G23: REVIEW_REQUIRED
A24: W10.90 | B24: W10 | C24: Интегральные сварные танки — условный пакет | D24: Изготовление встроенных танков, корпусные стенки/люки и испытание герметичности до подключения системы | E24: Покупные съёмные ёмкости и трубная обвязка W50; повторное начисление испытаний всей системы | F24: Решение о типе и материале танков; объёмы; чертежи; программа испытаний | G24: REVIEW_REQUIRED
A25: W20 | C25: Рангоут и палуба | D25: Пакеты систем Rig и Deck исходной базы | E25: См. дочерние пакеты | F25: Установить состав и ревизию | G25: REVIEW_REQUIRED
A26: W20.10 | B26: W20 | C26: Наружное остекление, люки и закрытия | D26: Изделия, рамки, стекло/прозрачные панели, уплотнение, крепёж, установка и локальный тест герметичности; наружные двери кроме силовой гаражной | E26: Приварные комингсы W10; шторы W60; силовая дверь гаража W10.30; непринятый материал тёмного стекла | F26: Ведомость проёмов; нагрузки; открывание/выходы; кривизна; оптические требования; монтажный узел | G26: REVIEW_REQUIRED
A27: W20.20 | B27: W20 | C27: Палубная металлическая арматура и швартовка | D27: Релинги/леера, поручни, утки, клюзы, трапы и съёмные детали: поставка, крепёж, установка | E27: Конструктивный фальшборт/подкрепления W10; якорная лебёдка W20.40; спасательные леера отдельно W70 если так назначено | F27: План палубы; нагрузки; электрическая изоляция соединений; чистые проходы | G27: REVIEW_REQUIRED
A28: W20.30 | B28: W20 | C28: Палубные настилы и наружная обивка | D28: Выбранный нескользящий настил или покрытие по раздельным зонам, наружные подушки/чехлы, посадочные поверхности | E28: Подготовка и окраска под настилом W10.70 если включена туда; интерьерная мягкая мебель W60 | F28: Карта зон; материал; масса; дренаж; уход; граница подготовки поверхности | G28: REVIEW_REQUIRED
A29: W20.40 | B29: W20 | C29: Якорное оборудование | D29: Якоря, цепь/канат, лебёдка, стопоры, ролики, направляющие: поставка и механический монтаж | E29: Корпус якорного колодца/подкрепления W10; питание W40; слив W50 | F29: Сценарий якорения; выбранные массы/цепь; падение цепи; места; граница электрического комплекта | G29: REVIEW_REQUIRED
A30: W20.50 | B30: W20 | C30: Рангоут и стоячий такелаж | D30: Мачта/гик, стоячий такелаж, оконцеватели и серийный степс, монтаж, настройка и собственные проверки | E30: Силовая опора корпуса W10.50; электрическая разводка мачты W40; общий спуск W90; паруса | F30: Парусный план; нагрузки; мачтовая схема; перечень включённого поставщиком; крановый план | G30: REVIEW_REQUIRED
A31: W20.55 | B31: W20 | C31: Бегучий такелаж и управление парусами | D31: Шкоты/фалы, блоки, погоны, каретки, лебёдки и закрутки: комплекты, монтаж, настройка | E31: Стоячий такелаж W20.50; центральная гидростанция/сеть W50 если назначена там; питание W40 | F31: Схема проводки; тип приводов; состав комплекта; рабочие зоны и усилия | G31: REVIEW_REQUIRED
A32: W20.60 | B32: W20 | C32: Паруса и их принадлежности | D32: Выбранный комплект парусов, чехлы/мешки, измерение под рангоут, доставка и примерка | E32: Неутверждённые площади как закупочные объёмы; бегучий такелаж; общесудовые ходовые испытания | F32: Окончательный парусный план; материал; комплектация; ветровые сценарии; согласование с рангоутом | G32: REVIEW_REQUIRED
A33: W20.70 | B33: W20 | C33: Тендер и его штатное оснащение | D33: Одна выбранная комплектация тендера, штатные принадлежности, передаточная проверка | E33: Гараж W10.30; балка/крепления W20.80; автоматический выбор Williams по названию типа | F33: Модель/масса в рабочем состоянии; габариты; способ хранения; комплектация и документы | G33: REVIEW_REQUIRED
A34: W20.80 | B34: W20 | C34: Подъём и размещение тендера, механизация гаража | D34: Кран-балка, тележка/стропы, ложемент, крепление в море, привод двери, локальная механика и собственные испытания | E34: Силовые корпусные основания/дверь W10; тендер W20.70; общая сеть гидравлики/питания вне локального комплекта | F34: Траектория и режимы; рабочая масса; опорные реакции; состав привода; аварийное закрытие; границы поставки | G34: REVIEW_REQUIRED
A35: W30 | C35: Движение и управление | D35: Propulsion, Steering и Thruster | E35: См. дочерние пакеты | F35: Установить состав и ревизию | G35: REVIEW_REQUIRED
A36: W30.10 | B36: W30 | C36: Главный двигатель и его установка | D36: Агрегат с редуктором по будущей комплектности; штатные приборы и локальные системы; монтаж, выверка и первичная проверка исполнителя. | E36: Изготовление корпусного фундамента W10; валопровод W30.20; общесудовое топливо W50.10; вентиляция W50.75; общие испытания W80. | F36: Утверждённая пропульсивная концепция, мощностной и весовой расчёт, габариты/сервисный доступ, перечень штатной поставки; модель не выбрана. | G36: REVIEW_REQUIRED
A37: W30.20 | B37: W30 | C37: Валопровод, движитель и внешние системы двигателя | D37: Муфты, упорный узел, вал, подшипники, уплотнения и винт по расчёту; внешние охлаждение и выхлоп от границы агрегата; защита от затопления, сервисные соединения. | E37: Редуктор, если включён в W30.10; изготовление корпуса/дейдвудных опор W10; общие забортные проходы W50.65; повторный учёт штатного охлаждения двигателя. | F37: Геометрия кормы, ось вала, расчёт нагрузок/вибрации, требования производителя к охлаждению/выхлопу, границы поставки. | G37: REVIEW_REQUIRED
A38: W30.30 | B38: W30 | C38: Рулевое устройство и аварийное управление | D38: Баллера/перо и подшипники по границе с конструкцией; механическое или гидравлическое управление, посты, аварийное управление; исполнительный привод автопилота и местные обходы. | E38: Киль/балласт W10.60; усиления корпуса W10; вычислитель/датчики автопилота W40.60; общая гидростанция W50.80. | F38: Обмер существующего рулевого, расчёт момента, выбор архитектуры, независимое аварийное управление, доступ и интерфейсы с автопилотом. | G38: REVIEW_REQUIRED
A39: W30.40 | B39: W30 | C39: Маневровые устройства — условный пакет | D39: Подруливающие или иные вспомогательные устройства, локальные исполнительные узлы и монтаж при принятии решения об установке. | E39: Туннели/вырезы/усиления W10; силовые батареи W40.40; внешние кабели W40.30; общая гидравлика W50.80. | F39: Решение о наличии, расчёт усилия/энергии, корпусная компоновка, шум и сервис; тип и количество не назначены. | G39: REVIEW_REQUIRED
A40: W40 | C40: Энергия, электрика и связь | D40: Electrical, Navigation и Networking | E40: См. дочерние пакеты | F40: Установить состав и ревизию | G40: REVIEW_REQUIRED
...

Sheet 03_Пакеты
A1: Задания на запрос КП / RFQ
A2: Синие ячейки — ввод; серые — формулы. Пусто = нет данных. Код строки сохранять при сортировке.
A3: Пакет_ID | B3: WBS | C3: Название | D3: Ревизия ТЗ | E3: Описание и характеристики | F3: Количество | G3: Единица | H3: Поставка / состав | I3: Монтаж / изготовление | J3: Испытания / документы | K3: Исключено | L3: Место передачи | M3: Желаемый срок | N3: Гарантия / сервис | O3: Источник ТЗ | P3: Ответственный | Q3: Статус

Sheet 04_КП
A1: Реестр исходных коммерческих предложений
A2: Синие ячейки — ввод; серые — формулы. Пусто = нет данных. Код строки сохранять при сортировке.
A3: КП_ID | B3: Поставщик_ID / имя | C3: Документ № | D3: Дата цены | E3: Действует до | F3: Валюта КП | G3: Основа NET/GROSS/OTHER | H3: Налог / режим текстом | I3: Ставка по документу | J3: Условия оплаты | K3: Срок поставки | L3: Место / условия передачи | M3: Доставка включена? | N3: Монтаж включён? | O3: Гарантия / сервис | P3: Документ_ID | Q3: Путь к оригиналу | R3: Доступ | S3: Примечание | T3: Контроль
T4: =IF(A4="","",IF(AND(COUNTIF(A$4:A$203,A4)=1,F4<>"",G4<>"",D4<>"",P4<>"",COUNTIF(13_Источники!$A$4:$A$203,P4)=1,OR(G4="NET",G4="GROSS",AND(G4="OTHER",H4<>""))),"READY","INCOMPLETE / ID"))
T5: =IF(A5="","",IF(AND(COUNTIF(A$4:A$203,A5)=1,F5<>"",G5<>"",D5<>"",P5<>"",COUNTIF(13_Источники!$A$4:$A$203,P5)=1,OR(G5="NET",G5="GROSS",AND(G5="OTHER",H5<>""))),"READY","INCOMPLETE / ID"))
T6: =IF(A6="","",IF(AND(COUNTIF(A$4:A$203,A6)=1,F6<>"",G6<>"",D6<>"",P6<>"",COUNTIF(13_Источники!$A$4:$A$203,P6)=1,OR(G6="NET",G6="GROSS",AND(G6="OTHER",H6<>""))),"READY","INCOMPLETE / ID"))
T7: =IF(A7="","",IF(AND(COUNTIF(A$4:A$203,A7)=1,F7<>"",G7<>"",D7<>"",P7<>"",COUNTIF(13_Источники!$A$4:$A$203,P7)=1,OR(G7="NET",G7="GROSS",AND(G7="OTHER",H7<>""))),"READY","INCOMPLETE / ID"))
T8: =IF(A8="","",IF(AND(COUNTIF(A$4:A$203,A8)=1,F8<>"",G8<>"",D8<>"",P8<>"",COUNTIF(13_Источники!$A$4:$A$203,P8)=1,OR(G8="NET",G8="GROSS",AND(G8="OTHER",H8<>""))),"READY","INCOMPLETE / ID"))
T9: =IF(A9="","",IF(AND(COUNTIF(A$4:A$203,A9)=1,F9<>"",G9<>"",D9<>"",P9<>"",COUNTIF(13_Источники!$A$4:$A$203,P9)=1,OR(G9="NET",G9="GROSS",AND(G9="OTHER",H9<>""))),"READY","INCOMPLETE / ID"))
T10: =IF(A10="","",IF(AND(COUNTIF(A$4:A$203,A10)=1,F10<>"",G10<>"",D10<>"",P10<>"",COUNTIF(13_Источники!$A$4:$A$203,P10)=1,OR(G10="NET",G10="GROSS",AND(G10="OTHER",H10<>""))),"READY","INCOMPLETE / ID"))
T11: =IF(A11="","",IF(AND(COUNTIF(A$4:A$203,A11)=1,F11<>"",G11<>"",D11<>"",P11<>"",COUNTIF(13_Источники!$A$4:$A$203,P11)=1,OR(G11="NET",G11="GROSS",AND(G11="OTHER",H11<>""))),"READY","INCOMPLETE / ID"))
T12: =IF(A12="","",IF(AND(COUNTIF(A$4:A$203,A12)=1,F12<>"",G12<>"",D12<>"",P12<>"",COUNTIF(13_Источники!$A$4:$A$203,P12)=1,OR(G12="NET",G12="GROSS",AND(G12="OTHER",H12<>""))),"READY","INCOMPLETE / ID"))
T13: =IF(A13="","",IF(AND(COUNTIF(A$4:A$203,A13)=1,F13<>"",G13<>"",D13<>"",P13<>"",COUNTIF(13_Источники!$A$4:$A$203,P13)=1,OR(G13="NET",G13="GROSS",AND(G13="OTHER",H13<>""))),"READY","INCOMPLETE / ID"))
T14: =IF(A14="","",IF(AND(COUNTIF(A$4:A$203,A14)=1,F14<>"",G14<>"",D14<>"",P14<>"",COUNTIF(13_Источники!$A$4:$A$203,P14)=1,OR(G14="NET",G14="GROSS",AND(G14="OTHER",H14<>""))),"READY","INCOMPLETE / ID"))
T15: =IF(A15="","",IF(AND(COUNTIF(A$4:A$203,A15)=1,F15<>"",G15<>"",D15<>"",P15<>"",COUNTIF(13_Источники!$A$4:$A$203,P15)=1,OR(G15="NET",G15="GROSS",AND(G15="OTHER",H15<>""))),"READY","INCOMPLETE / ID"))
... T203: =IF(A203="","",IF(AND(COUNTIF(A$4:A$203,A203)=1,F203<>"",G203<>"",D203<>"",P203<>"",COUNTIF(13_Источники!$A$4:$A$203,P203)=1,OR(G203="NET",G203="GROSS",AND(G203="OTHER",H203<>""))),"READY","INCOMPLETE / ID"))

Sheet 05_Строки_КП
A1: Исходные строки КП — без нормализации
A2: Синие ячейки — ввод; серые — формулы. Пусто = нет данных. Код строки сохранять при сортировке.
A3: СтрокаКП_ID | B3: КП_ID | C3: Пакет_ID | D3: Позиция / лист | E3: Наименование / исполнение | F3: Количество в КП | G3: Единица КП | H3: Цена единицы в валюте КП | I3: Состояние цены | J3: Включено | K3: Исключено | L3: Валюта (из КП) | M3: Основа (из КП) | N3: Источник / locator | O3: Контроль
L4: =IF(B4="","",IFERROR(INDEX(04_КП!$F$4:$F$203,MATCH(B4,04_КП!$A$4:$A$203,0)),"")) | M4: =IF(B4="","",IFERROR(INDEX(04_КП!$G$4:$G$203,MATCH(B4,04_КП!$A$4:$A$203,0)),"")) | O4: =IF(A4="","",IF(AND(COUNTIF(A$4:A$203,A4)=1,COUNTIF(04_КП!$A$4:$A$203,B4)=1,IFERROR(INDEX(04_КП!$T$4:$T$203,MATCH(B4,04_КП!$A$4:$A$203,0)),"")="READY",COUNTIF(03_Пакеты!$A$4:$A$203,C4)=1,G4<>"",ISNUMBER(H4),H4>=0,OR(AND(H4>0,I4="KNOWN"),AND(H4=0,I4="ZERO_CONFIRMED")),N4<>""),"READY","INCOMPLETE / SOURCE"))
L5: =IF(B5="","",IFERROR(INDEX(04_КП!$F$4:$F$203,MATCH(B5,04_КП!$A$4:$A$203,0)),"")) | M5: =IF(B5="","",IFERROR(INDEX(04_КП!$G$4:$G$203,MATCH(B5,04_КП!$A$4:$A$203,0)),"")) | O5: =IF(A5="","",IF(AND(COUNTIF(A$4:A$203,A5)=1,COUNTIF(04_КП!$A$4:$A$203,B5)=1,IFERROR(INDEX(04_КП!$T$4:$T$203,MATCH(B5,04_КП!$A$4:$A$203,0)),"")="READY",COUNTIF(03_Пакеты!$A$4:$A$203,C5)=1,G5<>"",ISNUMBER(H5),H5>=0,OR(AND(H5>0,I5="KNOWN"),AND(H5=0,I5="ZERO_CONFIRMED")),N5<>""),"READY","INCOMPLETE / SOURCE"))
L6: =IF(B6="","",IFERROR(INDEX(04_КП!$F$4:$F$203,MATCH(B6,04_КП!$A$4:$A$203,0)),"")) | M6: =IF(B6="","",IFERROR(INDEX(04_КП!$G$4:$G$203,MATCH(B6,04_КП!$A$4:$A$203,0)),"")) | O6: =IF(A6="","",IF(AND(COUNTIF(A$4:A$203,A6)=1,COUNTIF(04_КП!$A$4:$A$203,B6)=1,IFERROR(INDEX(04_КП!$T$4:$T$203,MATCH(B6,04_КП!$A$4:$A$203,0)),"")="READY",COUNTIF(03_Пакеты!$A$4:$A$203,C6)=1,G6<>"",ISNUMBER(H6),H6>=0,OR(AND(H6>0,I6="KNOWN"),AND(H6=0,I6="ZERO_CONFIRMED")),N6<>""),"READY","INCOMPLETE / SOURCE"))
L7: =IF(B7="","",IFERROR(INDEX(04_КП!$F$4:$F$203,MATCH(B7,04_КП!$A$4:$A$203,0)),"")) | M7: =IF(B7="","",IFERROR(INDEX(04_КП!$G$4:$G$203,MATCH(B7,04_КП!$A$4:$A$203,0)),"")) | O7: =IF(A7="","",IF(AND(COUNTIF(A$4:A$203,A7)=1,COUNTIF(04_КП!$A$4:$A$203,B7)=1,IFERROR(INDEX(04_КП!$T$4:$T$203,MATCH(B7,04_КП!$A$4:$A$203,0)),"")="READY",COUNTIF(03_Пакеты!$A$4:$A$203,C7)=1,G7<>"",ISNUMBER(H7),H7>=0,OR(AND(H7>0,I7="KNOWN"),AND(H7=0,I7="ZERO_CONFIRMED")),N7<>""),"READY","INCOMPLETE / SOURCE"))
L8: =IF(B8="","",IFERROR(INDEX(04_КП!$F$4:$F$203,MATCH(B8,04_КП!$A$4:$A$203,0)),"")) | M8: =IF(B8="","",IFERROR(INDEX(04_КП!$G$4:$G$203,MATCH(B8,04_КП!$A$4:$A$203,0)),"")) | O8: =IF(A8="","",IF(AND(COUNTIF(A$4:A$203,A8)=1,COUNTIF(04_КП!$A$4:$A$203,B8)=1,IFERROR(INDEX(04_КП!$T$4:$T$203,MATCH(B8,04_КП!$A$4:$A$203,0)),"")="READY",COUNTIF(03_Пакеты!$A$4:$A$203,C8)=1,G8<>"",ISNUMBER(H8),H8>=0,OR(AND(H8>0,I8="KNOWN"),AND(H8=0,I8="ZERO_CONFIRMED")),N8<>""),"READY","INCOMPLETE / SOURCE"))
L9: =IF(B9="","",IFERROR(INDEX(04_КП!$F$4:$F$203,MATCH(B9,04_КП!$A$4:$A$203,0)),"")) | M9: =IF(B9="","",IFERROR(INDEX(04_КП!$G$4:$G$203,MATCH(B9,04_КП!$A$4:$A$203,0)),"")) | O9: =IF(A9="","",IF(AND(COUNTIF(A$4:A$203,A9)=1,COUNTIF(04_КП!$A$4:$A$203,B9)=1,IFERROR(INDEX(04_КП!$T$4:$T$203,MATCH(B9,04_КП!$A$4:$A$203,0)),"")="READY",COUNTIF(03_Пакеты!$A$4:$A$203,C9)=1,G9<>"",ISNUMBER(H9),H9>=0,OR(AND(H9>0,I9="KNOWN"),AND(H9=0,I9="ZERO_CONFIRMED")),N9<>""),"READY","INCOMPLETE / SOURCE"))
L10: =IF(B10="","",IFERROR(INDEX(04_КП!$F$4:$F$203,MATCH(B10,04_КП!$A$4:$A$203,0)),"")) | M10: =IF(B10="","",IFERROR(INDEX(04_КП!$G$4:$G$203,MATCH(B10,04_КП!$A$4:$A$203,0)),"")) | O10: =IF(A10="","",IF(AND(COUNTIF(A$4:A$203,A10)=1,COUNTIF(04_КП!$A$4:$A$203,B10)=1,IFERROR(INDEX(04_КП!$T$4:$T$203,MATCH(B10,04_КП!$A$4:$A$203,0)),"")="READY",COUNTIF(03_Пакеты!$A$4:$A$203,C10)=1,G10<>"",ISNUMBER(H10),H10>=0,OR(AND(H10>0,I10="KNOWN"),AND(H10=0,I10="ZERO_CONFIRMED")),N10<>""),"READY","INCOMPLETE / SOURCE"))
L11: =IF(B11="","",IFERROR(INDEX(04_КП!$F$4:$F$203,MATCH(B11,04_КП!$A$4:$A$203,0)),"")) | M11: =IF(B11="","",IFERROR(INDEX(04_КП!$G$4:$G$203,MATCH(B11,04_КП!$A$4:$A$203,0)),"")) | O11: =IF(A11="","",IF(AND(COUNTIF(A$4:A$203,A11)=1,COUNTIF(04_КП!$A$4:$A$203,B11)=1,IFERROR(INDEX(04_КП!$T$4:$T$203,MATCH(B11,04_КП!$A$4:$A$203,0)),"")="READY",COUNTIF(03_Пакеты!$A$4:$A$203,C11)=1,G11<>"",ISNUMBER(H11),H11>=0,OR(AND(H11>0,I11="KNOWN"),AND(H11=0,I11="ZERO_CONFIRMED")),N11<>""),"READY","INCOMPLETE / SOURCE"))
L12: =IF(B12="","",IFERROR(INDEX(04_КП!$F$4:$F$203,MATCH(B12,04_КП!$A$4:$A$203,0)),"")) | M12: =IF(B12="","",IFERROR(INDEX(04_КП!$G$4:$G$203,MATCH(B12,04_КП!$A$4:$A$203,0)),"")) | O12: =IF(A12="","",IF(AND(COUNTIF(A$4:A$203,A12)=1,COUNTIF(04_КП!$A$4:$A$203,B12)=1,IFERROR(INDEX(04_КП!$T$4:$T$203,MATCH(B12,04_КП!$A$4:$A$203,0)),"")="READY",COUNTIF(03_Пакеты!$A$4:$A$203,C12)=1,G12<>"",ISNUMBER(H12),H12>=0,OR(AND(H12>0,I12="KNOWN"),AND(H12=0,I12="ZERO_CONFIRMED")),N12<>""),"READY","INCOMPLETE / SOURCE"))
L13: =IF(B13="","",IFERROR(INDEX(04_КП!$F$4:$F$203,MATCH(B13,04_КП!$A$4:$A$203,0)),"")) | M13: =IF(B13="","",IFERROR(INDEX(04_КП!$G$4:$G$203,MATCH(B13,04_КП!$A$4:$A$203,0)),"")) | O13: =IF(A13="","",IF(AND(COUNTIF(A$4:A$203,A13)=1,COUNTIF(04_КП!$A$4:$A$203,B13)=1,IFERROR(INDEX(04_КП!$T$4:$T$203,MATCH(B13,04_КП!$A$4:$A$203,0)),"")="READY",COUNTIF(03_Пакеты!$A$4:$A$203,C13)=1,G13<>"",ISNUMBER(H13),H13>=0,OR(AND(H13>0,I13="KNOWN"),AND(H13=0,I13="ZERO_CONFIRMED")),N13<>""),"READY","INCOMPLETE / SOURCE"))
L14: =IF(B14="","",IFERROR(INDEX(04_КП!$F$4:$F$203,MATCH(B14,04_КП!$A$4:$A$203,0)),"")) | M14: =IF(B14="","",IFERROR(INDEX(04_КП!$G$4:$G$203,MATCH(B14,04_КП!$A$4:$A$203,0)),"")) | O14: =IF(A14="","",IF(AND(COUNTIF(A$4:A$203,A14)=1,COUNTIF(04_КП!$A$4:$A$203,B14)=1,IFERROR(INDEX(04_КП!$T$4:$T$203,MATCH(B14,04_КП!$A$4:$A$203,0)),"")="READY",COUNTIF(03_Пакеты!$A$4:$A$203,C14)=1,G14<>"",ISNUMBER(H14),H14>=0,OR(AND(H14>0,I14="KNOWN"),AND(H14=0,I14="ZERO_CONFIRMED")),N14<>""),"READY","INCOMPLETE / SOURCE"))
L15: =IF(B15="","",IFERROR(INDEX(04_КП!$F$4:$F$203,MATCH(B15,04_КП!$A$4:$A$203,0)),"")) | M15: =IF(B15="","",IFERROR(INDEX(04_КП!$G$4:$G$203,MATCH(B15,04_КП!$A$4:$A$203,0)),"")) | O15: =IF(A15="","",IF(AND(COUNTIF(A$4:A$203,A15)=1,COUNTIF(04_КП!$A$4:$A$203,B15)=1,IFERROR(INDEX(04_КП!$T$4:$T$203,MATCH(B15,04_КП!$A$4:$A$203,0)),"")="READY",COUNTIF(03_Пакеты!$A$4:$A$203,C15)=1,G15<>"",ISNUMBER(H15),H15>=0,OR(AND(H15>0,I15="KNOWN"),AND(H15=0,I15="ZERO_CONFIRMED")),N15<>""),"READY","INCOMPLETE / SOURCE"))
... L203: =IF(B203="","",IFERROR(INDEX(04_КП!$F$4:$F$203,MATCH(B203,04_КП!$A$4:$A$203,0)),"")) | M203: =IF(B203="","",IFERROR(INDEX(04_КП!$G$4:$G$203,MATCH(B203,04_КП!$A$4:$A$203,0)),"")) | O203: =IF(A203="","",IF(AND(COUNTIF(A$4:A$203,A203)=1,COUNTIF(04_КП!$A$4:$A$203,B203)=1,IFERROR(INDEX(04_КП!$T$4:$T$203,MATCH(B203,04_КП!$A$4:$A$203,0)),"")="READY",COUNTIF(03_Пакеты!$A$4:$A$203,C203)=1,G203<>"",ISNUMBER(H203),H203>=0,OR(AND(H203>0,I203="KNOWN"),AND(H203=0,I203="ZERO_CONFIRMED")),N203<>""),"READY","INCOMPLETE / SOURCE"))

Sheet 06_КАЦ
A1: Сопоставление вариантов в единой валюте и составе
A2: Синие ячейки — ввод; серые — формулы. Пусто = нет данных. Код строки сохранять при сортировке.
A3: Опция_ID | B3: Группа сравнения_ID | C3: СтрокаКП_ID | D3: Пакет_ID | E3: Техническая сопоставимость | F3: Единица бюджета | G3: Единиц КП на1 ед. бюджета | H3: FX: база за1 валюты КП | I3: Дата FX | J3: Документ FX_ID | K3: Налоговая корректировка / ед. базы | L3: Недостающие работы / ед. базы | M3: Доставка / ед. базы | N3: Иные корректировки / ед. базы | O3: Исходная цена (из строки КП) | P3: Валюта КП | Q3: Основа КП | R3: Сопоставимая цена / ед. базы | S3: Выбор | T3: Причина решения | U3: Метод всех корректировок / единиц | V3: Контроль | W3: Документ корректировок_ID
O4: =IF(C4="","",IF(IFERROR(INDEX(05_Строки_КП!$O$4:$O$203,MATCH(C4,05_Строки_КП!$A$4:$A$203,0)),"")="READY",IFERROR(INDEX(05_Строки_КП!$H$4:$H$203,MATCH(C4,05_Строки_КП!$A$4:$A$203,0)),""),"")) | P4: =IF(C4="","",IF(IFERROR(INDEX(05_Строки_КП!$O$4:$O$203,MATCH(C4,05_Строки_КП!$A$4:$A$203,0)),"")="READY",IFERROR(INDEX(05_Строки_КП!$L$4:$L$203,MATCH(C4,05_Строки_КП!$A$4:$A$203,0)),""),"")) | Q4: =IF(C4="","",IF(IFERROR(INDEX(05_Строки_КП!$O$4:$O$203,MATCH(C4,05_Строки_КП!$A$4:$A$203,0)),"")="READY",IFERROR(INDEX(05_Строки_КП!$M$4:$M$203,MATCH(C4,05_Строки_КП!$A$4:$A$203,0)),""),"")) | R4: =IF(OR(V4="SELECTED_READY",V4="COMPARABLE_READY"),O4*G4*H4+SUM(K4:N4),"") | V4: =IF(A4="","",IF(AND(COUNTIF(A$4:A$203,A4)=1,B4<>"",C4<>"",D4<>"",COUNTIF(05_Строки_КП!$A$4:$A$203,C4)=1,IFERROR(INDEX(05_Строки_КП!$C$4:$C$203,MATCH(C4,05_Строки_КП!$A$4:$A$203,0)),"")=D4,IFERROR(INDEX(05_Строки_КП!$O$4:$O$203,MATCH(C4,05_Строки_КП!$A$4:$A$203,0)),"")="READY",E4="COMPARABLE",F4<>"",COUNT(G4:H4)=2,G4>0,H4>0,I4<>"",J4<>"",COUNTIF(13_Источники!$A$4:$A$203,J4)=1,W4<>"",COUNTIF(13_Источники!$A$4:$A$203,W4)=1,COUNT(K4:N4)=4,ISNUMBER(O4),U4<>"",01_Основания!$B$8<>"",OR(01_Основания!$B$9="NET",01_Основания!$B$9="GROSS"),01_Основания!$B$10<>"",IF(AND(ISNUMBER(O4),ISNUMBER(G4),ISNUMBER(H4)),O4*G4*H4+SUM(K4:N4)>=0,FALSE())),IF(S4="SELECTED",IF(AND(COUNTIFS(B$4:B$203,B4,S$4:S$203,"SELECTED")=1,T4<>""),"SELECTED_READY","SELECTION_ERROR"),"COMPARABLE_READY"),"INCOMPLETE / NOT_COMPARABLE"))
O5: =IF(C5="","",IF(IFERROR(INDEX(05_Строки_КП!$O$4:$O$203,MATCH(C5,05_Строки_КП!$A$4:$A$203,0)),"")="READY",IFERROR(INDEX(05_Строки_КП!$H$4:$H$203,MATCH(C5,05_Строки_КП!$A$4:$A$203,0)),""),"")) | P5: =IF(C5="","",IF(IFERROR(INDEX(05_Строки_КП!$O$4:$O$203,MATCH(C5,05_Строки_КП!$A$4:$A$203,0)),"")="READY",IFERROR(INDEX(05_Строки_КП!$L$4:$L$203,MATCH(C5,05_Строки_КП!$A$4:$A$203,0)),""),"")) | Q5: =IF(C5="","",IF(IFERROR(INDEX(05_Строки_КП!$O$4:$O$203,MATCH(C5,05_Строки_КП!$A$4:$A$203,0)),"")="READY",IFERROR(INDEX(05_Строки_КП!$M$4:$M$203,MATCH(C5,05_Строки_КП!$A$4:$A$203,0)),""),"")) | R5: =IF(OR(V5="SELECTED_READY",V5="COMPARABLE_READY"),O5*G5*H5+SUM(K5:N5),"") | V5: =IF(A5="","",IF(AND(COUNTIF(A$4:A$203,A5)=1,B5<>"",C5<>"",D5<>"",COUNTIF(05_Строки_КП!$A$4:$A$203,C5)=1,IFERROR(INDEX(05_Строки_КП!$C$4:$C$203,MATCH(C5,05_Строки_КП!$A$4:$A$203,0)),"")=D5,IFERROR(INDEX(05_Строки_КП!$O$4:$O$203,MATCH(C5,05_Строки_КП!$A$4:$A$203,0)),"")="READY",E5="COMPARABLE",F5<>"",COUNT(G5:H5)=2,G5>0,H5>0,I5<>"",J5<>"",COUNTIF(13_Источники!$A$4:$A$203,J5)=1,W5<>"",COUNTIF(13_Источники!$A$4:$A$203,W5)=1,COUNT(K5:N5)=4,ISNUMBER(O5),U5<>"",01_Основания!$B$8<>"",OR(01_Основания!$B$9="NET",01_Основания!$B$9="GROSS"),01_Основания!$B$10<>"",IF(AND(ISNUMBER(O5),ISNUMBER(G5),ISNUMBER(H5)),O5*G5*H5+SUM(K5:N5)>=0,FALSE())),IF(S5="SELECTED",IF(AND(COUNTIFS(B$4:B$203,B5,S$4:S$203,"SELECTED")=1,T5<>""),"SELECTED_READY","SELECTION_ERROR"),"COMPARABLE_READY"),"INCOMPLETE / NOT_COMPARABLE"))
O6: =IF(C6="","",IF(IFERROR(INDEX(05_Строки_КП!$O$4:$O$203,MATCH(C6,05_Строки_КП!$A$4:$A$203,0)),"")="READY",IFERROR(INDEX(05_Строки_КП!$H$4:$H$203,MATCH(C6,05_Строки_КП!$A$4:$A$203,0)),""),"")) | P6: =IF(C6="","",IF(IFERROR(INDEX(05_Строки_КП!$O$4:$O$203,MATCH(C6,05_Строки_КП!$A$4:$A$203,0)),"")="READY",IFERROR(INDEX(05_Строки_КП!$L$4:$L$203,MATCH(C6,05_Строки_КП!$A$4:$A$203,0)),""),"")) | Q6: =IF(C6="","",IF(IFERROR(INDEX(05_Строки_КП!$O$4:$O$203,MATCH(C6,05_Строки_КП!$A$4:$A$203,0)),"")="READY",IFERROR(INDEX(05_Строки_КП!$M$4:$M$203,MATCH(C6,05_Строки_КП!$A$4:$A$203,0)),""),"")) | R6: =IF(OR(V6="SELECTED_READY",V6="COMPARABLE_READY"),O6*G6*H6+SUM(K6:N6),"") | V6: =IF(A6="","",IF(AND(COUNTIF(A$4:A$203,A6)=1,B6<>"",C6<>"",D6<>"",COUNTIF(05_Строки_КП!$A$4:$A$203,C6)=1,IFERROR(INDEX(05_Строки_КП!$C$4:$C$203,MATCH(C6,05_Строки_КП!$A$4:$A$203,0)),"")=D6,IFERROR(INDEX(05_Строки_КП!$O$4:$O$203,MATCH(C6,05_Строки_КП!$A$4:$A$203,0)),"")="READY",E6="COMPARABLE",F6<>"",COUNT(G6:H6)=2,G6>0,H6>0,I6<>"",J6<>"",COUNTIF(13_Источники!$A$4:$A$203,J6)=1,W6<>"",COUNTIF(13_Источники!$A$4:$A$203,W6)=1,COUNT(K6:N6)=4,ISNUMBER(O6),U6<>"",01_Основания!$B$8<>"",OR(01_Основания!$B$9="NET",01_Основания!$B$9="GROSS"),01_Основания!$B$10<>"",IF(AND(ISNUMBER(O6),ISNUMBER(G6),ISNUMBER(H6)),O6*G6*H6+SUM(K6:N6)>=0,FALSE())),IF(S6="SELECTED",IF(AND(COUNTIFS(B$4:B$203,B6,S$4:S$203,"SELECTED")=1,T6<>""),"SELECTED_READY","SELECTION_ERROR"),"COMPARABLE_READY"),"INCOMPLETE / NOT_COMPARABLE"))
O7: =IF(C7="","",IF(IFERROR(INDEX(05_Строки_КП!$O$4:$O$203,MATCH(C7,05_Строки_КП!$A$4:$A$203,0)),"")="READY",IFERROR(INDEX(05_Строки_КП!$H$4:$H$203,MATCH(C7,05_Строки_КП!$A$4:$A$203,0)),""),"")) | P7: =IF(C7="","",IF(IFERROR(INDEX(05_Строки_КП!$O$4:$O$203,MATCH(C7,05_Строки_КП!$A$4:$A$203,0)),"")="READY",IFERROR(INDEX(05_Строки_КП!$L$4:$L$203,MATCH(C7,05_Строки_КП!$A$4:$A$203,0)),""),"")) | Q7: =IF(C7="","",IF(IFERROR(INDEX(05_Строки_КП!$O$4:$O$203,MATCH(C7,05_Строки_КП!$A$4:$A$203,0)),"")="READY",IFERROR(INDEX(05_Строки_КП!$M$4:$M$203,MATCH(C7,05_Строки_КП!$A$4:$A$203,0)),""),"")) | R7: =IF(OR(V7="SELECTED_READY",V7="COMPARABLE_READY"),O7*G7*H7+SUM(K7:N7),"") | V7: =IF(A7="","",IF(AND(COUNTIF(A$4:A$203,A7)=1,B7<>"",C7<>"",D7<>"",COUNTIF(05_Строки_КП!$A$4:$A$203,C7)=1,IFERROR(INDEX(05_Строки_КП!$C$4:$C$203,MATCH(C7,05_Строки_КП!$A$4:$A$203,0)),"")=D7,IFERROR(INDEX(05_Строки_КП!$O$4:$O$203,MATCH(C7,05_Строки_КП!$A$4:$A$203,0)),"")="READY",E7="COMPARABLE",F7<>"",COUNT(G7:H7)=2,G7>0,H7>0,I7<>"",J7<>"",COUNTIF(13_Источники!$A$4:$A$203,J7)=1,W7<>"",COUNTIF(13_Источники!$A$4:$A$203,W7)=1,COUNT(K7:N7)=4,ISNUMBER(O7),U7<>"",01_Основания!$B$8<>"",OR(01_Основания!$B$9="NET",01_Основания!$B$9="GROSS"),01_Основания!$B$10<>"",IF(AND(ISNUMBER(O7),ISNUMBER(G7),ISNUMBER(H7)),O7*G7*H7+SUM(K7:N7)>=0,FALSE())),IF(S7="SELECTED",IF(AND(COUNTIFS(B$4:B$203,B7,S$4:S$203,"SELECTED")=1,T7<>""),"SELECTED_READY","SELECTION_ERROR"),"COMPARABLE_READY"),"INCOMPLETE / NOT_COMPARABLE"))
O8: =IF(C8="","",IF(IFERROR(INDEX(05_Строки_КП!$O$4:$O$203,MATCH(C8,05_Строки_КП!$A$4:$A$203,0)),"")="READY",IFERROR(INDEX(05_Строки_КП!$H$4:$H$203,MATCH(C8,05_Строки_КП!$A$4:$A$203,0)),""),"")) | P8: =IF(C8="","",IF(IFERROR(INDEX(05_Строки_КП!$O$4:$O$203,MATCH(C8,05_Строки_КП!$A$4:$A$203,0)),"")="READY",IFERROR(INDEX(05_Строки_КП!$L$4:$L$203,MATCH(C8,05_Строки_КП!$A$4:$A$203,0)),""),"")) | Q8: =IF(C8="","",IF(IFERROR(INDEX(05_Строки_КП!$O$4:$O$203,MATCH(C8,05_Строки_КП!$A$4:$A$203,0)),"")="READY",IFERROR(INDEX(05_Строки_КП!$M$4:$M$203,MATCH(C8,05_Строки_КП!$A$4:$A$203,0)),""),"")) | R8: =IF(OR(V8="SELECTED_READY",V8="COMPARABLE_READY"),O8*G8*H8+SUM(K8:N8),"") | V8: =IF(A8="","",IF(AND(COUNTIF(A$4:A$203,A8)=1,B8<>"",C8<>"",D8<>"",COUNTIF(05_Строки_КП!$A$4:$A$203,C8)=1,IFERROR(INDEX(05_Строки_КП!$C$4:$C$203,MATCH(C8,05_Строки_КП!$A$4:$A$203,0)),"")=D8,IFERROR(INDEX(05_Строки_КП!$O$4:$O$203,MATCH(C8,05_Строки_КП!$A$4:$A$203,0)),"")="READY",E8="COMPARABLE",F8<>"",COUNT(G8:H8)=2,G8>0,H8>0,I8<>"",J8<>"",COUNTIF(13_Источники!$A$4:$A$203,J8)=1,W8<>"",COUNTIF(13_Источники!$A$4:$A$203,W8)=1,COUNT(K8:N8)=4,ISNUMBER(O8),U8<>"",01_Основания!$B$8<>"",OR(01_Основания!$B$9="NET",01_Основания!$B$9="GROSS"),01_Основания!$B$10<>"",IF(AND(ISNUMBER(O8),ISNUMBER(G8),ISNUMBER(H8)),O8*G8*H8+SUM(K8:N8)>=0,FALSE())),IF(S8="SELECTED",IF(AND(COUNTIFS(B$4:B$203,B8,S$4:S$203,"SELECTED")=1,T8<>""),"SELECTED_READY","SELECTION_ERROR"),"COMPARABLE_READY"),"INCOMPLETE / NOT_COMPARABLE"))
O9: =IF(C9="","",IF(IFERROR(INDEX(05_Строки_КП!$O$4:$O$203,MATCH(C9,05_Строки_КП!$A$4:$A$203,0)),"")="READY",IFERROR(INDEX(05_Строки_КП!$H$4:$H$203,MATCH(C9,05_Строки_КП!$A$4:$A$203,0)),""),"")) | P9: =IF(C9="","",IF(IFERROR(INDEX(05_Строки_КП!$O$4:$O$203,MATCH(C9,05_Строки_КП!$A$4:$A$203,0)),"")="READY",IFERROR(INDEX(05_Строки_КП!$L$4:$L$203,MATCH(C9,05_Строки_КП!$A$4:$A$203,0)),""),"")) | Q9: =IF(C9="","",IF(IFERROR(INDEX(05_Строки_КП!$O$4:$O$203,MATCH(C9,05_Строки_КП!$A$4:$A$203,0)),"")="READY",IFERROR(INDEX(05_Строки_КП!$M$4:$M$203,MATCH(C9,05_Строки_КП!$A$4:$A$203,0)),""),"")) | R9: =IF(OR(V9="SELECTED_READY",V9="COMPARABLE_READY"),O9*G9*H9+SUM(K9:N9),"") | V9: =IF(A9="","",IF(AND(COUNTIF(A$4:A$203,A9)=1,B9<>"",C9<>"",D9<>"",COUNTIF(05_Строки_КП!$A$4:$A$203,C9)=1,IFERROR(INDEX(05_Строки_КП!$C$4:$C$203,MATCH(C9,05_Строки_КП!$A$4:$A$203,0)),"")=D9,IFERROR(INDEX(05_Строки_КП!$O$4:$O$203,MATCH(C9,05_Строки_КП!$A$4:$A$203,0)),"")="READY",E9="COMPARABLE",F9<>"",COUNT(G9:H9)=2,G9>0,H9>0,I9<>"",J9<>"",COUNTIF(13_Источники!$A$4:$A$203,J9)=1,W9<>"",COUNTIF(13_Источники!$A$4:$A$203,W9)=1,COUNT(K9:N9)=4,ISNUMBER(O9),U9<>"",01_Основания!$B$8<>"",OR(01_Основания!$B$9="NET",01_Основания!$B$9="GROSS"),01_Основания!$B$10<>"",IF(AND(ISNUMBER(O9),ISNUMBER(G9),ISNUMBER(H9)),O9*G9*H9+SUM(K9:N9)>=0,FALSE())),IF(S9="SELECTED",IF(AND(COUNTIFS(B$4:B$203,B9,S$4:S$203,"SELECTED")=1,T9<>""),"SELECTED_READY","SELECTION_ERROR"),"COMPARABLE_READY"),"INCOMPLETE / NOT_COMPARABLE"))
O10: =IF(C10="","",IF(IFERROR(INDEX(05_Строки_КП!$O$4:$O$203,MATCH(C10,05_Строки_КП!$A$4:$A$203,0)),"")="READY",IFERROR(INDEX(05_Строки_КП!$H$4:$H$203,MATCH(C10,05_Строки_КП!$A$4:$A$203,0)),""),"")) | P10: =IF(C10="","",IF(IFERROR(INDEX(05_Строки_КП!$O$4:$O$203,MATCH(C10,05_Строки_КП!$A$4:$A$203,0)),"")="READY",IFERROR(INDEX(05_Строки_КП!$L$4:$L$203,MATCH(C10,05_Строки_КП!$A$4:$A$203,0)),""),"")) | Q10: =IF(C10="","",IF(IFERROR(INDEX(05_Строки_КП!$O$4:$O$203,MATCH(C10,05_Строки_КП!$A$4:$A$203,0)),"")="READY",IFERROR(INDEX(05_Строки_КП!$M$4:$M$203,MATCH(C10,05_Строки_КП!$A$4:$A$203,0)),""),"")) | R10: =IF(OR(V10="SELECTED_READY",V10="COMPARABLE_READY"),O10*G10*H10+SUM(K10:N10),"") | V10: =IF(A10="","",IF(AND(COUNTIF(A$4:A$203,A10)=1,B10<>"",C10<>"",D10<>"",COUNTIF(05_Строки_КП!$A$4:$A$203,C10)=1,IFERROR(INDEX(05_Строки_КП!$C$4:$C$203,MATCH(C10,05_Строки_КП!$A$4:$A$203,0)),"")=D10,IFERROR(INDEX(05_Строки_КП!$O$4:$O$203,MATCH(C10,05_Строки_КП!$A$4:$A$203,0)),"")="READY",E10="COMPARABLE",F10<>"",COUNT(G10:H10)=2,G10>0,H10>0,I10<>"",J10<>"",COUNTIF(13_Источники!$A$4:$A$203,J10)=1,W10<>"",COUNTIF(13_Источники!$A$4:$A$203,W10)=1,COUNT(K10:N10)=4,ISNUMBER(O10),U10<>"",01_Основания!$B$8<>"",OR(01_Основания!$B$9="NET",01_Основания!$B$9="GROSS"),01_Основания!$B$10<>"",IF(AND(ISNUMBER(O10),ISNUMBER(G10),ISNUMBER(H10)),O10*G10*H10+SUM(K10:N10)>=0,FALSE())),IF(S10="SELECTED",IF(AND(COUNTIFS(B$4:B$203,B10,S$4:S$203,"SELECTED")=1,T10<>""),"SELECTED_READY","SELECTION_ERROR"),"COMPARABLE_READY"),"INCOMPLETE / NOT_COMPARABLE"))
O11: =IF(C11="","",IF(IFERROR(INDEX(05_Строки_КП!$O$4:$O$203,MATCH(C11,05_Строки_КП!$A$4:$A$203,0)),"")="READY",IFERROR(INDEX(05_Строки_КП!$H$4:$H$203,MATCH(C11,05_Строки_КП!$A$4:$A$203,0)),""),"")) | P11: =IF(C11="","",IF(IFERROR(INDEX(05_Строки_КП!$O$4:$O$203,MATCH(C11,05_Строки_КП!$A$4:$A$203,0)),"")="READY",IFERROR(INDEX(05_Строки_КП!$L$4:$L$203,MATCH(C11,05_Строки_КП!$A$4:$A$203,0)),""),"")) | Q11: =IF(C11="","",IF(IFERROR(INDEX(05_Строки_КП!$O$4:$O$203,MATCH(C11,05_Строки_КП!$A$4:$A$203,0)),"")="READY",IFERROR(INDEX(05_Строки_КП!$M$4:$M$203,MATCH(C11,05_Строки_КП!$A$4:$A$203,0)),""),"")) | R11: =IF(OR(V11="SELECTED_READY",V11="COMPARABLE_READY"),O11*G11*H11+SUM(K11:N11),"") | V11: =IF(A11="","",IF(AND(COUNTIF(A$4:A$203,A11)=1,B11<>"",C11<>"",D11<>"",COUNTIF(05_Строки_КП!$A$4:$A$203,C11)=1,IFERROR(INDEX(05_Строки_КП!$C$4:$C$203,MATCH(C11,05_Строки_КП!$A$4:$A$203,0)),"")=D11,IFERROR(INDEX(05_Строки_КП!$O$4:$O$203,MATCH(C11,05_Строки_КП!$A$4:$A$203,0)),"")="READY",E11="COMPARABLE",F11<>"",COUNT(G11:H11)=2,G11>0,H11>0,I11<>"",J11<>"",COUNTIF(13_Источники!$A$4:$A$203,J11)=1,W11<>"",COUNTIF(13_Источники!$A$4:$A$203,W11)=1,COUNT(K11:N11)=4,ISNUMBER(O11),U11<>"",01_Основания!$B$8<>"",OR(01_Основания!$B$9="NET",01_Основания!$B$9="GROSS"),01_Основания!$B$10<>"",IF(AND(ISNUMBER(O11),ISNUMBER(G11),ISNUMBER(H11)),O11*G11*H11+SUM(K11:N11)>=0,FALSE())),IF(S11="SELECTED",IF(AND(COUNTIFS(B$4:B$203,B11,S$4:S$203,"SELECTED")=1,T11<>""),"SELECTED_READY","SELECTION_ERROR"),"COMPARABLE_READY"),"INCOMPLETE / NOT_COMPARABLE"))
O12: =IF(C12="","",IF(IFERROR(INDEX(05_Строки_КП!$O$4:$O$203,MATCH(C12,05_Строки_КП!$A$4:$A$203,0)),"")="READY",IFERROR(INDEX(05_Строки_КП!$H$4:$H$203,MATCH(C12,05_Строки_КП!$A$4:$A$203,0)),""),"")) | P12: =IF(C12="","",IF(IFERROR(INDEX(05_Строки_КП!$O$4:$O$203,MATCH(C12,05_Строки_КП!$A$4:$A$203,0)),"")="READY",IFERROR(INDEX(05_Строки_КП!$L$4:$L$203,MATCH(C12,05_Строки_КП!$A$4:$A$203,0)),""),"")) | Q12: =IF(C12="","",IF(IFERROR(INDEX(05_Строки_КП!$O$4:$O$203,MATCH(C12,05_Строки_КП!$A$4:$A$203,0)),"")="READY",IFERROR(INDEX(05_Строки_КП!$M$4:$M$203,MATCH(C12,05_Строки_КП!$A$4:$A$203,0)),""),"")) | R12: =IF(OR(V12="SELECTED_READY",V12="COMPARABLE_READY"),O12*G12*H12+SUM(K12:N12),"") | V12: =IF(A12="","",IF(AND(COUNTIF(A$4:A$203,A12)=1,B12<>"",C12<>"",D12<>"",COUNTIF(05_Строки_КП!$A$4:$A$203,C12)=1,IFERROR(INDEX(05_Строки_КП!$C$4:$C$203,MATCH(C12,05_Строки_КП!$A$4:$A$203,0)),"")=D12,IFERROR(INDEX(05_Строки_КП!$O$4:$O$203,MATCH(C12,05_Строки_КП!$A$4:$A$203,0)),"")="READY",E12="COMPARABLE",F12<>"",COUNT(G12:H12)=2,G12>0,H12>0,I12<>"",J12<>"",COUNTIF(13_Источники!$A$4:$A$203,J12)=1,W12<>"",COUNTIF(13_Источники!$A$4:$A$203,W12)=1,COUNT(K12:N12)=4,ISNUMBER(O12),U12<>"",01_Основания!$B$8<>"",OR(01_Основания!$B$9="NET",01_Основания!$B$9="GROSS"),01_Основания!$B$10<>"",IF(AND(ISNUMBER(O12),ISNUMBER(G12),ISNUMBER(H12)),O12*G12*H12+SUM(K12:N12)>=0,FALSE())),IF(S12="SELECTED",IF(AND(COUNTIFS(B$4:B$203,B12,S$4:S$203,"SELECTED")=1,T12<>""),"SELECTED_READY","SELECTION_ERROR"),"COMPARABLE_READY"),"INCOMPLETE / NOT_COMPARABLE"))
O13: =IF(C13="","",IF(IFERROR(INDEX(05_Строки_КП!$O$4:$O$203,MATCH(C13,05_Строки_КП!$A$4:$A$203,0)),"")="READY",IFERROR(INDEX(05_Строки_КП!$H$4:$H$203,MATCH(C13,05_Строки_КП!$A$4:$A$203,0)),""),"")) | P13: =IF(C13="","",IF(IFERROR(INDEX(05_Строки_КП!$O$4:$O$203,MATCH(C13,05_Строки_КП!$A$4:$A$203,0)),"")="READY",IFERROR(INDEX(05_Строки_КП!$L$4:$L$203,MATCH(C13,05_Строки_КП!$A$4:$A$203,0)),""),"")) | Q13: =IF(C13="","",IF(IFERROR(INDEX(05_Строки_КП!$O$4:$O$203,MATCH(C13,05_Строки_КП!$A$4:$A$203,0)),"")="READY",IFERROR(INDEX(05_Строки_КП!$M$4:$M$203,MATCH(C13,05_Строки_КП!$A$4:$A$203,0)),""),"")) | R13: =IF(OR(V13="SELECTED_READY",V13="COMPARABLE_READY"),O13*G13*H13+SUM(K13:N13),"") | V13: =IF(A13="","",IF(AND(COUNTIF(A$4:A$203,A13)=1,B13<>"",C13<>"",D13<>"",COUNTIF(05_Строки_КП!$A$4:$A$203,C13)=1,IFERROR(INDEX(05_Строки_КП!$C$4:$C$203,MATCH(C13,05_Строки_КП!$A$4:$A$203,0)),"")=D13,IFERROR(INDEX(05_Строки_КП!$O$4:$O$203,MATCH(C13,05_Строки_КП!$A$4:$A$203,0)),"")="READY",E13="COMPARABLE",F13<>"",COUNT(G13:H13)=2,G13>0,H13>0,I13<>"",J13<>"",COUNTIF(13_Источники!$A$4:$A$203,J13)=1,W13<>"",COUNTIF(13_Источники!$A$4:$A$203,W13)=1,COUNT(K13:N13)=4,ISNUMBER(O13),U13<>"",01_Основания!$B$8<>"",OR(01_Основания!$B$9="NET",01_Основания!$B$9="GROSS"),01_Основания!$B$10<>"",IF(AND(ISNUMBER(O13),ISNUMBER(G13),ISNUMBER(H13)),O13*G13*H13+SUM(K13:N13)>=0,FALSE())),IF(S13="SELECTED",IF(AND(COUNTIFS(B$4:B$203,B13,S$4:S$203,"SELECTED")=1,T13<>""),"SELECTED_READY","SELECTION_ERROR"),"COMPARABLE_READY"),"INCOMPLETE / NOT_COMPARABLE"))
O14: =IF(C14="","",IF(IFERROR(INDEX(05_Строки_КП!$O$4:$O$203,MATCH(C14,05_Строки_КП!$A$4:$A$203,0)),"")="READY",IFERROR(INDEX(05_Строки_КП!$H$4:$H$203,MATCH(C14,05_Строки_КП!$A$4:$A$203,0)),""),"")) | P14: =IF(C14="","",IF(IFERROR(INDEX(05_Строки_КП!$O$4:$O$203,MATCH(C14,05_Строки_КП!$A$4:$A$203,0)),"")="READY",IFERROR(INDEX(05_Строки_КП!$L$4:$L$203,MATCH(C14,05_Строки_КП!$A$4:$A$203,0)),""),"")) | Q14: =IF(C14="","",IF(IFERROR(INDEX(05_Строки_КП!$O$4:$O$203,MATCH(C14,05_Строки_КП!$A$4:$A$203,0)),"")="READY",IFERROR(INDEX(05_Строки_КП!$M$4:$M$203,MATCH(C14,05_Строки_КП!$A$4:$A$203,0)),""),"")) | R14: =IF(OR(V14="SELECTED_READY",V14="COMPARABLE_READY"),O14*G14*H14+SUM(K14:N14),"") | V14: =IF(A14="","",IF(AND(COUNTIF(A$4:A$203,A14)=1,B14<>"",C14<>"",D14<>"",COUNTIF(05_Строки_КП!$A$4:$A$203,C14)=1,IFERROR(INDEX(05_Строки_КП!$C$4:$C$203,MATCH(C14,05_Строки_КП!$A$4:$A$203,0)),"")=D14,IFERROR(INDEX(05_Строки_КП!$O$4:$O$203,MATCH(C14,05_Строки_КП!$A$4:$A$203,0)),"")="READY",E14="COMPARABLE",F14<>"",COUNT(G14:H14)=2,G14>0,H14>0,I14<>"",J14<>"",COUNTIF(13_Источники!$A$4:$A$203,J14)=1,W14<>"",COUNTIF(13_Источники!$A$4:$A$203,W14)=1,COUNT(K14:N14)=4,ISNUMBER(O14),U14<>"",01_Основания!$B$8<>"",OR(01_Основания!$B$9="NET",01_Основания!$B$9="GROSS"),01_Основания!$B$10<>"",IF(AND(ISNUMBER(O14),ISNUMBER(G14),ISNUMBER(H14)),O14*G14*H14+SUM(K14:N14)>=0,FALSE())),IF(S14="SELECTED",IF(AND(COUNTIFS(B$4:B$203,B14,S$4:S$203,"SELECTED")=1,T14<>""),"SELECTED_READY","SELECTION_ERROR"),"COMPARABLE_READY"),"INCOMPLETE / NOT_COMPARABLE"))
O15: =IF(C15="","",IF(IFERROR(INDEX(05_Строки_КП!$O$4:$O$203,MATCH(C15,05_Строки_КП!$A$4:$A$203,0)),"")="READY",IFERROR(INDEX(05_Строки_КП!$H$4:$H$203,MATCH(C15,05_Строки_КП!$A$4:$A$203,0)),""),"")) | P15: =IF(C15="","",IF(IFERROR(INDEX(05_Строки_КП!$O$4:$O$203,MATCH(C15,05_Строки_КП!$A$4:$A$203,0)),"")="READY",IFERROR(INDEX(05_Строки_КП!$L$4:$L$203,MATCH(C15,05_Строки_КП!$A$4:$A$203,0)),""),"")) | Q15: =IF(C15="","",IF(IFERROR(INDEX(05_Строки_КП!$O$4:$O$203,MATCH(C15,05_Строки_КП!$A$4:$A$203,0)),"")="READY",IFERROR(INDEX(05_Строки_КП!$M$4:$M$203,MATCH(C15,05_Строки_КП!$A$4:$A$203,0)),""),"")) | R15: =IF(OR(V15="SELECTED_READY",V15="COMPARABLE_READY"),O15*G15*H15+SUM(K15:N15),"") | V15: =IF(A15="","",IF(AND(COUNTIF(A$4:A$203,A15)=1,B15<>"",C15<>"",D15<>"",COUNTIF(05_Строки_КП!$A$4:$A$203,C15)=1,IFERROR(INDEX(05_Строки_КП!$C$4:$C$203,MATCH(C15,05_Строки_КП!$A$4:$A$203,0)),"")=D15,IFERROR(INDEX(05_Строки_КП!$O$4:$O$203,MATCH(C15,05_Строки_КП!$A$4:$A$203,0)),"")="READY",E15="COMPARABLE",F15<>"",COUNT(G15:H15)=2,G15>0,H15>0,I15<>"",J15<>"",COUNTIF(13_Источники!$A$4:$A$203,J15)=1,W15<>"",COUNTIF(13_Источники!$A$4:$A$203,W15)=1,COUNT(K15:N15)=4,ISNUMBER(O15),U15<>"",01_Основания!$B$8<>"",OR(01_Основания!$B$9="NET",01_Основания!$B$9="GROSS"),01_Основания!$B$10<>"",IF(AND(ISNUMBER(O15),ISNUMBER(G15),ISNUMBER(H15)),O15*G15*H15+SUM(K15:N15)>=0,FALSE())),IF(S15="SELECTED",IF(AND(COUNTIFS(B$4:B$203,B15,S$4:S$203,"SELECTED")=1,T15<>""),"SELECTED_READY","SELECTION_ERROR"),"COMPARABLE_READY"),"INCOMPLETE / NOT_COMPARABLE"))
... O203: =IF(C203="","",IF(IFERROR(INDEX(05_Строки_КП!$O$4:$O$203,MATCH(C203,05_Строки_КП!$A$4:$A$203,0)),"")="READY",IFERROR(INDEX(05_Строки_КП!$H$4:$H$203,MATCH(C203,05_Строки_КП!$A$4:$A$203,0)),""),"")) | P203: =IF(C203="","",IF(IFERROR(INDEX(05_Строки_КП!$O$4:$O$203,MATCH(C203,05_Строки_КП!$A$4:$A$203,0)),"")="READY",IFERROR(INDEX(05_Строки_КП!$L$4:$L$203,MATCH(C203,05_Строки_КП!$A$4:$A$203,0)),""),"")) | Q203: =IF(C203="","",IF(IFERROR(INDEX(05_Строки_КП!$O$4:$O$203,MATCH(C203,05_Строки_КП!$A$4:$A$203,0)),"")="READY",IFERROR(INDEX(05_Строки_КП!$M$4:$M$203,MATCH(C203,05_Строки_КП!$A$4:$A$203,0)),""),"")) | R203: =IF(OR(V203="SELECTED_READY",V203="COMPARABLE_READY"),O203*G203*H203+SUM(K203:N203),"") | V203: =IF(A203="","",IF(AND(COUNTIF(A$4:A$203,A203)=1,B203<>"",C203<>"",D203<>"",COUNTIF(05_Строки_КП!$A$4:$A$203,C203)=1,IFERROR(INDEX(05_Строки_КП!$C$4:$C$203,MATCH(C203,05_Строки_КП!$A$4:$A$203,0)),"")=D203,IFERROR(INDEX(05_Строки_КП!$O$4:$O$203,MATCH(C203,05_Строки_КП!$A$4:$A$203,0)),"")="READY",E203="COMPARABLE",F203<>"",COUNT(G203:H203)=2,G203>0,H203>0,I203<>"",J203<>"",COUNTIF(13_Источники!$A$4:$A$203,J203)=1,W203<>"",COUNTIF(13_Источники!$A$4:$A$203,W203)=1,COUNT(K203:N203)=4,ISNUMBER(O203),U203<>"",01_Основания!$B$8<>"",OR(01_Основания!$B$9="NET",01_Основания!$B$9="GROSS"),01_Основания!$B$10<>"",IF(AND(ISNUMBER(O203),ISNUMBER(G203),ISNUMBER(H203)),O203*G203*H203+SUM(K203:N203)>=0,FALSE())),IF(S203="SELECTED",IF(AND(COUNTIFS(B$4:B$203,B203,S$4:S$203,"SELECTED")=1,T203<>""),"SELECTED_READY","SELECTION_ERROR"),"COMPARABLE_READY"),"INCOMPLETE / NOT_COMPARABLE"))

Sheet 07_Смета
A1: Рабочая смета — заготовка будущей УТВ
A2: Синие ячейки — ввод; серые — формулы. Пусто = нет данных. Код строки сохранять при сортировке.
A3: Строка_ID | B3: WBS | C3: Пакет_ID | D3: Наименование работы / ресурса | E3: Вид затрат | F3: Состояние объекта | G3: Кто поставляет | H3: Граница затрат | I3: Количество | J3: Единица | K3: Основание цены_ID | L3: Цена / ед. базовая | M3: Сумма базовая | N3: Контроль готовности | O3: Документ количества_ID | P3: Ревизия / лист | Q3: Состояние количества | R3: Состав / исключения | S3: Ответственный | T3: Решение / версия УТВ | U3: Примечание | V3: Тип основания цены
A4: EST-001 | B4: W00.10 | D4: Управление и координация проекта | L4: =IF(N4="READY",IF(V4="KAC",IFERROR(INDEX(06_КАЦ!$R$4:$R$203,MATCH(K4,06_КАЦ!$A$4:$A$203,0)),""),IFERROR(INDEX(06а_Оценки!$F$4:$F$203,MATCH(K4,06а_Оценки!$A$4:$A$203,0)),"")),"") | M4: =IF(N4="READY",ROUND(I4*L4,2),"") | N4: =IF(A4="","",IF(Q4="NOT_APPLICABLE",IF(AND(COUNTIF(A$4:A$203,A4)=1,H4="OUTSIDE",R4<>"",O4<>"",COUNTIF(13_Источники!$A$4:$A$203,O4)=1),"NOT_APPLICABLE","INCOMPLETE / EXCLUSION"),IF(AND(COUNTIF(A$4:A$203,A4)=1,COUNTIF(02_WBS!$A$4:$A$200,B4)=1,C4<>"",COUNTIF(03_Пакеты!$A$4:$A$203,C4)=1,IFERROR(INDEX(03_Пакеты!$B$4:$B$203,MATCH(C4,03_Пакеты!$A$4:$A$203,0)),"")=B4,E4<>"",F4<>"",F4<>"UNKNOWN",G4<>"",G4<>"UNKNOWN",OR(H4="REMAINING",H4="SUNK",H4="OUTSIDE"),ISNUMBER(I4),I4>=0,OR(AND(I4>0,Q4="KNOWN"),AND(I4=0,Q4="ZERO_CONFIRMED")),J4<>"",K4<>"",OR(AND(V4="KAC",COUNTIF(06_КАЦ!$A$4:$A$203,K4)=1,IFERROR(INDEX(06_КАЦ!$V$4:$V$203,MATCH(K4,06_КАЦ!$A$4:$A$203,0)),"")="SELECTED_READY",IFERROR(INDEX(06_КАЦ!$D$4:$D$203,MATCH(K4,06_КАЦ!$A$4:$A$203,0)),"")=C4,IFERROR(INDEX(06_КАЦ!$F$4:$F$203,MATCH(K4,06_КАЦ!$A$4:$A$203,0)),"")=J4),AND(V4="DIRECT",COUNTIF(06а_Оценки!$A$4:$A$203,K4)=1,IFERROR(INDEX(06а_Оценки!$N$4:$N$203,MATCH(K4,06а_Оценки!$A$4:$A$203,0)),"")="READY",IFERROR(INDEX(06а_Оценки!$B$4:$B$203,MATCH(K4,06а_Оценки!$A$4:$A$203,0)),"")=C4,IFERROR(INDEX(06а_Оценки!$E$4:$E$203,MATCH(K4,06а_Оценки!$A$4:$A$203,0)),"")=J4)),O4<>"",COUNTIF(13_Источники!$A$4:$A$203,O4)=1,P4<>"",R4<>""),"READY","INCOMPLETE / LINK"))) -> INCOMPLETE / LINK | Q4: UNKNOWN | R4: Техническое проектирование W02; включённые накладные подрядчиков
A5: EST-002 | B5: W01.10 | D5: Приёмка существующего корпуса и документов | L5: =IF(N5="READY",IF(V5="KAC",IFERROR(INDEX(06_КАЦ!$R$4:$R$203,MATCH(K5,06_КАЦ!$A$4:$A$203,0)),""),IFERROR(INDEX(06а_Оценки!$F$4:$F$203,MATCH(K5,06а_Оценки!$A$4:$A$203,0)),"")),"") | M5: =IF(N5="READY",ROUND(I5*L5,2),"") | N5: =IF(A5="","",IF(Q5="NOT_APPLICABLE",IF(AND(COUNTIF(A$4:A$203,A5)=1,H5="OUTSIDE",R5<>"",O5<>"",COUNTIF(13_Источники!$A$4:$A$203,O5)=1),"NOT_APPLICABLE","INCOMPLETE / EXCLUSION"),IF(AND(COUNTIF(A$4:A$203,A5)=1,COUNTIF(02_WBS!$A$4:$A$200,B5)=1,C5<>"",COUNTIF(03_Пакеты!$A$4:$A$203,C5)=1,IFERROR(INDEX(03_Пакеты!$B$4:$B$203,MATCH(C5,03_Пакеты!$A$4:$A$203,0)),"")=B5,E5<>"",F5<>"",F5<>"UNKNOWN",G5<>"",G5<>"UNKNOWN",OR(H5="REMAINING",H5="SUNK",H5="OUTSIDE"),ISNUMBER(I5),I5>=0,OR(AND(I5>0,Q5="KNOWN"),AND(I5=0,Q5="ZERO_CONFIRMED")),J5<>"",K5<>"",OR(AND(V5="KAC",COUNTIF(06_КАЦ!$A$4:$A$203,K5)=1,IFERROR(INDEX(06_КАЦ!$V$4:$V$203,MATCH(K5,06_КАЦ!$A$4:$A$203,0)),"")="SELECTED_READY",IFERROR(INDEX(06_КАЦ!$D$4:$D$203,MATCH(K5,06_КАЦ!$A$4:$A$203,0)),"")=C5,IFERROR(INDEX(06_КАЦ!$F$4:$F$203,MATCH(K5,06_КАЦ!$A$4:$A$203,0)),"")=J5),AND(V5="DIRECT",COUNTIF(06а_Оценки!$A$4:$A$203,K5)=1,IFERROR(INDEX(06а_Оценки!$N$4:$N$203,MATCH(K5,06а_Оценки!$A$4:$A$203,0)),"")="READY",IFERROR(INDEX(06а_Оценки!$B$4:$B$203,MATCH(K5,06а_Оценки!$A$4:$A$203,0)),"")=C5,IFERROR(INDEX(06а_Оценки!$E$4:$E$203,MATCH(K5,06а_Оценки!$A$4:$A$203,0)),"")=J5)),O5<>"",COUNTIF(13_Источники!$A$4:$A$203,O5)=1,P5<>"",R5<>""),"READY","INCOMPLETE / LINK"))) -> INCOMPLETE / LINK | Q5: UNKNOWN | R5: Повторная покупка существующего корпуса; ремонт и достройка
A6: EST-003 | B6: W01.20 | D6: Обмер, контроль состояния и дефектная ведомость | L6: =IF(N6="READY",IF(V6="KAC",IFERROR(INDEX(06_КАЦ!$R$4:$R$203,MATCH(K6,06_КАЦ!$A$4:$A$203,0)),""),IFERROR(INDEX(06а_Оценки!$F$4:$F$203,MATCH(K6,06а_Оценки!$A$4:$A$203,0)),"")),"") | M6: =IF(N6="READY",ROUND(I6*L6,2),"") | N6: =IF(A6="","",IF(Q6="NOT_APPLICABLE",IF(AND(COUNTIF(A$4:A$203,A6)=1,H6="OUTSIDE",R6<>"",O6<>"",COUNTIF(13_Источники!$A$4:$A$203,O6)=1),"NOT_APPLICABLE","INCOMPLETE / EXCLUSION"),IF(AND(COUNTIF(A$4:A$203,A6)=1,COUNTIF(02_WBS!$A$4:$A$200,B6)=1,C6<>"",COUNTIF(03_Пакеты!$A$4:$A$203,C6)=1,IFERROR(INDEX(03_Пакеты!$B$4:$B$203,MATCH(C6,03_Пакеты!$A$4:$A$203,0)),"")=B6,E6<>"",F6<>"",F6<>"UNKNOWN",G6<>"",G6<>"UNKNOWN",OR(H6="REMAINING",H6="SUNK",H6="OUTSIDE"),ISNUMBER(I6),I6>=0,OR(AND(I6>0,Q6="KNOWN"),AND(I6=0,Q6="ZERO_CONFIRMED")),J6<>"",K6<>"",OR(AND(V6="KAC",COUNTIF(06_КАЦ!$A$4:$A$203,K6)=1,IFERROR(INDEX(06_КАЦ!$V$4:$V$203,MATCH(K6,06_КАЦ!$A$4:$A$203,0)),"")="SELECTED_READY",IFERROR(INDEX(06_КАЦ!$D$4:$D$203,MATCH(K6,06_КАЦ!$A$4:$A$203,0)),"")=C6,IFERROR(INDEX(06_КАЦ!$F$4:$F$203,MATCH(K6,06_КАЦ!$A$4:$A$203,0)),"")=J6),AND(V6="DIRECT",COUNTIF(06а_Оценки!$A$4:$A$203,K6)=1,IFERROR(INDEX(06а_Оценки!$N$4:$N$203,MATCH(K6,06а_Оценки!$A$4:$A$203,0)),"")="READY",IFERROR(INDEX(06а_Оценки!$B$4:$B$203,MATCH(K6,06а_Оценки!$A$4:$A$203,0)),"")=C6,IFERROR(INDEX(06а_Оценки!$E$4:$E$203,MATCH(K6,06а_Оценки!$A$4:$A$203,0)),"")=J6)),O6<>"",COUNTIF(13_Источники!$A$4:$A$203,O6)=1,P6<>"",R6<>""),"READY","INCOMPLETE / LINK"))) -> INCOMPLETE / LINK | Q6: UNKNOWN | R6: Ремонт выявленного; производственный контроль новых швов
A7: EST-004 | B7: W02.10 | D7: Базовая геометрия, компоновка и расчётная координация | L7: =IF(N7="READY",IF(V7="KAC",IFERROR(INDEX(06_КАЦ!$R$4:$R$203,MATCH(K7,06_КАЦ!$A$4:$A$203,0)),""),IFERROR(INDEX(06а_Оценки!$F$4:$F$203,MATCH(K7,06а_Оценки!$A$4:$A$203,0)),"")),"") | M7: =IF(N7="READY",ROUND(I7*L7,2),"") | N7: =IF(A7="","",IF(Q7="NOT_APPLICABLE",IF(AND(COUNTIF(A$4:A$203,A7)=1,H7="OUTSIDE",R7<>"",O7<>"",COUNTIF(13_Источники!$A$4:$A$203,O7)=1),"NOT_APPLICABLE","INCOMPLETE / EXCLUSION"),IF(AND(COUNTIF(A$4:A$203,A7)=1,COUNTIF(02_WBS!$A$4:$A$200,B7)=1,C7<>"",COUNTIF(03_Пакеты!$A$4:$A$203,C7)=1,IFERROR(INDEX(03_Пакеты!$B$4:$B$203,MATCH(C7,03_Пакеты!$A$4:$A$203,0)),"")=B7,E7<>"",F7<>"",F7<>"UNKNOWN",G7<>"",G7<>"UNKNOWN",OR(H7="REMAINING",H7="SUNK",H7="OUTSIDE"),ISNUMBER(I7),I7>=0,OR(AND(I7>0,Q7="KNOWN"),AND(I7=0,Q7="ZERO_CONFIRMED")),J7<>"",K7<>"",OR(AND(V7="KAC",COUNTIF(06_КАЦ!$A$4:$A$203,K7)=1,IFERROR(INDEX(06_КАЦ!$V$4:$V$203,MATCH(K7,06_КАЦ!$A$4:$A$203,0)),"")="SELECTED_READY",IFERROR(INDEX(06_КАЦ!$D$4:$D$203,MATCH(K7,06_КАЦ!$A$4:$A$203,0)),"")=C7,IFERROR(INDEX(06_КАЦ!$F$4:$F$203,MATCH(K7,06_КАЦ!$A$4:$A$203,0)),"")=J7),AND(V7="DIRECT",COUNTIF(06а_Оценки!$A$4:$A$203,K7)=1,IFERROR(INDEX(06а_Оценки!$N$4:$N$203,MATCH(K7,06а_Оценки!$A$4:$A$203,0)),"")="READY",IFERROR(INDEX(06а_Оценки!$B$4:$B$203,MATCH(K7,06а_Оценки!$A$4:$A$203,0)),"")=C7,IFERROR(INDEX(06а_Оценки!$E$4:$E$203,MATCH(K7,06а_Оценки!$A$4:$A$203,0)),"")=J7)),O7<>"",COUNTIF(13_Источники!$A$4:$A$203,O7)=1,P7<>"",R7<>""),"READY","INCOMPLETE / LINK"))) -> INCOMPLETE / LINK | Q7: UNKNOWN | R7: Серийное оборудование; повторное включение проектирования из пакетов поставщика
A8: EST-005 | B8: W02.20 | D8: Проект конструкции и изменений | L8: =IF(N8="READY",IF(V8="KAC",IFERROR(INDEX(06_КАЦ!$R$4:$R$203,MATCH(K8,06_КАЦ!$A$4:$A$203,0)),""),IFERROR(INDEX(06а_Оценки!$F$4:$F$203,MATCH(K8,06а_Оценки!$A$4:$A$203,0)),"")),"") | M8: =IF(N8="READY",ROUND(I8*L8,2),"") | N8: =IF(A8="","",IF(Q8="NOT_APPLICABLE",IF(AND(COUNTIF(A$4:A$203,A8)=1,H8="OUTSIDE",R8<>"",O8<>"",COUNTIF(13_Источники!$A$4:$A$203,O8)=1),"NOT_APPLICABLE","INCOMPLETE / EXCLUSION"),IF(AND(COUNTIF(A$4:A$203,A8)=1,COUNTIF(02_WBS!$A$4:$A$200,B8)=1,C8<>"",COUNTIF(03_Пакеты!$A$4:$A$203,C8)=1,IFERROR(INDEX(03_Пакеты!$B$4:$B$203,MATCH(C8,03_Пакеты!$A$4:$A$203,0)),"")=B8,E8<>"",F8<>"",F8<>"UNKNOWN",G8<>"",G8<>"UNKNOWN",OR(H8="REMAINING",H8="SUNK",H8="OUTSIDE"),ISNUMBER(I8),I8>=0,OR(AND(I8>0,Q8="KNOWN"),AND(I8=0,Q8="ZERO_CONFIRMED")),J8<>"",K8<>"",OR(AND(V8="KAC",COUNTIF(06_КАЦ!$A$4:$A$203,K8)=1,IFERROR(INDEX(06_КАЦ!$V$4:$V$203,MATCH(K8,06_КАЦ!$A$4:$A$203,0)),"")="SELECTED_READY",IFERROR(INDEX(06_КАЦ!$D$4:$D$203,MATCH(K8,06_КАЦ!$A$4:$A$203,0)),"")=C8,IFERROR(INDEX(06_КАЦ!$F$4:$F$203,MATCH(K8,06_КАЦ!$A$4:$A$203,0)),"")=J8),AND(V8="DIRECT",COUNTIF(06а_Оценки!$A$4:$A$203,K8)=1,IFERROR(INDEX(06а_Оценки!$N$4:$N$203,MATCH(K8,06а_Оценки!$A$4:$A$203,0)),"")="READY",IFERROR(INDEX(06а_Оценки!$B$4:$B$203,MATCH(K8,06а_Оценки!$A$4:$A$203,0)),"")=C8,IFERROR(INDEX(06а_Оценки!$E$4:$E$203,MATCH(K8,06а_Оценки!$A$4:$A$203,0)),"")=J8)),O8<>"",COUNTIF(13_Источники!$A$4:$A$203,O8)=1,P8<>"",R8<>""),"READY","INCOMPLETE / LINK"))) -> INCOMPLETE / LINK | Q8: UNKNOWN | R8: Материалы и изготовление W10; EXP-003 не рабочий проект
A9: EST-006 | B9: W02.30 | D9: Интерьерный проект и макеты помещаемости | L9: =IF(N9="READY",IF(V9="KAC",IFERROR(INDEX(06_КАЦ!$R$4:$R$203,MATCH(K9,06_КАЦ!$A$4:$A$203,0)),""),IFERROR(INDEX(06а_Оценки!$F$4:$F$203,MATCH(K9,06а_Оценки!$A$4:$A$203,0)),"")),"") | M9: =IF(N9="READY",ROUND(I9*L9,2),"") | N9: =IF(A9="","",IF(Q9="NOT_APPLICABLE",IF(AND(COUNTIF(A$4:A$203,A9)=1,H9="OUTSIDE",R9<>"",O9<>"",COUNTIF(13_Источники!$A$4:$A$203,O9)=1),"NOT_APPLICABLE","INCOMPLETE / EXCLUSION"),IF(AND(COUNTIF(A$4:A$203,A9)=1,COUNTIF(02_WBS!$A$4:$A$200,B9)=1,C9<>"",COUNTIF(03_Пакеты!$A$4:$A$203,C9)=1,IFERROR(INDEX(03_Пакеты!$B$4:$B$203,MATCH(C9,03_Пакеты!$A$4:$A$203,0)),"")=B9,E9<>"",F9<>"",F9<>"UNKNOWN",G9<>"",G9<>"UNKNOWN",OR(H9="REMAINING",H9="SUNK",H9="OUTSIDE"),ISNUMBER(I9),I9>=0,OR(AND(I9>0,Q9="KNOWN"),AND(I9=0,Q9="ZERO_CONFIRMED")),J9<>"",K9<>"",OR(AND(V9="KAC",COUNTIF(06_КАЦ!$A$4:$A$203,K9)=1,IFERROR(INDEX(06_КАЦ!$V$4:$V$203,MATCH(K9,06_КАЦ!$A$4:$A$203,0)),"")="SELECTED_READY",IFERROR(INDEX(06_КАЦ!$D$4:$D$203,MATCH(K9,06_КАЦ!$A$4:$A$203,0)),"")=C9,IFERROR(INDEX(06_КАЦ!$F$4:$F$203,MATCH(K9,06_КАЦ!$A$4:$A$203,0)),"")=J9),AND(V9="DIRECT",COUNTIF(06а_Оценки!$A$4:$A$203,K9)=1,IFERROR(INDEX(06а_Оценки!$N$4:$N$203,MATCH(K9,06а_Оценки!$A$4:$A$203,0)),"")="READY",IFERROR(INDEX(06а_Оценки!$B$4:$B$203,MATCH(K9,06а_Оценки!$A$4:$A$203,0)),"")=C9,IFERROR(INDEX(06а_Оценки!$E$4:$E$203,MATCH(K9,06а_Оценки!$A$4:$A$203,0)),"")=J9)),O9<>"",COUNTIF(13_Источники!$A$4:$A$203,O9)=1,P9<>"",R9<>""),"READY","INCOMPLETE / LINK"))) -> INCOMPLETE / LINK | Q9: UNKNOWN | R9: Серийная мебель и её монтаж; повторение общей CAD координации
A10: EST-007 | B10: W02.40 | D10: Применимость требований и согласования | L10: =IF(N10="READY",IF(V10="KAC",IFERROR(INDEX(06_КАЦ!$R$4:$R$203,MATCH(K10,06_КАЦ!$A$4:$A$203,0)),""),IFERROR(INDEX(06а_Оценки!$F$4:$F$203,MATCH(K10,06а_Оценки!$A$4:$A$203,0)),"")),"") | M10: =IF(N10="READY",ROUND(I10*L10,2),"") | N10: =IF(A10="","",IF(Q10="NOT_APPLICABLE",IF(AND(COUNTIF(A$4:A$203,A10)=1,H10="OUTSIDE",R10<>"",O10<>"",COUNTIF(13_Источники!$A$4:$A$203,O10)=1),"NOT_APPLICABLE","INCOMPLETE / EXCLUSION"),IF(AND(COUNTIF(A$4:A$203,A10)=1,COUNTIF(02_WBS!$A$4:$A$200,B10)=1,C10<>"",COUNTIF(03_Пакеты!$A$4:$A$203,C10)=1,IFERROR(INDEX(03_Пакеты!$B$4:$B$203,MATCH(C10,03_Пакеты!$A$4:$A$203,0)),"")=B10,E10<>"",F10<>"",F10<>"UNKNOWN",G10<>"",G10<>"UNKNOWN",OR(H10="REMAINING",H10="SUNK",H10="OUTSIDE"),ISNUMBER(I10),I10>=0,OR(AND(I10>0,Q10="KNOWN"),AND(I10=0,Q10="ZERO_CONFIRMED")),J10<>"",K10<>"",OR(AND(V10="KAC",COUNTIF(06_КАЦ!$A$4:$A$203,K10)=1,IFERROR(INDEX(06_КАЦ!$V$4:$V$203,MATCH(K10,06_КАЦ!$A$4:$A$203,0)),"")="SELECTED_READY",IFERROR(INDEX(06_КАЦ!$D$4:$D$203,MATCH(K10,06_КАЦ!$A$4:$A$203,0)),"")=C10,IFERROR(INDEX(06_КАЦ!$F$4:$F$203,MATCH(K10,06_КАЦ!$A$4:$A$203,0)),"")=J10),AND(V10="DIRECT",COUNTIF(06а_Оценки!$A$4:$A$203,K10)=1,IFERROR(INDEX(06а_Оценки!$N$4:$N$203,MATCH(K10,06а_Оценки!$A$4:$A$203,0)),"")="READY",IFERROR(INDEX(06а_Оценки!$B$4:$B$203,MATCH(K10,06а_Оценки!$A$4:$A$203,0)),"")=C10,IFERROR(INDEX(06а_Оценки!$E$4:$E$203,MATCH(K10,06а_Оценки!$A$4:$A$203,0)),"")=J10)),O10<>"",COUNTIF(13_Источники!$A$4:$A$203,O10)=1,P10<>"",R10<>""),"READY","INCOMPLETE / LINK"))) -> INCOMPLETE / LINK | Q10: UNKNOWN | R10: Согласования не назначены автоматически; инженерная разработка в W02.10–30
